Workbook

Sheet NAV
A1: Vessel | B1: DWT | C1: Class | D1: Employment | E1: Ownership | F1: Built | G1: Age 2024 | H1: Age 2025 | I1: Scrubber | J1: ECO | K1: Value 2024 | L1: Value 2025 | N1: Cotización: | O1: ='[1]Stock Valuation'!$C$10 -> 11.24
A2: DHT Mustang | B2: 317.975 | C2: ABS | D2: Spot | E2: 1 | F2: 43101 | G2: =(TODAY()-F2)/365 -> 6.7972603 | H2: =G2+1 -> 7.7972603 | I2: 1 | J2: 1 | K2: =$O$23*G2^3+$P$23*G2^2+$Q$23*G2+$R$23 -> 98.454717 | L2: =$O$23*H2^3+$P$23*H2^2+$Q$23*H2+$R$23 -> 93.390066
A3: DHT Bronco | B3: 317.975 | C3: ABS | D3: Spot | E3: 1 | F3: 43101 | G3: =(TODAY()-F3)/365 -> 6.7972603 | H3: =G3+1 -> 7.7972603 | I3: 1 | J3: 1 | K3: =$O$23*G3^3+$P$23*G3^2+$Q$23*G3+$R$23 -> 98.454717 | L3: =$O$23*H3^3+$P$23*H3^2+$Q$23*H3+$R$23 -> 93.390066 | N3: Net Asset Value | O3: Q2 2023 | P3: Q3 2023 | Q3: Q4 2023 | R3: Q1 2024 | S3: Q2 2024 | T3: Q3 2024 | U3: Q4 2024
A4: DHT Colt | B4: 319.713 | C4: LR | D4: Spot | E4: 1 | F4: 43101 | G4: =(TODAY()-F4)/365 -> 6.7972603 | H4: =G4+1 -> 7.7972603 | I4: 1 | J4: 1 | K4: =$O$23*G4^3+$P$23*G4^2+$Q$23*G4+$R$23 -> 98.454717 | L4: =$O$23*H4^3+$P$23*H4^2+$Q$23*H4+$R$23 -> 93.390066 | N4: Fleet Value | O4: 1809.9 | P4: 1809.9 | Q4: 1809.9 | R4: 1784.23 | S4: 1965.46 | T4: =SUM(K2:K25) -> 1793.3905 | U4: =SUM(K2:K25) -> 1793.3905
A5: DHT Stallion | B5: 319.713 | C5: LR | D5: Spot | E5: 1 | F5: 43101 | G5: =(TODAY()-F5)/365 -> 6.7972603 | H5: =G5+1 -> 7.7972603 | I5: 1 | J5: 1 | K5: =$O$23*G5^3+$P$23*G5^2+$Q$23*G5+$R$23 -> 98.454717 | L5: =$O$23*H5^3+$P$23*H5^2+$Q$23*H5+$R$23 -> 93.390066 | N5: Financial Debt | O5: =-Balance!G53/1000 -> -388.299 | P5: =-Balance!H53/1000 -> -436.58 | Q5: =-Balance!I53/1000 -> -428.725 | R5: =-Balance!J53/1000 -> -397.78 | S5: =-Balance!K53/1000 -> -414.604 | T5: =-Balance!L53/1000 -> -406.17 | U5: =-Balance!M53/1000 -> -397.736
A6: DHT Tiger | B6: 299.629 | C6: ABS | D6: Spot | E6: 1 | F6: 42736 | G6: =(TODAY()-F6)/365 -> 7.7972603 | H6: =G6+1 -> 8.7972603 | I6: 1 | J6: 1 | K6: =$O$23*G6^3+$P$23*G6^2+$Q$23*G6+$R$23 -> 93.390066 | L6: =$O$23*H6^3+$P$23*H6^2+$Q$23*H6+$R$23 -> 88.103779 | N6: Cash | O6: =Balance!G4/1000 -> 130.649 | P6: =Balance!H4/1000 -> 73.92 | Q6: =Balance!I4/1000 -> 74.738 | R6: =Balance!J4/1000 -> 73.076 | S6: =Balance!K4/1000 -> 72.642 | T6: =Balance!L4/1000 -> 72.4686 | U6: =Balance!M4/1000 -> 97.88232
A7: DHT Harrier | B7: 299.985 | C7: LR | D7: Q4 2024 | E7: 1 | F7: 42370 | G7: =(TODAY()-F7)/365 -> 8.8 | H7: =G7+1 -> 9.8 | I7: 1 | J7: 1 | K7: =$O$23*G7^3+$P$23*G7^2+$Q$23*G7+$R$23 -> 88.089046 | L7: =$O$23*H7^3+$P$23*H7^2+$Q$23*H7+$R$23 -> 82.640406 | N7: Payments on NB
A8: DHT Osprey | B8: 299.999 | C8: LR | D8: Q2 2027 | E8: 1 | F8: 42370 | G8: =(TODAY()-F8)/365 -> 8.8 | H8: =G8+1 -> 9.8 | I8: 1 | J8: 1 | K8: =$O$23*G8^3+$P$23*G8^2+$Q$23*G8+$R$23 -> 88.089046 | L8: =$O$23*H8^3+$P$23*H8^2+$Q$23*H8+$R$23 -> 82.640406 | N8: Bunker
A9: DHT Puma | B9: 299.629 | C9: ABS | D9: Q1 2026 sharing | E9: 1 | F9: 42370 | G9: =(TODAY()-F9)/365 -> 8.8 | H9: =G9+1 -> 9.8 | I9: 1 | J9: 1 | K9: =$O$23*G9^3+$P$23*G9^2+$Q$23*G9+$R$23 -> 88.089046 | L9: =$O$23*H9^3+$P$23*H9^2+$Q$23*H9+$R$23 -> 82.640406 | N9: Working Capital | O9: =Balance!G70/1000 -> 85.426 | P9: =Balance!H70/1000 -> 80.691 | Q9: =Balance!I70/1000 -> 107.828 | R9: =Balance!J70/1000 -> 112.714 | S9: =Balance!K70/1000 -> 156.583 | T9: =Balance!L70/1000 -> 156.583 | U9: =Balance!M70/1000 -> 156.583
A10: DHT Panther | B10: 299.629 | C10: ABS | D10: Spot | E10: 1 | F10: 42370 | G10: =(TODAY()-F10)/365 -> 8.8 | H10: =G10+1 -> 9.8 | I10: 1 | J10: 1 | K10: =$O$23*G10^3+$P$23*G10^2+$Q$23*G10+$R$23 -> 88.089046 | L10: =$O$23*H10^3+$P$23*H10^2+$Q$23*H10+$R$23 -> 82.640406 | N10: Scrubbers | O10: =COUNT(I2:I25)*2 -> 48 | P10: =O10 -> 48 | Q10: 48 | R10: 48 | S10: 48 | T10: =COUNT(I2:I25)*2 -> 48 | U10: =COUNT(I2:I25)*2 -> 48
A11: DHT Lion | B11: 299.629 | C11: ABS | D11: Spot | E11: 1 | F11: 42370 | G11: =(TODAY()-F11)/365 -> 8.8 | H11: =G11+1 -> 9.8 | I11: 1 | J11: 1 | K11: =$O$23*G11^3+$P$23*G11^2+$Q$23*G11+$R$23 -> 88.089046 | L11: =$O$23*H11^3+$P$23*H11^2+$Q$23*H11+$R$23 -> 82.640406 | N11: Net Assets | O11: =SUM(O4:O10) -> 1685.676 | P11: =SUM(P4:P10) -> 1575.931 | Q11: =SUM(Q4:Q10) -> 1611.741 | R11: =SUM(R4:R10) -> 1620.24 | S11: =SUM(S4:S10) -> 1828.081 | T11: =SUM(T4:T10) -> 1664.2721 | U11: =SUM(U4:U10) -> 1698.1199
A12: DHT Leopard | B12: 299.629 | C12: ABS | D12: Q4 2027 | E12: 1 | F12: 42370 | G12: =(TODAY()-F12)/365 -> 8.8 | H12: =G12+1 -> 9.8 | I12: 1 | J12: 1 | K12: =$O$23*G12^3+$P$23*G12^2+$Q$23*G12+$R$23 -> 88.089046 | L12: =$O$23*H12^3+$P$23*H12^2+$Q$23*H12+$R$23 -> 82.640406
A13: DHT Jaguar | B13: 299.629 | C13: ABS | D13: Spot | E13: 1 | F13: 42005 | G13: =(TODAY()-F13)/365 -> 9.8 | H13: =G13+1 -> 10.8 | I13: 1 | J13: 1 | K13: =$O$23*G13^3+$P$23*G13^2+$Q$23*G13+$R$23 -> 82.640406 | L13: =$O$23*H13^3+$P$23*H13^2+$Q$23*H13+$R$23 -> 77.089584 | N13: Shares Outstanding | O13: ='P&L'!G38/1000000 -> 163.17299 | P13: ='P&L'!H38/1000000 -> 161.90203 | Q13: ='P&L'!I38/1000000 -> 161.20649 | R13: ='P&L'!J38/1000000 -> 161.42505 | S13: ='P&L'!K38/1000000 -> 161.4865 | T13: ='P&L'!L38/1000000 -> 161.4865 | U13: ='P&L'!M38/1000000 -> 161.4865
A14: DHT Opal | B14: 320.105 | C14: LR | D14: Spot | E14: 1 | F14: 40909 | G14: =(TODAY()-F14)/365 -> 12.80274 | H14: =G14+1 -> 13.80274 | I14: 1 | J14: 1 | K14: =$O$23*G14^3+$P$23*G14^2+$Q$23*G14+$R$23 -> 65.904769 | L14: =$O$23*H14^3+$P$23*H14^2+$Q$23*H14+$R$23 -> 60.405557
A15: DHT Sundarbans | B15: 318.123 | C15: LR | D15: Spot | E15: 1 | F15: 40909 | G15: =(TODAY()-F15)/365 -> 12.80274 | H15: =G15+1 -> 13.80274 | I15: 1 | J15: 1 | K15: =$O$23*G15^3+$P$23*G15^2+$Q$23*G15+$R$23 -> 65.904769 | L15: =$O$23*H15^3+$P$23*H15^2+$Q$23*H15+$R$23 -> 60.405557 | N15: Net Asset Value $/sh | O15: =O11/O13 -> 10.330607 | P15: =P11/P13 -> 9.733856 | Q15: =Q11/Q13 -> 9.997991 | R15: =R11/R13 -> 10.037104 | S15: =S11/S13 -> 11.320333 | T15: =T11/T13 -> 10.305952 | U15: =U11/U13 -> 10.515553
A16: DHT Taiga | B16: 314.249 | C16: ABS | D16: Spot | E16: 1 | F16: 40909 | G16: =(TODAY()-F16)/365 -> 12.80274 | H16: =G16+1 -> 13.80274 | I16: 1 | J16: 1 | K16: =$O$23*G16^3+$P$23*G16^2+$Q$23*G16+$R$23 -> 65.904769 | L16: =$O$23*H16^3+$P$23*H16^2+$Q$23*H16+$R$23 -> 60.405557 | N16: Más DIVI | Q16: 0.15 | R16: 0.22 | S16: 0.29 | T16: 0.27 | U16: 0.28
A17: DHT Peony | B17: 320.013 | C17: ABS | D17: Spot | E17: 1 | F17: 40544 | G17: =(TODAY()-F17)/365 -> 13.80274 | H17: =G17+1 -> 14.80274 | I17: 1 | J17: 1 | K17: =$O$23*G17^3+$P$23*G17^2+$Q$23*G17+$R$23 -> 60.405557 | L17: =$O$23*H17^3+$P$23*H17^2+$Q$23*H17+$R$23 -> 55.042904 | N17: P / NAV | O17: =SUM($O$1/O15) -> 1.088029 | P17: =SUM($O$1/P15) -> 1.1547325 | Q17: =SUM($O$1/Q15) -> 1.1242259 | R17: =SUM($O$1/R15) -> 1.119845 | S17: =SUM($O$1/(S15)) -> 0.99290365 | T17: =SUM($O$1/(T15)) -> 1.0906319 | U17: =SUM($O$1/(U15+U16)) -> 1.0411695
A18: DHT Lotus | B18: 320.142 | C18: ABS | D18: Spot | E18: 1 | F18: 40544 | G18: =(TODAY()-F18)/365 -> 13.80274 | H18: =G18+1 -> 14.80274 | I18: 1 | J18: 1 | K18: =$O$23*G18^3+$P$23*G18^2+$Q$23*G18+$R$23 -> 60.405557 | L18: =$O$23*H18^3+$P$23*H18^2+$Q$23*H18+$R$23 -> 55.042904
A19: DHT Amazon | B19: 318.13 | C19: LR | D19: Spot | E19: 1 | F19: 40544 | G19: =(TODAY()-F19)/365 -> 13.80274 | H19: =G19+1 -> 14.80274 | I19: 1 | J19: 1 | K19: =$O$23*G19^3+$P$23*G19^2+$Q$23*G19+$R$23 -> 60.405557 | L19: =$O$23*H19^3+$P$23*H19^2+$Q$23*H19+$R$23 -> 55.042904
A20: DHT Redwood | B20: 314.249 | C20: ABS | D20: Spot | E20: 1 | F20: 40544 | G20: =(TODAY()-F20)/365 -> 13.80274 | H20: =G20+1 -> 14.80274 | I20: 1 | J20: 1 | K20: =$O$23*G20^3+$P$23*G20^2+$Q$23*G20+$R$23 -> 60.405557 | L20: =$O$23*H20^3+$P$23*H20^2+$Q$23*H20+$R$23 -> 55.042904 | N20: Suscrito alertas noticias: | O20: sí
A21: DHT China | B21: 317.794 | C21: LR | D21: Spot | E21: 1 | F21: 39083 | G21: =(TODAY()-F21)/365 -> 17.805479 | H21: =G21+1 -> 18.805479 | I21: 1 | K21: =$O$23*G21^3+$P$23*G21^2+$Q$23*G21+$R$23 -> 40.358636 | L21: =$O$23*H21^3+$P$23*H21^2+$Q$23*H21+$R$23 -> 36.139769
A22: DHT Europe | B22: 317.713 | C22: LR | D22: Spot | E22: 1 | F22: 39083 | G22: =(TODAY()-F22)/365 -> 17.805479 | H22: =G22+1 -> 18.805479 | I22: 1 | K22: =$O$23*G22^3+$P$23*G22^2+$Q$23*G22+$R$23 -> 40.358636 | L22: =$O$23*H22^3+$P$23*H22^2+$Q$23*H22+$R$23 -> 36.139769 | N22: Estimación lineal:
A23: DHT Bauhinia | B23: 301.019 | C23: LR | D23: Spot | E23: 1 | F23: 39083 | G23: =(TODAY()-F23)/365 -> 17.805479 | H23: =G23+1 -> 18.805479 | I23: 1 | K23: =$O$23*G23^3+$P$23*G23^2+$Q$23*G23+$R$23 -> 40.358636 | L23: =$O$23*H23^3+$P$23*H23^2+$Q$23*H23+$R$23 -> 36.139769 | N23: VLCC | O23: ='[1]Cleaves Vessels Value'!$C$11 -> 0.0099407407 | P23: ='[1]Cleaves Vessels Value'!$D$11 -> -0.34334921 | Q23: ='[1]Cleaves Vessels Value'!$E$11 -> -1.6441534 | R23: ='[1]Cleaves Vessels Value'!$F$11 -> 122.37222
A24: DHT Scandinavia | B24: 317.826 | C24: ABS | D24: Spot | E24: 1 | F24: 38718 | G24: =(TODAY()-F24)/365 -> 18.805479 | H24: =G24+1 -> 19.805479 | I24: 1 | K24: =$O$23*G24^3+$P$23*G24^2+$Q$23*G24+$R$23 -> 36.139769 | L24: =$O$23*H24^3+$P$23*H24^2+$Q$23*H24+$R$23 -> 32.355847
A25: DHT Appaloosa | B25: 318.918 | C25: ABS | D25: Spot | E25: 1 | F25: 43101 | G25: =(TODAY()-F25)/365 -> 6.7972603 | H25: =G25+1 -> 7.7972603 | I25: 1 | J25: 1 | K25: =$O$23*G25^3+$P$23*G25^2+$Q$23*G25+$R$23 -> 98.454717 | L25: =$O$23*H25^3+$P$23*H25^2+$Q$23*H25+$R$23 -> 93.390066
A26: NB VLCC | B26: VLCC | E26: 1 | F26: 46054 | N26: Dividends: | O26: 2 - 5 - 8 - 11
A27: NB VLCC | B27: VLCC | E27: 1 | F27: 46113 | N27: Calendar: | O27: 2 - 5 - 8 - 11
B28: VLCC | E28: 1 | F28: 46143
B29: VLCC | E29: 1 | F29: 46204

Sheet Scenarios
C2: Bunker Fuel Consumption (50% laden / 50% ballast)
C3: Sailing Days VLCC | H3: 325
C4: Eco + Scrubber VLCC | H4: 45 | I4: tons/day
C5: Non-Eco, Non-Scrubber VLCC | H5: 61.5 | I5: tons/day
C6: Incremental for Scrubber VLCC | H6: 2
C7: Bunker Fuel Prices
C8: High Sulphur Fuel Oil (HSFO), Average 20 Ports | H8: =[1]Shipping!$C$22 -> 521.40909 | I8: $/ton
C9: Very Low Sulphur Fuel Oil (VLSFO), Average 20 Ports | H9: =[1]Shipping!$C$24 -> 664.45455 | I9: $/ton
C10: Eco Savings
C11: Eco Daily Savings VLCC | H11: =+(H3*(H5-H4)*H9/365) -> 9762.0205 | I11: $/d
C12: Scrubber Savings
C13: VLCC | H13: =+(H3*(H4-H6)*(H9-H8))/365 -> 5476.8773 | I13: $/d
C14: Scrubber + Eco Savings
C15: VLCC | H15: =+H13+H11 -> 15238.898 | I15: $/d
C18: TCE | F18: Q1 2023 | G18: Q2 2023 | H18: Q3 2023 | I18: Q4 2023 | J18: Q1 2024 | K18: Q2 2024 | L18: Q3 2024 | M18: Q4 2024
C19: VLCC | F19: 49100 | G19: 56300 | H19: 42500 | I19: =42800 -> 42800 | J19: 50900 | K19: 49100 | L19: 42400 | M19: =39200*1.15 -> 45080
F23: 2024 | R23: 2025
C24: October: | D24: November | E24: December | F24: January | G24: February | H24: March | I24: April | J24: May | K24: June | L24: July | M24: August | N24: September | O24: October | P24: November | Q24: December | R24: January | S24: February | T24: March
C28: BASE | D28: Q3 2022 | E28: Q4 2022 | F28: Q1 2023 | G28: Q2 2023 | H28: Q3 2023 | I28: Q4 2023 | J28: Q1 2024 | K28: Q2 2024 | L28: Q3 2024 | M28: Q4 2024
C29: VLCC
C30: Suezmax
C31: Aframax/LR2
B33: TC | C33: LOW | D33: Q3 2022 | E33: Q4 2022 | F33: Q1 2023 | G33: Q2 2023 | H33: Q3 2023 | I33: Q4 2023 | J33: Q1 2024 | K33: Q2 2024 | L33: Q3 2024 | M33: Q4 2024
C34: VLCC | H34: =H29-3000 -> -3000 | I34: =I29-3000 -> -3000 | J34: =J29-3000 -> -3000 | K34: =K29-3000 -> -3000
C35: Suezmax | H35: =H30-3000 -> -3000 | I35: =I30-3000 -> -3000 | J35: =J30-3000 -> -3000 | K35: =K30-3000 -> -3000
C36: Aframax/LR2 | H36: =H31-3000 -> -3000 | I36: =I31-3000 -> -3000 | J36: =J31-3000 -> -3000 | K36: =K31-3000 -> -3000
C38: HIGH | D38: Q3 2022 | E38: Q4 2022 | F38: Q1 2023 | G38: Q2 2023 | H38: Q3 2023 | I38: Q4 2023 | J38: Q1 2024 | K38: Q2 2024 | L38: Q3 2024 | M38: Q4 2024
C39: VLCC | H39: =H29+3000 -> 3000 | I39: =I29+3000 -> 3000 | J39: =J29+3000 -> 3000 | K39: =K29+3000 -> 3000
C40: Suezmax | H40: =H30+3000 -> 3000 | I40: =I30+3000 -> 3000 | J40: =J30+3000 -> 3000 | K40: =K30+3000 -> 3000
C41: Aframax/LR2 | H41: =H31+3000 -> 3000 | I41: =I31+3000 -> 3000 | J41: =J31+3000 -> 3000 | K41: =K31+3000 -> 3000
C44: VLCC Opex / vessel $/d
C47: Dividend Pay-Out
C48: 1
C50: Fleewide G&A
C51: N.A.

Sheet P&L
B1: DHT (Thousands $) | C1: =D1-1 -> 2021 | D1: 2022 | E1: 2023 | F1: Q1 2023 | G1: Q2 2023 | H1: Q3 2023 | I1: Q4 2023 | J1: Q1 2024 | K1: Q2 2024 | L1: Q3 2024 | M1: Q4 2024
A2: x | B2: P&L
B3: Shipping Revenues | C3: 295853 | D3: 450382 | E3: =SUM(F3:I3) -> 556075 | F3: 131468 | G3: 151993 | H3: 130322 | I3: 142292 | J3: 145876 | K3: 150066 | L3: =SUM(L70:L93)/1000 -> 87089.6 | M3: =SUM(M70:M93)/1000 -> 92594.32
B4: Other revenues | D4: 3765 | F4: 1100 | G4: 1054 | H4: 1243 | I4: 1084 | J4: 1162 | K4: 1171 | L4: 1000 | M4: 1000
B5: Total Revenues | C5: =SUM(C3:C4) -> 295853 | D5: =SUM(D3:D4) -> 454147 | E5: =SUM(E3:E4) -> 556075 | F5: =SUM(F3:F4) -> 132568 | G5: =SUM(G3:G4) -> 153047 | H5: =SUM(H3:H4) -> 131565 | I5: =SUM(I3:I4) -> 143376 | J5: =SUM(J3:J4) -> 147038 | ... M5: =SUM(M3:M4) -> 93594.32
B7: Other income | C7: 4612
B9: Operating expenses
B10: Voyage expenses | C10: -92405 | D10: -185502 | E10: =SUM(F10:I10) -> -165667 | F10: -37569 | G10: -39092 | H10: -41235 | I10: -47771 | J10: -39537 | K10: -46370
B11: Vessel operating expenses | C11: -77807 | D11: -73808 | E11: =SUM(F11:I11) -> -75430 | F11: -18417 | G11: -19687 | H11: -18608 | I11: -18718 | J11: -19172 | K11: -20393 | L11: -20393 | M11: -20393
B12: D&A | C12: -128639 | D12: -123255 | E12: =SUM(F12:I12) -> -108903 | F12: -25726 | G12: -26376 | H12: -28326 | I12: -28475 | J12: -28250 | K12: -27878 | L12: -27878 | M12: -27878
B13: Impairment charges | C13: 0 | E13: =SUM(F13:I13) -> 0
B14: Gain/(loss) sale of vessels | C14: 15153 | D14: 19512 | E14: =SUM(F14:I14) -> 0
B15: G&A | C15: -16565 | D15: -16890 | E15: =SUM(F15:I15) -> -17448 | F15: -4637 | G15: -4515 | H15: -4303 | I15: -3993 | J15: -4664 | K15: -4521 | L15: -4521 | M15: -4521
B16: Total operating expenses | C16: =SUM(C10:C15) -> -300263 | D16: =SUM(D10:D15) -> -379943 | E16: =SUM(E10:E15) -> -367448 | F16: =SUM(F10:F15) -> -86349 | G16: =SUM(G10:G15) -> -89670 | H16: =SUM(H10:H15) -> -92472 | I16: =SUM(I10:I15) -> -98957 | J16: =SUM(J10:J15) -> -91623 | ... M16: =SUM(M10:M15) -> -52792
B18: Operating (loss)/income | C18: =C5+C7+C16 -> 202 | D18: =D5+D7+D16 -> 74204 | E18: =E5+E7+E16 -> 188627 | F18: =F5+F7+F16 -> 46219 | G18: =G5+G7+G16 -> 63377 | H18: =H5+H7+H16 -> 39093 | I18: =I5+I7+I16 -> 44419 | J18: =J5+J7+J16 -> 55415 | ... M18: =M5+M7+M16 -> 40802.32
B20: Share of profit from associated companies | C20: 1278 | D20: 1407 | E20: =SUM(F20:I20) -> 0 | G20: 0 | H20: 0 | I20: 0 | J20: 0 | K20: 0 | L20: 0 | M20: 0
B21: Interest income | C21: 6 | D21: -5941 | E21: =SUM(F21:I21) -> 4485 | F21: 398 | G21: 1966 | H21: 1213 | I21: 908 | J21: 1091 | K21: 935 | L21: 1000 | M21: 1000
B22: Interest expense | C22: -25727 | D22: -16471 | E22: =SUM(F22:I22) -> -33061 | F22: -7586 | G22: -7492 | H22: -8789 | I22: -9194 | J22: -8775 | K22: -7921 | L22: -7921 | M22: -7921
B23: Fair value gain/(loss) on derivative financial liabilities | C23: 12450 | D23: 11726 | E23: =SUM(F23:I23) -> -503 | F23: -433 | G23: -70 | H23: 0 | I23: 0 | J23: 0 | K23: 0 | L23: 0 | M23: 0
B24: Other financial (expense)/income | C24: 645 | D24: -2357 | E24: =SUM(F24:I24) -> -1984 | F24: -366 | G24: -606 | H24: -413 | I24: -599 | J24: -454 | K24: -470 | L24: -470 | M24: -470
B25: Profit/(loss) before tax | C25: =C18+SUM(C20:C24) -> -11146 | D25: =D18+SUM(D20:D24) -> 62568 | E25: =E18+SUM(E20:E24) -> 157564 | F25: =F18+SUM(F20:F24) -> 38232 | G25: =G18+SUM(G20:G24) -> 57175 | H25: =H18+SUM(H20:H24) -> 31104 | I25: =I18+SUM(I20:I24) -> 35534 | J25: =J18+SUM(J20:J24) -> 47277 | ... M25: =M18+SUM(M20:M24) -> 33411.32
B27: Income tax expense | C27: -360 | D27: -588 | E27: =SUM(F27:I27) -> -648 | F27: -191 | G27: -94 | H27: -137 | I27: -226 | J27: -206 | K27: -129 | L27: 0 | M27: 0
B28: Profit/(loss) after tax | C28: =C25+C27 -> -11506 | D28: =D25+D27 -> 61980 | E28: =E25+E27 -> 156916 | F28: =F25+F27 -> 38041 | G28: =G25+G27 -> 57081 | H28: =H25+H27 -> 30967 | I28: =I25+I27 -> 35308 | J28: =J25+J27 -> 47071 | ... M28: =M25+M27 -> 33411.32
B30: Attributable to owners of non-controlling interest | C30: 14 | D30: 459 | E30: =SUM(F30:I30) -> 44 | F30: -136 | G30: 25 | H30: 208 | I30: -53 | J30: 181 | K30: 143 | L30: 143 | M30: 143
B31: Attributable to the owners of parent | C31: =C28-C30 -> -11520 | D31: =D28-D30 -> 61521 | E31: =SUM(F31:I31) -> 161353 | F31: =F28-F30 -> 38177 | G31: =G28-G30 -> 57056 | H31: =H28-H30 -> 30759 | I31: =I28-I30 -> 35361 | J31: =J28-J30 -> 46890 | K31: =K28-K30 -> 44347 | L31: =L28-L30 -> 27763.6 | M31: =M28-M30 -> 33268.32
B33: Attributable to the owners of parent
B34: Basic earnings/(loss) per share | C34: -0.07 | D34: 0.37 | E34: =SUM(F34:I34) -> 0.98981453 | F34: 0.23 | G34: 0.35 | H34: =H31*1000/H37 -> 0.19018037 | I34: =I31*1000/I37 -> 0.21963417 | J34: =J31*1000/J37 -> 0.29068032 | K34: =K31*1000/K37 -> 0.27481658 | L34: =L31*1000/L37 -> 0.17204992 | M34: =M31*1000/M37 -> 0.20616245
B35: Diluted earnings/(loss) per share | C35: -0.07 | D35: 0.37 | E35: =SUM(F35:I35) -> 0.98933749 | F35: 0.23 | G35: 0.35 | H35: =H31*1000/H38 -> 0.18998527 | I35: =I31*1000/I38 -> 0.21935222 | J35: =J31*1000/J38 -> 0.29047536 | K35: =K31*1000/K38 -> 0.27461738 | L35: =L31*1000/L38 -> 0.1719252 | M35: =M31*1000/M38 -> 0.20601301
B37: Weighted average number of shares (basic) | C37: 169089325 | D37: 164692954 | F37: 162967375 | G37: 163037628 | H37: 161735939 | I37: 160999542 | J37: 161311231 | K37: 161369447 | L37: 161369447 | M37: 161369447
B38: Weighted average number of shares (diluted) | C38: 169089325 | D38: 164850097 | F38: 163249977 | G38: 163172987 | H38: 161902025 | I38: 161206487 | J38: 161425054 | K38: 161486503 | L38: 161486503 | M38: 161486503
A42: x | B42: Operating Days | F42: SCRUBBER | G42: ECO
B43: DHT Mustang | F43: 1 | G43: 1 | H43: 87 | I43: 88 | J43: 88 | K43: 88 | L43: 88 | M43: 88
B44: DHT Bronco | F44: 1 | G44: 1 | H44: 87 | I44: 88 | J44: 88 | K44: 88 | L44: 88 | M44: 88
B45: DHT Colt | F45: 1 | G45: 1 | H45: 87 | I45: 88 | J45: 88 | K45: 88 | L45: 88 | M45: 88
B46: DHT Stallion | F46: 1 | G46: 1 | H46: 87 | I46: 88 | J46: 88 | K46: 88 | L46: 88 | M46: 88
B47: DHT Tiger | F47: 1 | G47: 1 | H47: 87 | I47: 88 | J47: 88 | K47: 88 | L47: 88 | M47: 88
B48: DHT Harrier | F48: 1 | G48: 1 | H48: 87 | I48: 88 | J48: 88 | K48: 88 | L48: 88 | M48: 88
B49: DHT Osprey | F49: 1 | G49: 1 | H49: 87 | I49: 88 | J49: 88 | K49: 88 | L49: 88 | M49: 88
B50: DHT Puma | F50: 1 | G50: 1 | H50: 87 | I50: 88 | J50: 88 | K50: 88 | L50: 88 | M50: 88
B51: DHT Panther | F51: 1 | G51: 1 | H51: 87 | I51: 88 | J51: 88 | K51: 88 | L51: 88 | M51: 88
...

Sheet Balance
B1: DHT (Thousands $) | C1: =D1-1 -> 2021 | D1: 2022 | E1: 2023 | F1: Q1 2023 | G1: Q2 2023 | H1: Q3 2023 | I1: Q4 2023 | J1: Q1 2024 | K1: Q2 2024 | L1: Q3 2024 | M1: Q4 2024
B2: Balance
B3: Current Assets | C3: =SUM(C4:C9) -> 131972 | D3: =SUM(D4:D9) -> 235590 | E3: =SUM(E4:E9) -> 0 | F3: =SUM(F4:F9) -> 213214 | G3: =SUM(G4:G9) -> 234317 | H3: =SUM(H4:H9) -> 179227 | I3: =SUM(I4:I9) -> 200498 | J3: =SUM(J4:J9) -> 203397 | ... M3: =SUM(M4:M9) -> 220988.32
B4: Cash and cash equivalents | C4: 60658 | D4: 125948 | F4: 117549 | G4: 130649 | H4: 73920 | I4: 74738 | J4: 73076 | K4: 72642 | L4: =CashFlow!L62 -> 72468.6 | M4: =CashFlow!M62 -> 97882.32
B5: Accounts receivable and accrued revenues | C5: 30361 | D5: 59465 | F5: 55010 | G5: 56831 | H5: 55684 | I5: 75848 | J5: 80561 | K5: 70355 | L5: 70355 | M5: 70355
B6: Capitalized voyage expenses | C6: 1395 | D6: 2799 | F6: 3487 | G6: 2192 | H6: 2817 | I6: 2549 | J6: 4679 | K6: 6051 | L6: 6051 | M6: 6051
B7: Prepaid expenses | C7: 6162 | D7: 10550 | F7: 9440 | G7: 10287 | H7: 9023 | I7: 13557 | J7: 7650 | K7: 9894 | L7: 9894 | M7: 9894
B8: Derivative financial assets | D8: 3759 | F8: 70 | H8: 0 | I8: 0 | J8: 0 | K8: 0 | L8: 0 | M8: 0
B9: Bunker inventory | C9: 33396 | D9: 33069 | F9: 27658 | G9: 34358 | H9: 37783 | I9: 33806 | J9: 37431 | K9: 36806 | L9: 36806 | M9: 36806
B11: Non-Current Assets | C11: =SUM(C12:C18) -> 1477390 | D11: =SUM(D12:D18) -> 1272886 | E11: =SUM(E12:E18) -> 0 | F11: =SUM(F12:F18) -> 1264323 | G11: =SUM(G12:G18) -> 1255535 | H11: =SUM(H12:H18) -> 1318248 | I11: =SUM(I12:I18) -> 1291725 | J11: =SUM(J12:J18) -> 1268933 | ... M11: =SUM(M12:M18) -> 1240039
B12: Vessels | C12: 1467846 | D12: 1261998 | F12: 1254056 | G12: 1237411 | H12: 1311892 | I12: 1283710 | J12: 1261388 | K12: 1233164 | L12: =K12+'P&L'!L12+Balance!L77 -> 1208786 | M12: =L12+'P&L'!M12+Balance!M77 -> 1180908
B13: Advances for vessels under construction | J13: 43 | K13: 51866 | L13: 51866 | M13: 51866
B14: Advances for vessel upgrades | C14: 372 | D14: 4583 | F14: 4594 | G14: 11369 | H14: 15 | I14: 10 | J14: 160 | K14: 382 | L14: 382 | M14: 382
B15: Other PPE | C15: 3766 | D15: 4949 | F15: 4317 | G15: 5399 | H15: 4985 | I15: 6649 | J15: 5986 | K15: 5527 | L15: 5527 | M15: 5527
B16: Investment in associate company | C16: 5406
B17: Goodwill | D17: 1356 | F17: 1356 | G17: 1356 | H17: 1356 | I17: 1356 | J17: 1356 | K17: 1356 | L17: 1356 | M17: 1356
B18: Derivative financial assets
B20: Total Assets | C20: =SUM(C3+C11) -> 1609362 | D20: =SUM(D3+D11) -> 1508476 | E20: =SUM(E3+E11) -> 0 | F20: =SUM(F3+F11) -> 1477537 | G20: =SUM(G3+G11) -> 1489852 | H20: =SUM(H3+H11) -> 1497475 | I20: =SUM(I3+I11) -> 1492223 | J20: =SUM(J3+J11) -> 1472330 | ... M20: =SUM(M3+M11) -> 1461027.3
B23: Current liabilities | C23: =SUM(C24:C28) -> 41945 | D23: =SUM(D24:D28) -> 64374 | E23: =SUM(E24:E28) -> 0 | F23: =SUM(F24:F28) -> 61243 | G23: =SUM(G24:G28) -> 75160 | H23: =SUM(H24:H28) -> 78755 | I23: =SUM(I24:I28) -> 56605 | J23: =SUM(J24:J28) -> 61723 | ... M23: =SUM(M24:M28) -> 26179
B24: Accounts payable and accrued expenses | C24: 19662 | D24: 29398 | F24: 22020 | G24: 29302 | H24: 25111 | I24: 20493 | J24: 24150 | K24: 21495 | L24: 21495 | M24: 21495
B25: Derivative financial liabilities | C25: 7002 | D25: 29626
B26: Current portion long-term debt | C26: 9792 | D26: 1178 | F26: 33109 | G26: 38947 | H26: 47933 | I26: 30300 | J26: 36161 | K26: 42025
B27: Other current liabilities | C27: 624 | D27: 4172 | F27: 1022 | G27: 1401 | H27: 1317 | I27: 1418 | J27: 1412 | K27: 1437 | L27: 1437 | M27: 1437
B28: Deferred shipping revenues | C28: 4865 | F28: 5092 | G28: 5510 | H28: 4394 | I28: 4394 | J28: 0 | K28: 3247 | L28: 3247 | M28: 3247
B30: Non-Current Liabilities | C30: =SUM(C31:C33) -> 520059 | D30: =SUM(D31:D33) -> 370614 | E30: =SUM(E31:E33) -> 0 | F30: =SUM(F31:F33) -> 365740 | G30: =SUM(G31:G33) -> 353152 | H30: =SUM(H31:H33) -> 392204 | I30: =SUM(I31:I33) -> 403952 | J30: =SUM(J31:J33) -> 366547 | ... M30: =SUM(M31:M33) -> 402270
B31: Long-term debt | C31: 512507 | D31: 367069 | F31: 362616 | G31: 349352 | H31: 388647 | I31: 398425 | J31: 361619 | K31: 372579 | L31: =(K31+K26)-(Debt!$I$7/3) -> 406170 | M31: =(L31+L26)-(Debt!$I$7/3) -> 397736
B32: Derivative financial liabilities | C32: 4222
B33: Other non-current liabilities | C33: 3330 | D33: 3545 | F33: 3124 | G33: 3800 | H33: 3557 | I33: 5527 | J33: 4928 | K33: 4534 | L33: 4534 | M33: 4534
B35: Total Liabilities | C35: =C23+C30 -> 562004 | D35: =D23+D30 -> 434988 | E35: =E23+E30 -> 0 | F35: =F23+F30 -> 426983 | G35: =G23+G30 -> 428312 | H35: =H23+H30 -> 470959 | I35: =I23+I30 -> 460557 | J35: =J23+J30 -> 428270 | ... M35: =M23+M30 -> 428449
B38: Equity | C38: =C40+C47 -> 1047359 | D38: =D40+D47 -> 1073486 | E38: =E40+E47 -> 0 | F38: =F40+F47 -> 1050553 | G38: =G40+G47 -> 1061542 | H38: =H40+H47 -> 1026515 | I38: =I40+I47 -> 1031667 | J38: =J40+J47 -> 1044060 | K38: =K40+K47 -> 1042727 | L38: =K38+'P&L'!L28+CashFlow!L45+CashFlow!L49 -> 1026286.6 | M38: =L38+'P&L'!M28+CashFlow!M45+CashFlow!M49 -> 1031934.3
B40: Total Equity attributable to the Company | C40: =SUM(C41:C46) -> 1047325 | D40: =SUM(D41:D46) -> 1068478 | E40: =SUM(E41:E46) -> 0 | F40: =SUM(F41:F46) -> 1045646 | G40: =SUM(G41:G46) -> 1057276 | H40: =SUM(H41:H46) -> 1022094 | I40: =SUM(I41:I46) -> 1027154 | J40: =SUM(J41:J46) -> 1039438 | K40: =SUM(K41:K46) -> 1037985
B41: Common stock ar par value | C41: 1661 | D41: 1627 | F41: 1630 | G41: 1624 | H41: 1610 | I41: 1610 | J41: 1613 | K41: 1615
B42: Additional paid-in-capital | C42: 1264000 | D42: 1243754 | F42: 1245698 | G42: 1240068 | H42: 1228037 | I42: 1228254 | J42: 1229905 | K42: 1230832
B43: Treasury shares | G43: -2102
B44: Accumulated deficit | C44: -222405 | D44: -180664 | F44: -204422 | G44: -184853 | H44: -210754 | I44: -206477 | J44: -195079 | K44: -197519
B45: Translation differences | C45: 101 | D45: 138 | F45: 173 | G45: 123 | H45: 69 | I45: 201 | J45: 97 | K45: 78
B46: Other reserves | C46: 3968 | D46: 3623 | F46: 2567 | G46: 2416 | H46: 3132 | I46: 3566 | J46: 2902 | K46: 2979
B47: Non-controlling interest | C47: 34 | D47: 5008 | F47: 4907 | G47: 4266 | H47: 4421 | I47: 4513 | J47: 4622 | K47: 4742
B49: Total Equity and Liabilities | C49: =C38+C35 -> 1609363 | D49: =D38+D35 -> 1508474 | E49: =E38+E35 -> 0 | F49: =F38+F35 -> 1477536 | G49: =G38+G35 -> 1489854 | H49: =H38+H35 -> 1497474 | I49: =I38+I35 -> 1492224 | J49: =J38+J35 -> 1472330 | ... M49: =M38+M35 -> 1460383.3
B50: Check | C50: =C20-C49 -> -1 | D50: =D20-D49 -> 2 | F50: =F20-F49 -> 1 | G50: =G20-G49 -> -2 | H50: =H20-H49 -> 1 | I50: =I20-I49 -> -1 | J50: =J20-J49 -> 0 | K50: =K20-K49 -> -1 | L50: =L20-L49 -> 322 | M50: =M20-M49 -> 644
...

Sheet CashFlow
B1: DHT (Thousands $) | C1: =D1-1 -> 2021 | D1: 2022 | E1: 2023 | F1: Q1 2023 | G1: Q2 2023 | H1: Q3 2023 | I1: Q4 2023 | J1: Q1 2024 | K1: Q2 2024 | L1: Q3 2024 | M1: Q4 2024
B2: Cash Flow
B3: Profit/(loss) after tax | C3: ='P&L'!C28 -> -11506 | D3: ='P&L'!D28 -> 61980 | E3: ='P&L'!E28 -> 156916 | F3: ='P&L'!F28 -> 38041 | G3: ='P&L'!G28 -> 57081 | H3: ='P&L'!H28 -> 30967 | I3: ='P&L'!I28 -> 35308 | J3: ='P&L'!J28 -> 47071 | ... M3: ='P&L'!M28 -> 33411.32
B5: items included in net income not affecting cash flows | C5: =SUM(C6:C17) -> 103606 | D5: =SUM(D6:D17) -> 94232 | E5: =SUM(E6:E17) -> 114902 | F5: =SUM(F6:F17) -> 27204 | G5: =SUM(G6:G17) -> 28140 | H5: =SUM(H6:H17) -> 29705 | I5: =SUM(I6:I17) -> 29853 | J5: =SUM(J6:J17) -> 29956 | ... M5: =SUM(M6:M17) -> 28540
B6: D&A | C6: 128639 | D6: 123255 | E6: =SUM(F6:I6) -> 108903 | F6: 25726 | G6: 26376 | H6: 28326 | I6: 28475 | J6: 28250 | K6: =-'P&L'!K12 -> 27878 | L6: =-'P&L'!L12 -> 27878 | M6: =-'P&L'!M12 -> 27878
B7: Impairment charges | E7: =SUM(F7:I7) -> 0
B8: Amortization of upfront fees | C8: 2550 | D8: 2281 | E8: =SUM(F8:I8) -> 0
B9: Amortization of deferred debt issuance cost | D9: 621 | E9: =SUM(F9:I9) -> 2971 | F9: 836 | G9: 722 | H9: 664 | I9: 749 | J9: 680 | K9: 662 | L9: 662 | M9: 662
B10: (Gain)/loss, disposal of PPE | E10: =SUM(F10:I10) -> 17 | F10: 9 | H10: 8 | J10: 0 | K10: 0 | L10: 0 | M10: 0
B11: (Gain)/loss, disposal of vessel | C11: -15153 | D11: -19512 | E11: =SUM(F11:I11) -> 0 | J11: 0 | K11: 0 | L11: 0 | M11: 0
B12: Fair value (gain)/loss on derivative financial instruments | C12: -12450 | D12: -14983 | E12: =SUM(F12:I12) -> 503 | F12: 433 | G12: 70 | J12: 0 | K12: 0 | L12: 0 | M12: 0
B13: Impairment of equity accounted investment | D13: 637 | E13: =SUM(F13:I13) -> 0
B14: Compensation related to options and restricted stock | C14: 4347 | D14: 4133 | E14: =SUM(F14:I14) -> 3233 | F14: 891 | G14: 976 | H14: 716 | I14: 650 | J14: 991 | K14: 1005
B15: Net foreign exchange differences | D15: -204 | E15: =SUM(F15:I15) -> -32 | F15: 2 | G15: -4 | H15: -9 | I15: -21 | J15: 35 | K15: 9
B16: (Gain)/loss modification of debt | C16: -3049 | D16: -669 | E16: =SUM(F16:I16) -> -693 | F16: -693 | J16: 0
B17: Share of profit in associated companies | C17: -1278 | D17: -1327 | E17: =SUM(F17:I17) -> 0
B18: Income adjusted for non-cash items | C18: =C3+C5 -> 92100 | D18: =D3+D5 -> 156212 | E18: =E3+E5 -> 271818 | F18: =F3+F5 -> 65245 | G18: =G3+G5 -> 85221 | H18: =H3+H5 -> 60672 | I18: =I3+I5 -> 65161 | J18: =J3+J5 -> 77027 | ... M18: =M3+M5 -> 61951.32
B20: Changes in operating assets and liabilities: | C20: =SUM(C21:C27) -> -31538 | D20: =SUM(D21:D27) -> -28436 | E20: =SUM(E21:E27) -> -24890 | F20: =SUM(F21:F27) -> 1209 | G20: =SUM(G21:G27) -> 1744 | H20: =SUM(H21:H27) -> -4948 | I20: =SUM(I21:I27) -> -22895 | J20: =SUM(J21:J27) -> -7160 | ... M20: =SUM(M21:M27) -> 0
B21: Accounts receivable and accrued revenues | C21: -301 | D21: -28702 | E21: =SUM(F21:I21) -> -16383 | F21: 4454 | G21: -1820 | H21: 1147 | I21: -20164 | J21: -4713 | K21: 10206
B22: Capitalized voyage expenses | C22: -356 | D22: -1403 | E22: =SUM(F22:I22) -> 250 | F22: -688 | G22: 1295 | H22: -625 | I22: 268 | J22: -2129 | K22: -1373
B23: Prepaid expenses | C23: 523 | D23: -3538 | E23: =SUM(F23:I23) -> -3009 | F23: 1109 | G23: -847 | H23: 1264 | I23: -4535 | J23: 5907 | K23: -2244
B24: Accounts payable and accrued expenses | C24: 1510 | D24: 5641 | E24: =SUM(F24:I24) -> -4938 | F24: -9932 | G24: 9506 | H24: -2214 | I24: -2298 | J24: 1894 | K24: -1626
B25: Deferred shipping revenues | C25: -11372 | D25: -692 | E25: =SUM(F25:I25) -> 222 | F25: 920 | G25: 418 | H25: -1116 | I25: 0 | J25: -4394 | K25: 3247
B26: Bunker inventory | C26: -21542 | D26: 327 | E26: =SUM(F26:I26) -> -737 | F26: 5411 | G26: -6700 | H26: -3425 | I26: 3977 | J26: -3625 | K26: 625
B27: Pension liability | D27: -69 | E27: =SUM(F27:I27) -> -295 | F27: -65 | G27: -108 | H27: 21 | I27: -143 | J27: -100 | K27: -20
B28: Net Cash provided by operating activities | C28: =C18+C20 -> 60562 | D28: =D18+D20 -> 127776 | E28: =E18+E20 -> 246928 | F28: =F18+F20 -> 66454 | G28: =G18+G20 -> 86965 | H28: =H18+H20 -> 55724 | I28: =I18+I20 -> 42266 | J28: =J18+J20 -> 69867 | ... M28: =M18+M20 -> 61951.32
B31: Investment in vessels | C31: -174558 | D31: -9902 | E31: =SUM(F31:I31) -> -128082 | F31: -14829 | G31: -18125 | H31: -92943 | I31: -2185 | J31: -3832 | K31: -798 | L31: =-Balance!L77 -> -3500 | M31: =-Balance!M77 -> 0
B32: Investment in vessels under construction | J32: -43 | K32: -51454
B33: Proceeds from sale of vessels | C33: 87062 | D33: 112399 | E33: =SUM(F33:I33) -> 0 | J33: 0
B34: Investment in subsidiaries | D34: -2 | E34: =SUM(F34:I34) -> 0
B35: Acquisition of subsidiary, net of cash paid | D35: 8267 | E35: =SUM(F35:I35) -> 0
B36: Dividend received from associated company | C36: 1031 | D36: 0 | E36: =SUM(F36:I36) -> 0
B37: Investment in other PPE | C37: -48 | D37: -243 | E37: =SUM(F37:I37) -> -151 | F37: -35 | G37: -10 | H37: -89 | I37: -17 | J37: -3 | K37: -19
B38: Investing Cash Flow | C38: =SUM(C31:C37) -> -86513 | D38: =SUM(D31:D37) -> 110519 | E38: =SUM(E31:E37) -> -128233 | F38: =SUM(F31:F37) -> -14864 | G38: =SUM(G31:G37) -> -18135 | H38: =SUM(H31:H37) -> -93032 | I38: =SUM(I31:I37) -> -2202 | J38: =SUM(J31:J37) -> -3878 | ... M38: =SUM(M31:M37) -> 0
B41: Levered FCF | C41: =C28+C31+C37 -> -114044 | D41: =D28+D31+D37 -> 117631 | E41: =SUM(F41:I41) -> 123176 | F41: =F28+F31+F37 -> 51590 | G41: =G28+G31+G37 -> 68830 | H41: =H28+H31+H37 -> -37308 | I41: =I28+I31+I37 -> 40064 | J41: =J28+J31+J37 -> 66032 | K41: =K28+K31+K37 -> 82042 | L41: =L28+L31+L37 -> 52946.6 | M41: =M28+M31+M37 -> 61951.32
B42: UnLevered FCF | C42: =C41-'P&L'!C22-'P&L'!C21 -> -88323 | D42: =D41-'P&L'!D22-'P&L'!D21 -> 140043 | E42: =E41-'P&L'!E22-'P&L'!E21 -> 151752 | F42: =F41-'P&L'!F22-'P&L'!F21 -> 58778 | G42: =G41-'P&L'!G22-'P&L'!G21 -> 74356 | H42: =H41-'P&L'!H22-'P&L'!H21 -> -29732 | I42: =I41-'P&L'!I22-'P&L'!I21 -> 48350 | J42: =J41-'P&L'!J22-'P&L'!J21 -> 73716 | ... M42: =M41-'P&L'!M22-'P&L'!M21 -> 68872.32
B45: Cash dividends paid | C45: -22083 | D45: -19678 | E45: =SUM(F45:I45) -> -186673 | F45: -61935 | G45: -37487 | H45: -56661 | I45: -30590 | J45: -35492 | K45: -46786 | L45: =-('P&L'!K34*('P&L'!L37/1000)) -> -44347 | M45: =-('P&L'!L34*('P&L'!M37/1000)) -> -27763.6
B46: Dividends paid to non-controlling interest | D46: 0 | E46: =SUM(F46:I46) -> -590 | G46: -590 | I46: 0
B47: Repayment principal element of lease liability | C47: -611 | D47: -1089 | E47: =SUM(F47:I47) -> -1424 | F47: -386 | G47: -350 | H47: -346 | I47: -342 | J47: -340 | K47: -340 | L47: -340 | M47: -340
B48: Issuance of long-term debt | C48: 355840 | D48: 4008 | E48: =SUM(F48:I48) -> 339633 | F48: 216399 | G48: -208 | H48: 99492 | I48: 23950 | J48: 49999 | K48: 25000 | L48: 0 | M48: 0
...

Sheet Debt
B1: Debt Analyse Thousands € | C1: Date | D1: Maturity | E1: Fixed | F1: Variable | G1: Pending | H1: Q1 2024 | I1: Q2-Q4 2024 | J1: 2025 | K1: 2026 | L1: Thereafter
B2: Credit Agricole Credit Facility | E2: 0.0205 | F2: =$C$22 -> 0.05 | H2: 625 | I2: 1875 | J2: 2500 | K2: 2500 | L2: 27500
B3: Danish Ship Finance Credit Facility | E3: 0.02 | F3: =$C$22 -> 0.05 | I3: 2427 | J3: 26693 | L3: 0
B4: ING Credit Facility | E4: 0.019 | F4: =$C$22 -> 0.05 | H4: 6250 | I4: 18750 | J4: 25000 | K4: 25000 | L4: 160150
B5: ING Credit Facility | E5: 0.018 | F5: =$C$22 -> 0.05 | H5: 750 | I5: 2250 | J5: 3000 | K5: 3000 | L5: 35250
B6: Nordea Credit Facility | E6: =1.9% + 0.26% -> 0.0216 | F6: =$C$22 -> 0.05 | H6: 0 | J6: 23715 | K6: 23715 | L6: 46091
B7: Total paid | H7: =SUM(H2:H6) -> 7625 | I7: =SUM(I2:I6) -> 25302 | J7: =SUM(J2:J6) -> 80908 | K7: =SUM(K2:K6) -> 54215 | L7: =SUM(L2:L6) -> 268991 | M7: =SUM(M2:M6) -> 0 | N7: =SUM(N2:N6) -> 0 | O7: =SUM(O2:O6) -> 0 | ... U7: =SUM(U2:U6) -> 0
B8: Pending Debt | G8: 428726 | H8: =G8-H7 -> 421101 | I8: =H8-I7 -> 395799 | J8: =I8-J7 -> 314891 | K8: =J8-K7 -> 260676 | L8: =K8-L7 -> -8315 | M8: =L8-M7 -> -8315 | N8: =M8-N7 -> -8315 | O8: =N8-O7 -> -8315 | ... T8: =S8-T7 -> -8315
B9: Fees Ban Loan | G9: 8315
A12: x | B12: Interest Analyse Thousands € | C12: Date | D12: Maturity | E12: Fixed | F12: Variable | G12: Pending | H12: Q1 2024 | I12: Q2-Q4 2024 | J12: 2025 | K12: =J12+1 -> 2026 | L12: Thereafter
B13: Credit Agricole Credit Facility | E13: 0.0205 | F13: =$C$22 -> 0.05 | G13: =SUM(H2:L2) -> 35000 | H13: =(($E$13+$F$13)*($G$13-SUM($H$2:H2)))/4 -> 605.85938 | I13: =(($E$13+$F$13)*($G$13-SUM($H$2:I2)))-H13 -> 1685.3906 | J13: =(($E$13+$F$13)*($G$13-SUM($H$2:J2))) -> 2115 | K13: =(($E$13+$F$13)*($G$13-SUM($H$2:K2))) -> 1938.75 | L13: =(($E$13+$F$13)*($G$13-SUM($H$2:L2))) -> 0
B14: Danish Ship Finance Credit Facility | E14: =1.9% + 0.26% -> 0.0216 | F14: =$C$22 -> 0.05 | G14: =SUM(H3:L3) -> 29120 | H14: =(($E$14+$F$14)*($G$14-SUM($H$3:H3)))/4 -> 521.248 | I14: =(($E$14+$F$14)*($G$14-SUM($H$3:I3)))-H14 -> 1389.9708 | J14: =(($E$14+$F$14)*($G$14-SUM($H$3:J3))) -> 0 | K14: =(($E$14+$F$14)*($G$14-SUM($H$3:K3))) -> 0 | L14: =(($E$14+$F$14)*($G$14-SUM($H$3:L3))) -> 0
B15: ING Credit Facility | E15: 0.019 | F15: =$C$22 -> 0.05 | G15: =SUM(H4:L4) -> 235150 | H15: =(($E$15+$F$15)*($G$15-SUM($H$4:H4)))/4 -> 3948.525 | I15: =(($E$15+$F$15)*($G$15-SUM($H$4:I4)))-H15 -> 10551.825 | J15: =(($E$15+$F$15)*($G$15-SUM($H$4:J4))) -> 12775.35 | K15: =(($E$15+$F$15)*($G$15-SUM($H$4:K4))) -> 11050.35 | L15: =(($E$15+$F$15)*($G$15-SUM($H$4:L4))) -> 0
B16: ING Credit Facility | E16: 0.018 | F16: =$C$22 -> 0.05 | G16: =SUM(H5:L5) -> 44250 | H16: =(($E$16+$F$16)*($G$16-SUM($H$5:H5)))/4 -> 739.5 | I16: =(($E$16+$F$16)*($G$16-SUM($H$5:I5)))-H16 -> 2065.5 | J16: =(($E$16+$F$16)*($G$16-SUM($H$5:J5))) -> 2601 | K16: =(($E$16+$F$16)*($G$16-SUM($H$5:K5))) -> 2397 | L16: =(($E$16+$F$16)*($G$16-SUM($H$5:L5))) -> 0
B17: Nordea Credit Facility | E17: =1.9% + 0.26% -> 0.0216 | F17: =$C$22 -> 0.05 | G17: =SUM(H6:L6) -> 93521 | H17: =(($E$17+$F$17)*($G$17-SUM($H$6:H6)))/4 -> 1674.0259 | I17: =((($E$17+$F$17)*($G$17-SUM($H$6:I6))))-H17 -> 5022.0777 | J17: =(($E$17+$F$17)*($G$17-SUM($H$6:J6))) -> 4998.1096 | K17: =(($E$17+$F$17)*($G$17-SUM($H$6:K6))) -> 3300.1156 | L17: =(($E$17+$F$17)*($G$17-SUM($H$6:L6))) -> 0
B18: Total: | H18: =SUM(H13:H17) -> 7489.1583 | I18: =SUM(I13:I17) -> 20714.764 | J18: =SUM(J13:J17) -> 22489.46 | K18: =SUM(K13:K17) -> 18686.216 | L18: =SUM(L13:L17) -> 0 | M18: =SUM(M13:M17) -> 0 | N18: =SUM(N13:N17) -> 0 | O18: =SUM(O13:O17) -> 0 | ... T18: =SUM(T13:T17) -> 0
B22: SOFR: | C22: =[1]Exchange!$E$3 -> 0.05

Sheet Notes
B1: WEB
B35: Q3 2023
B82: Presentation Q3 2023
K94: 17/01/24: Sacan update bajando su cash breakeven rates a $18600 y a 13800 en spot
B108: Interesting geneal information
B177: Q4 2023
B340: Press release 28/02/24
B359: 20-F 2023
B386: Q1 2024
B497: Update 11/07/24
B514: Q2 2024

Sheet Dudas
