Workbook

Sheet Cover
A3: DHT | F3: Copyright:
A4: Crude oil tanker company | F4: Tankers & Dry Bulks
A5: VLCC segment | F5: shippingupmore.com
F6: info@shippingupmore.com
A10: DISCLAIMER
A11: The financial models and projections provided herein are based on internal assumptions, historical data, and current market trends (such as charter rates, fuel costs, and vessel valuations) which are subject to high volatility and change without notice.
A12: These models are intended for illustrative and informational purposes only. They do not constitute financial, investment, or legal advice. While we strive for accuracy, we make no guarantees regarding the future performance of any asset or the realization of the projected returns.
A16: General Colours in Financial Data
A17: In green: | B17: Data copied from last quarter or reported by company
A18: In blue: | B18: Our own assumption
A19: In black: | B19: Automatically filled
A20: In yellow | B20: You should only change yellow cells
A24: NAV Content
A25: Fleet list: | B25: Vessel name, type of vessel, year built, Yard, Country, scrubber, neutral value and corrected value by country coefficient
A26: Price to update: | B26: Share price, that it´s update from Master
A27: NAV calculation: | B27: Net Asset Value calculation
A28: Adjusted fleet value: | B28: Change it if you think the value is going up or down. Default we leave it in 1.
A29: Value growth in %: | B29: Change in value between quarters
A30: Scrubbers: | B30: How many scrubbers are installed in the vessels, reported by the company.
A31: Fleet : | B31: How many vessels has the company
A32: % Fleet with scrubber: | B32: As it titles says, % fleet with scrubber
A33: TCE: | B33: Time Charter Equivalent, based in data reported by the company or own assumptions
A34: Financial data: | B34: Market Cap, Enterprise Value, Adjusted Earnings, Adjusted EBITDA, Levered FCF, Adjusted P/E, Adjusted EV/EBITDA and P/FCF
A35: Linear Estimation: | B35: Don´t remove or change this data. It´s to automatically calculate vessels value from the Master
A36: Value added by country: | B36: Correction factor depending on the country of construction
A38: Fleet colours by status:
A39: No color: | B39: In the fleet list
A40: Red: | B40: Sold vessel reported by the company
A41: Orange: | B41: Acquired vessel reported by the company
A45: P&L Content
A46: P&L from company reports
A47: Operating days: | B47: You can change it on your own
A48: TCE revenue per vessel: | B48: Operating days x TCE assumption
A49: P&L Notes
A50: Estimating revenues are from TCE and operating days. For that reason, operating expenses is in grey background. We prepare the TCE revenues looking at what the company say about it.
A54: BALANCE Content
A55: Balance from company reports
A56: Debt: | B56: Debt - Cash
A57: Working Capital: | B57: Working Capital calculation
A58: CapEx: | B58: CapEx Assumption that you can change on your own
...

Sheet NAV
B1: Vessel | C1: DWT | D1: Yard | E1: Country | F1: Ownership | G1: Built | H1: Age ´26 | I1: Value ´26 | J1: Plus Coef. | K1: Scrub. | L1: Empl. | N1: Price:
B2: DHT Mustang | C2: VLCC | D2: Hyundai | E2: S. Korea | F2: 1 | G2: 43101 | H2: =(TODAY()-G2)/365 -> 8.3506849 | I2: =$C$42*H2^3+$F$42*H2^2+$G$42*H2+$H$42 -> 110.93636 | J2: =I2*$C$45 -> 119.81127 | K2: 1 | L2: Spot | N2: ='[1]Stock Valuation'!$C$10 -> 18.86
B3: DHT Bronco | C3: VLCC | D3: Hyundai | E3: S. Korea | F3: 1 | G3: 43101 | H3: =(TODAY()-G3)/365 -> 8.3506849 | I3: =$C$42*H3^3+$F$42*H3^2+$G$42*H3+$H$42 -> 110.93636 | J3: =I3*$C$45 -> 119.81127 | K3: 1 | L3: Spot
B4: DHT Colt | C4: VLCC | D4: Daewoo | E4: S. Korea | F4: 1 | G4: 43101 | H4: =(TODAY()-G4)/365 -> 8.3506849 | I4: =$C$42*H4^3+$F$42*H4^2+$G$42*H4+$H$42 -> 110.93636 | J4: =I4*$C$45 -> 119.81127 | K4: 1 | L4: Spot | N4: Net Asset Value | O4: Q2 2023 | P4: Q3 2023 | Q4: Q4 2023 | R4: Q1 2024 | S4: Q2 2024 | T4: Q3 2024 | U4: Q4 2024 | V4: Q1 2025 | W4: Q2 2025 | X4: Q3 2025 | Y4: Q4 2025 | Z4: Q1 2026 | AA4: Q2 2026 | AB4: Q3 2026 | AC4: Q4 2026 | AD4: Q1 2027
B5: DHT Stallion | C5: VLCC | D5: Daewoo | E5: S. Korea | F5: 1 | G5: 43101 | H5: =(TODAY()-G5)/365 -> 8.3506849 | I5: =$C$42*H5^3+$F$42*H5^2+$G$42*H5+$H$42 -> 110.93636 | J5: =I5*$C$45 -> 119.81127 | K5: 1 | L5: Spot | N5: Fleet Value | O5: 1809.9 | P5: 1809.9 | Q5: 1809.9 | R5: 1784.23 | S5: 1965.46 | T5: 1828.23 | U5: 1758.13 | V5: 1648.63 | W5: 1570.75 | X5: 1592.41 | Y5: 1694.96 | Z5: 2387.56 | AA5: =AA21*(SUM($J$2:$J$24)) -> 2565.9783 | AB5: =AB21*(SUM($J$2:$J$24)) -> 2565.9783 | AC5: =AC21*(SUM($J$2:$J$24)) -> 2553.1484 | AD5: =AD21*(SUM($J$2:$J$24)) -> 2540.3185
B6: DHT Tiger | C6: VLCC | D6: Hyundai | E6: S. Korea | F6: 1 | G6: 42736 | H6: =(TODAY()-G6)/365 -> 9.3506849 | I6: =$C$42*H6^3+$F$42*H6^2+$G$42*H6+$H$42 -> 106.3659 | J6: =I6*$C$45 -> 114.87517 | K6: 1 | L6: Spot | N6: Financial Debt | O6: =-Balance!D45/1000 -> -388.299 | P6: =-Balance!E45/1000 -> -436.58 | Q6: =-Balance!F45/1000 -> -428.725 | R6: =-Balance!G45/1000 -> -397.78 | S6: =-Balance!H45/1000 -> -414.604 | T6: =-Balance!I45/1000 -> -407.629 | U6: =-Balance!J45/1000 -> -409.424 | V6: =-Balance!K45/1000 -> -364.072 | ... AD6: =-Balance!S45/1000 -> -400.696
B7: DHT Harrier | C7: VLCC | D7: Daewoo | E7: S. Korea | F7: 1 | G7: 42370 | H7: =(TODAY()-G7)/365 -> 10.353425 | I7: =$C$42*H7^3+$F$42*H7^2+$G$42*H7+$H$42 -> 101.43858 | J7: =I7*$C$45 -> 109.55367 | K7: 1 | L7: Q4 ´30 | N7: Cash | O7: =Balance!D3/1000 -> 130.649 | P7: =Balance!E3/1000 -> 73.92 | Q7: =Balance!F3/1000 -> 74.738 | R7: =Balance!G3/1000 -> 73.076 | S7: =Balance!H3/1000 -> 72.642 | T7: =Balance!I3/1000 -> 73.829 | U7: =Balance!J3/1000 -> 78.143 | V7: =Balance!K3/1000 -> 80.51 | ... AD7: =Balance!S3/1000 -> 124.25802
B8: DHT Osprey | C8: VLCC | D8: Daewoo | E8: S. Korea | F8: 1 | G8: 42370 | H8: =(TODAY()-G8)/365 -> 10.353425 | I8: =$C$42*H8^3+$F$42*H8^2+$G$42*H8+$H$42 -> 101.43858 | J8: =I8*$C$45 -> 109.55367 | K8: 1 | L8: Q2 ´27 | N8: Payments on NB | O8: =Balance!D13/1000 -> 0 | P8: =Balance!E13/1000 -> 0 | Q8: =Balance!F13/1000 -> 0 | R8: =Balance!G13/1000 -> 0.043 | S8: =Balance!H13/1000 -> 51.866 | T8: =Balance!I13/1000 -> 78.87 | U8: =Balance!J13/1000 -> 93.178 | V8: =Balance!K13/1000 -> 120.679 | ... AD8: =Balance!S13/1000 -> 55.676
B9: DHT Puma | C9: VLCC | D9: Hyundai | E9: S. Korea | F9: 1 | G9: 42370 | H9: =(TODAY()-G9)/365 -> 10.353425 | I9: =$C$42*H9^3+$F$42*H9^2+$G$42*H9+$H$42 -> 101.43858 | J9: =I9*$C$45 -> 109.55367 | K9: 1 | L9: Q1 ´27 | N9: Bunker
B10: DHT Panther | C10: VLCC | D10: Hyundai | E10: S. Korea | F10: 1 | G10: 42370 | H10: =(TODAY()-G10)/365 -> 10.353425 | I10: =$C$42*H10^3+$F$42*H10^2+$G$42*H10+$H$42 -> 101.43858 | J10: =I10*$C$45 -> 109.55367 | K10: 1 | L10: Spot | N10: Working Capital | O10: =Balance!D53/1000 -> 85.426 | P10: =Balance!E53/1000 -> 80.691 | Q10: =Balance!F53/1000 -> 107.828 | R10: =Balance!G53/1000 -> 112.714 | S10: =Balance!H53/1000 -> 156.583 | T10: =Balance!I53/1000 -> 166.961 | U10: =Balance!J53/1000 -> 169.542 | V10: =Balance!K53/1000 -> 189.105 | ... AD10: =Balance!S53/1000 -> 152.722
B11: DHT Lion | C11: VLCC | D11: Hyundai | E11: S. Korea | F11: 1 | G11: 42370 | H11: =(TODAY()-G11)/365 -> 10.353425 | I11: =$C$42*H11^3+$F$42*H11^2+$G$42*H11+$H$42 -> 101.43858 | J11: =I11*$C$45 -> 109.55367 | K11: 1 | L11: Spot | N11: Scrubbers | O11: =COUNT(K2:K19)*2 -> 36 | P11: =O11 -> 36 | Q11: 48 | R11: 48 | S11: 48 | T11: 48 | U11: 36 | V11: =(COUNT($K$2:$K$19)-1)*1.5 -> 25.5 | W11: =(COUNT($K$2:$K$19)-1)*1.5 -> 25.5 | X11: =(COUNT($K$2:$K$19)-1)*1.5 -> 25.5 | Y11: =(COUNT($K$2:$K$19)-1)*1.5 -> 25.5 | Z11: =Z23*1.5 -> 34.5 | AA11: =AA23*1.5 -> 36 | AB11: =AB23*1.5 -> 34.5 | AC11: =AC23*1.5 -> 34.5 | AD11: =AD23*1.5 -> 34.5
B12: DHT Leopard | C12: VLCC | D12: Hyundai | E12: S. Korea | F12: 1 | G12: 42370 | H12: =(TODAY()-G12)/365 -> 10.353425 | I12: =$C$42*H12^3+$F$42*H12^2+$G$42*H12+$H$42 -> 101.43858 | J12: =I12*$C$45 -> 109.55367 | K12: 1 | L12: Q4 ´27 | N12: Net Assets | O12: =SUM(O5:O11) -> 1673.676 | P12: =SUM(P5:P11) -> 1563.931 | Q12: =SUM(Q5:Q11) -> 1611.741 | R12: =SUM(R5:R11) -> 1620.283 | S12: =SUM(S5:S11) -> 1879.947 | T12: =SUM(T5:T11) -> 1788.261 | U12: =SUM(U5:U11) -> 1725.569 | V12: =SUM(V5:V11) -> 1700.352 | ... AD12: =SUM(AD5:AD11) -> 2506.7786
B13: DHT Jaguar | C13: VLCC | D13: Hyundai | E13: S. Korea | F13: 1 | G13: 42005 | H13: =(TODAY()-G13)/365 -> 11.353425 | I13: =$C$42*H13^3+$F$42*H13^2+$G$42*H13+$H$42 -> 96.236893 | J13: =I13*$C$45 -> 103.93584 | K13: 1 | L13: Spot
B14: DHT Opal | C14: VLCC | D14: Daewoo | E14: S. Korea | F14: 1 | G14: 40909 | H14: =(TODAY()-G14)/365 -> 14.356164 | I14: =$C$42*H14^3+$F$42*H14^2+$G$42*H14+$H$42 -> 79.445843 | J14: =I14*$C$45 -> 85.801511 | K14: 1 | L14: Q1 ´27 | N14: Shares Outstanding | O14: ='P&L'!I40/1000000 -> 163.17299 | P14: ='P&L'!J40/1000000 -> 161.90203 | Q14: ='P&L'!K40/1000000 -> 161.20649 | R14: ='P&L'!L40/1000000 -> 161.42505 | S14: ='P&L'!M40/1000000 -> 161.4865 | T14: ='P&L'!N40/1000000 -> 161.55319 | U14: ='P&L'!O40/1000000 -> 161.34744 | V14: ='P&L'!P40/1000000 -> 160.55881 | ... AD14: ='P&L'!X40/1000000 -> 161.21597
B15: DHT Sundarbans | C15: VLCC | D15: Hyundai | E15: S. Korea | F15: 1 | G15: 40909 | H15: =(TODAY()-G15)/365 -> 14.356164 | I15: =$C$42*H15^3+$F$42*H15^2+$G$42*H15+$H$42 -> 79.445843 | J15: =I15*$C$45 -> 85.801511 | K15: 1 | L15: Q1 ´27
B16: DHT Taiga | C16: VLCC | D16: Hyundai | E16: S. Korea | F16: 1 | G16: 40909 | H16: =(TODAY()-G16)/365 -> 14.356164 | I16: =$C$42*H16^3+$F$42*H16^2+$G$42*H16+$H$42 -> 79.445843 | J16: =I16*$C$45 -> 85.801511 | K16: 1 | L16: Spot | N16: Net Asset Value $/sh | O16: =O12/O14 -> 10.257065 | P16: =P12/P14 -> 9.6597371 | Q16: =Q12/Q14 -> 9.997991 | R16: =R12/R14 -> 10.03737 | S16: =S12/S14 -> 11.641512 | T16: =T12/T14 -> 11.069178 | U16: =U12/U14 -> 10.69474 | V16: =V12/V14 -> 10.590213 | ... AD16: =AD12/AD14 -> 15.549195
B17: DHT Amazon | C17: VLCC | D17: Hyundai | E17: S. Korea | F17: 1 | G17: 40544 | H17: =(TODAY()-G17)/365 -> 15.356164 | I17: =$C$42*H17^3+$F$42*H17^2+$G$42*H17+$H$42 -> 73.648684 | J17: =I17*$C$45 -> 79.540579 | K17: 1 | L17: Spot | N17: Más DIVI | Q17: 0.15 | R17: 0.22 | S17: 0.29 | T17: 0.27 | U17: 0.22 | V17: ='P&L'!O35 -> 0.34063452 | W17: 0.15 | X17: 0.24 | Y17: 0.18 | Z17: ='P&L'!S35 -> 0.41087838 | AA17: 0.64 | AB17: ='P&L'!U45 -> 1.1455937 | AC17: ='P&L'!V45 -> 1.1536196 | AD17: ='P&L'!W45 -> 1.0792957
B18: DHT Redwood | C18: VLCC | D18: Hyundai | E18: S. Korea | F18: 1 | G18: 40544 | H18: =(TODAY()-G18)/365 -> 15.356164 | I18: =$C$42*H18^3+$F$42*H18^2+$G$42*H18+$H$42 -> 73.648684 | J18: =I18*$C$45 -> 79.540579 | K18: 1 | L18: Spot | N18: P / NAV | Z18: =SUM($N$2/(Z16)) -> 1.3505312 | AA18: =SUM($N$2/(AA16+AA17)) -> 1.1623865 | AB18: =SUM($N$2/(AB16+AB17)) -> 1.1166396 | AC18: =SUM($N$2/(AC16+AC17)) -> 1.1156794 | AD18: =SUM($N$2/(AD16+AD17)) -> 1.1341979
B19: DHT Appaloosa | C19: VLCC | D19: Hyundai | E19: S. Korea | F19: 1 | G19: 43101 | H19: =(TODAY()-G19)/365 -> 8.3506849 | I19: =$C$42*H19^3+$F$42*H19^2+$G$42*H19+$H$42 -> 110.93636 | J19: =I19*$C$45 -> 119.81127 | K19: 1 | L19: Q2 ´32
B20: DHT Nokota | C20: VLCC | D20: Hyundai | E20: S. Korea | F20: 1 | G20: 43101 | H20: =(TODAY()-G20)/365 -> 8.3506849 | I20: =$C$42*H20^3+$F$42*H20^2+$G$42*H20+$H$42 -> 110.93636 | J20: =I20*$C$45 -> 119.81127 | K20: 1 | L20: Spot
B21: DHT Antelope | C21: VLCC | D21: Hanwha | E21: S. Korea | F21: 1 | G21: 46054 | H21: =(TODAY()-G21)/365 -> 0.26027397 | I21: =$C$42*H21^3+$F$42*H21^2+$G$42*H21+$H$42 -> 128.44654 | J21: =I21*$C$45 -> 138.72226 | K21: 1 | L21: Spot | N21: Asjusted Fleet Value | Z21: 1 | AA21: 1 | AB21: 1 | AC21: 0.995 | AD21: 0.99
B22: DHT Addax | C22: VLCC | D22: Hanwha | E22: S. Korea | F22: 1 | G22: 46082 | H22: =(TODAY()-G22)/365 -> 0.18356164 | I22: =$C$42*H22^3+$F$42*H22^2+$G$42*H22+$H$42 -> 128.39368 | J22: =I22*$C$45 -> 138.66517 | K22: 1 | L22: Spot | N22: Value Growth in % | Z22: =Z5/Y5-1 -> 0.40862321 | AA22: =AA5/Z5-1 -> 0.074728306 | AB22: =AB5/AA5-1 -> 0 | AC22: =AC5/AB5-1 -> -0.005 | AD22: =AD5/AC5-1 -> -0.0050251256
B23: DHT Gazelle | C23: VLCC | D23: Hyundai | E23: S. Korea | F23: 1 | G23: 46082 | H23: =(TODAY()-G23)/365 -> 0.18356164 | I23: =$C$42*H23^3+$F$42*H23^2+$G$42*H23+$H$42 -> 128.39368 | J23: =I23*$C$45 -> 138.66517 | K23: 1 | L23: Q1 ´31 | N23: Scrubber | Z23: 23 | AA23: =COUNT($K$2:$K$24)+K33 -> 24 | AB23: =COUNT($K$2:$K$24) -> 23 | AC23: =COUNT($K$2:$K$24) -> 23 | AD23: =COUNT($K$2:$K$24) -> 23
B24: DHT Impala | C24: VLCC | D24: Hyundai | E24: S. Korea | F24: 1 | G24: 46174 | H24: =(TODAY()-G24)/365 -> -0.068493151 | I24: =$C$42*H24^3+$F$42*H24^2+$G$42*H24+$H$42 -> 128.18461 | J24: =I24*$C$45 -> 138.43938 | K24: 1 | L24: TBD | N24: Fleet | Z24: 23 | AA24: =COUNT($H$2:$H$33) -> 24 | AB24: =COUNT($H$2:$H$24) -> 23 | AC24: =COUNT($H$2:$H$24) -> 23 | AD24: =COUNT($H$2:$H$24) -> 23
N25: % Fleet with scrubber | Z25: =(Z24/Z23) -> 1 | AA25: =(AA24/AA23) -> 1 | AB25: =(AB24/AB23) -> 1 | AC25: =(AC24/AC23) -> 1 | AD25: =(AD24/AD23) -> 1
N27: TCE | O27: 56300 | P27: 42500 | Q27: =42800 -> 42800 | R27: 50900 | S27: 49100 | T27: 42400 | U27: 38800 | V27: 38200 | W27: 46300 | X27: 40500 | Y27: 60300 | Z27: 78800 | AA27: =113500 -> 113500 | AB27: =AA27*1.02 -> 115770 | AC27: =AB27*0.95 -> 109981.5 | AD27: =AC27*0.8 -> 87985.2
B28: DHT Scandinavia | C28: VLCC | F28: 1 | G28: 38718 | K28: 1 | N28: Spot | Z28: 14 | AA28: =COUNTIF($L$2:$L$33, "Spot") -> 14 | AB28: =COUNTIF($L$2:$L$33, "Spot") -> 14 | AC28: =COUNTIF($L$2:$L$33, "Spot") -> 14 | AD28: =COUNTIF($L$2:$L$33, "Spot") -> 14
B29: DHT Lotus | C29: VLCC | F29: 1 | G29: 40544 | K29: 1 | N29: % Spot | Z29: =Z28/Z24 -> 0.60869565 | AA29: =AA28/AA24 -> 0.58333333 | AB29: =AB28/AB24 -> 0.60869565 | AC29: =AC28/AC24 -> 0.60869565 | AD29: =AD28/AD24 -> 0.60869565
B30: DHT Peony | C30: VLCC | F30: 1 | G30: 40544 | K30: 1
B31: DHT China | C31: VLCC | F31: 1 | G31: 39083 | K31: 1 | N31: *in millions USD, except multiples | AC31: FY 2026 | AD31: NTM
B32: DHT Europe | C32: VLCC | F32: 1 | G32: 39083 | K32: 1 | N32: Market Value | AC32: =$N$2*AC14 -> 3040.5332 | AD32: =$N$2*AD14 -> 3040.5332
B33: DHT Bauhinia | C33: VLCC | D33: Daewoo | E33: S. Korea | F33: 1 | G33: 39083 | H33: =(TODAY()-G33)/365 -> 19.358904 | K33: 1 | L33: Q2 ´26 | N33: EV | AC33: =AC32-AC6-AC7-AC8 -> 3241.6105 | AD33: =AD32-AD6-AD7-AD8 -> 3261.2952
N34: Diluted Adj. EPS | AC34: =SUM('P&L'!T45:W45) -> 4.0269125 | AD34: =SUM('P&L'!U45:X45) -> 4.175374
N35: Adj. EBITDA | AC35: =SUM('P&L'!T19:W19)/1000 -> 767.2896 | AD35: =SUM('P&L'!U19:X19)/1000 -> 792.21697
B36: Sold | N36: Dividend | AC36: =SUM(Z17:AC17) -> 3.3500917 | AD36: =SUM(AA17:AD17) -> 4.018509
B37: Acquired | N37: FCF | AC37: =SUM(CashFlow!T41:W41)/1000 -> 639.8256 | AD37: =SUM(CashFlow!U41:X41)/1000 -> 698.21697
N38: Adjusted P/E | AC38: =$N$2/AC34 -> 4.6834889 | AD38: =$N$2/AD34 -> 4.5169606
N39: EV/Adj. EBITDA | AC39: =AC33/AC35 -> 4.2247549 | AD39: =AD33/AD35 -> 4.1166691
N40: P/FCF | AC40: =N2/(AC37/AC14) -> 4.752128 | AD40: =O2/(AD37/AD14) -> 0
B41: Linear Estimation: | N41: Dividend Yield | AC41: =AC36/$N$2 -> 0.17762946 | AD41: =AD36/$N$2 -> 0.21307047
...

Sheet P&L
B1: DHT (Thousands $) | C1: =D1-1 -> 2021 | D1: 2022 | E1: 2023 | F1: 2024 | G1: 2025 | H1: Q1 2023 | I1: Q2 2023 | J1: Q3 2023 | K1: Q4 2023 | L1: Q1 2024 | M1: Q2 2024 | N1: Q3 2024 | O1: Q4 2024 | P1: Q1 2025 | Q1: Q2 2025 | R1: Q3 2025 | S1: Q4 2025 | T1: Q1 2026 | U1: Q2 2026 | V1: Q3 2026 | W1: Q4 2026 | X1: Q1 2027
B2: Shipping Revenues | C2: 295853 | D2: 450382 | E2: =SUM(H2:K2) -> 556075 | F2: =SUM(L2:O2) -> 567835 | G2: =SUM(P2:S2) -> 497197 | H2: 131468 | I2: 151993 | J2: 130322 | K2: 142292 | L2: 145876 | M2: 150066 | N2: 141125 | O2: 130768 | P2: 118165 | Q2: 127950 | R2: 107151 | S2: 143931 | T2: 186285 | U2: =SUM(U81:U109)/1000 -> 238350 | V2: =SUM(V81:V109)/1000 -> 239643.9 | W2: =SUM(W81:W109)/1000 -> 227661.7 | X2: =SUM(X81:X109)/1000 -> 182129.36
B3: Other revenues | D3: 3765 | F3: =SUM(L3:O3) -> 3938 | G3: =SUM(P3:S3) -> 1204 | H3: 1100 | I3: 1054 | J3: 1243 | K3: 1084 | L3: 1162 | M3: 1171 | N3: 982 | O3: 623 | P3: 409 | Q3: 366 | R3: 197 | S3: 232 | T3: 191 | U3: 191 | V3: 191 | W3: 191 | X3: 191
B4: Total Revenues | C4: =SUM(C2:C3) -> 295853 | D4: =SUM(D2:D3) -> 454147 | E4: =SUM(E2:E3) -> 556075 | F4: =SUM(F2:F3) -> 571773 | G4: =SUM(G2:G3) -> 498401 | H4: =SUM(H2:H3) -> 132568 | I4: =SUM(I2:I3) -> 153047 | J4: =SUM(J2:J3) -> 131565 | ... X4: =SUM(X2:X3) -> 182320.36
B6: Other income | C6: 4612 | D6: 0 | E6: 0 | F6: 0 | G6: 0
B8: Operating expenses
B9: Voyage expenses | C9: -92405 | D9: -185502 | E9: =SUM(H9:K9) -> -165667 | F9: =SUM(L9:O9) -> -179624 | G9: =SUM(P9:S9) -> -128087 | H9: -37569 | I9: -39092 | J9: -41235 | K9: -47771 | L9: -39537 | M9: -46370 | N9: -48484 | O9: -45233 | P9: -38828 | Q9: -35131 | R9: -28047 | S9: -26081 | T9: -29083
B10: Vessel operating expenses | C10: -77807 | D10: -73808 | E10: =SUM(H10:K10) -> -75430 | F10: =SUM(L10:O10) -> -78593 | G10: =SUM(P10:S10) -> -72995 | H10: -18417 | I10: -19687 | J10: -18608 | K10: -18718 | L10: -19172 | M10: -20393 | N10: -19048 | O10: -19980 | P10: -17828 | Q10: -19605 | R10: -18436 | S10: -17126 | T10: -19126 | U10: -19126 | V10: -19126 | W10: -19126 | X10: -19126
B11: D&A | C11: -128639 | D11: -123255 | E11: =SUM(H11:K11) -> -108903 | F11: =SUM(L11:O11) -> -111884 | G11: =SUM(P11:S11) -> -106369 | H11: -25726 | I11: -26376 | J11: -28326 | K11: -28475 | L11: -28250 | M11: -27878 | N11: -28135 | O11: -27621 | P11: -27270 | Q11: -26139 | R11: -25969 | S11: -26991 | T11: -25647 | U11: -25647 | V11: -25647 | W11: -25647 | X11: -25647
B12: Impairment charges | C12: 0 | E12: =SUM(H12:K12) -> 0 | F12: =SUM(L12:O12) -> 0 | G12: =SUM(P12:S12) -> 0
B13: Gain/(loss) sale of vessels | C13: 15153 | D13: 19512 | E13: =SUM(H13:K13) -> 0 | F13: =SUM(L13:O13) -> 27909 | G13: =SUM(P13:S13) -> 53912 | O13: 27909 | P13: 19795 | Q13: 17459 | R13: =15688+970 -> 16658 | T13: 59994 | U13: 34200
B14: G&A | C14: -16565 | D14: -16890 | E14: =SUM(H14:K14) -> -17448 | F14: =SUM(L14:O14) -> -18943 | G14: =SUM(P14:S14) -> -19890 | H14: -4637 | I14: -4515 | J14: -4303 | K14: -3993 | L14: -4664 | M14: -4521 | N14: -4169 | O14: -5589 | P14: -5548 | Q14: -4587 | R14: -4132 | S14: -5623 | T14: -4957 | U14: -4957 | V14: -4957 | W14: -4957 | X14: -4957
B15: Total operating expenses | C15: =SUM(C9:C14) -> -300263 | D15: =SUM(D9:D14) -> -379943 | E15: =SUM(E9:E14) -> -367448 | F15: =SUM(F9:F14) -> -361135 | G15: =SUM(G9:G14) -> -273429 | H15: =SUM(H9:H14) -> -86349 | I15: =SUM(I9:I14) -> -89670 | J15: =SUM(J9:J14) -> -92472 | ... X15: =SUM(X9:X14) -> -49730
B17: Operating (loss)/income | C17: =C4+C6+C15 -> 202 | D17: =D4+D6+D15 -> 74204 | E17: =E4+E6+E15 -> 188627 | F17: =F4+F6+F15 -> 210638 | G17: =G4+G6+G15 -> 224972 | H17: =H4+H6+H15 -> 46219 | I17: =I4+I6+I15 -> 63377 | J17: =J4+J6+J15 -> 39093 | ... X17: =X4+X6+X15 -> 132590.36
B18: EBITDA | C18: =C17-C11 -> 128841 | D18: =D17-D11 -> 197459 | E18: =E17-E11 -> 297530 | F18: =F17-F11 -> 322522 | G18: =G17-G11 -> 331341 | H18: =H17-H11 -> 71945 | I18: =I17-I11 -> 89753 | J18: =J17-J11 -> 67419 | ... X18: =X17-X11 -> 158237.36
B19: Adjusted EBITDA | C19: =C18-C13 -> 113688 | D19: =D18-D13 -> 177947 | E19: =E18-E13 -> 297530 | F19: =F18-F13 -> 294613 | G19: =G18-G13 -> 277429 | H19: =H18-H13 -> 71945 | I19: =I18-I13 -> 89753 | J19: =J18-J13 -> 67419 | ... X19: =X18-X13 -> 158237.36
B21: Share of profit from associated companies | C21: 1278 | D21: 1407 | E21: =SUM(H21:K21) -> 0 | F21: =SUM(L21:O21) -> 0 | G21: =SUM(P21:S21) -> 0 | I21: 0 | J21: 0 | K21: 0 | L21: 0 | M21: 0 | N21: 0 | O21: 0 | P21: 0 | Q21: 0 | R21: 0 | S21: 0 | T21: 0 | U21: 0 | V21: 0 | W21: 0 | X21: 0
B22: Interest income | C22: 6 | D22: -5941 | E22: =SUM(H22:K22) -> 4485 | F22: =SUM(L22:O22) -> 3918 | G22: =SUM(P22:S22) -> 3139 | H22: 398 | I22: 1966 | J22: 1213 | K22: 908 | L22: 1091 | M22: 935 | N22: 1035 | O22: 857 | P22: 793 | Q22: 820 | R22: 936 | S22: 590 | T22: 784 | U22: 784 | V22: 784 | W22: 784 | X22: 784
B23: Interest expense | C23: -25727 | D23: -16471 | E23: =SUM(H23:K23) -> -33061 | F23: =SUM(L23:O23) -> -30398 | G23: =SUM(P23:S23) -> -14168 | H23: -7586 | I23: -7492 | J23: -8789 | K23: -9194 | L23: -8775 | M23: -7921 | N23: -7318 | O23: -6384 | P23: -5106 | Q23: -4186 | R23: -2586 | S23: -2290 | T23: -4424 | U23: -4424 | V23: -4424 | W23: -4424 | X23: -4424
B24: Fair value gain/(loss) on derivative financial liabilities | C24: 12450 | D24: 11726 | E24: =SUM(H24:K24) -> -503 | F24: =SUM(L24:O24) -> 0 | G24: =SUM(P24:S24) -> -169 | H24: -433 | I24: -70 | J24: 0 | K24: 0 | L24: 0 | M24: 0 | N24: 0 | O24: 0 | P24: 0 | Q24: 0 | R24: -354 | S24: 185 | T24: 1119 | U24: 0 | V24: 0 | W24: 0 | X24: 0
B25: Other financial (expense)/income | C25: 645 | D25: -2357 | E25: =SUM(H25:K25) -> -1984 | F25: =SUM(L25:O25) -> -2088 | G25: =SUM(P25:S25) -> -2396 | H25: -366 | I25: -606 | J25: -413 | K25: -599 | L25: -454 | M25: -470 | N25: -719 | O25: -445 | P25: -447 | Q25: -885 | R25: -520 | S25: -544 | T25: -485 | U25: -485 | V25: -485 | W25: -485 | X25: -485
B26: Profit/(loss) before tax | C26: =C17+SUM(C21:C25) -> -11146 | D26: =D17+SUM(D21:D25) -> 62568 | E26: =E17+SUM(E21:E25) -> 157564 | F26: =F17+SUM(F21:F25) -> 182070 | G26: =G17+SUM(G21:G25) -> 211378 | H26: =H17+SUM(H21:H25) -> 38232 | I26: =I17+SUM(I21:I25) -> 57175 | J26: =J17+SUM(J21:J25) -> 31104 | ... X26: =X17+SUM(X21:X25) -> 128465.36
B28: Income tax expense | C28: -360 | D28: -588 | E28: =SUM(H28:K28) -> -648 | F28: =SUM(L28:O28) -> -608 | G28: =SUM(P28:S28) -> -384 | H28: -191 | I28: -94 | J28: -137 | K28: -226 | L28: -206 | M28: -129 | N28: -79 | O28: -194 | P28: -84 | Q28: 0 | R28: -93 | S28: -207 | T28: -126 | U28: 0 | V28: 0 | W28: 0 | X28: 0
B29: Profit/(loss) after tax | C29: =C26+C28 -> -11506 | D29: =D26+D28 -> 61980 | E29: =E26+E28 -> 156916 | F29: =F26+F28 -> 181462 | G29: =G26+G28 -> 210994 | H29: =H26+H28 -> 38041 | I29: =I26+I28 -> 57081 | J29: =J26+J28 -> 30967 | ... X29: =X26+X28 -> 128465.36
B31: Attributable to owners of non-controlling interest | C31: 14 | D31: 459 | E31: =SUM(H31:K31) -> 44 | F31: =SUM(L31:O31) -> 83 | G31: =SUM(P31:S31) -> -91 | H31: -136 | I31: 25 | J31: 208 | K31: -53 | L31: 181 | M31: 143 | N31: -17 | O31: -224 | P31: -71 | Q31: -29 | R31: 2 | S31: 7 | T31: 2 | U31: 2 | V31: 2 | W31: 2 | X31: 2
B32: Attributable to the owners of parent | C32: =C29-C31 -> -11520 | D32: =D29-D31 -> 61521 | E32: =SUM(H32:K32) -> 161353 | F32: =F29-F31 -> 181379 | G32: =G29-G31 -> 211085 | H32: =H29-H31 -> 38177 | I32: =I29-I31 -> 57056 | J32: =J29-J31 -> 30759 | K32: =K29-K31 -> 35361 | L32: =L29-L31 -> 46890 | M32: =M29-M31 -> 44347 | ... X32: =X29-X31 -> 128463.36
B34: Attributable to the owners of parent
B35: Basic earnings/(loss) per share | C35: -0.07 | D35: 0.37 | E35: =SUM(H35:K35) -> 0.98981453 | F35: =F32*1000/F38 -> 1.1241025 | G35: =G32*1000/G38 -> 1.3136146 | H35: 0.23 | I35: 0.35 | J35: =J32*1000/J38 -> 0.19018037 | K35: =K32*1000/K38 -> 0.21963417 | L35: =L32*1000/L38 -> 0.29068032 | M35: =M32*1000/M38 -> 0.27481658 | N35: =N32*1000/N38 -> 0.21804795 | O35: =O32*1000/O38 -> 0.34063452 | P35: =P32*1000/P38 -> 0.27491034 | Q35: =Q32*1000/Q38 -> 0.34912531 | ... X35: =X32*1000/X38 -> 0.79776946
B36: Diluted earnings/(loss) per share | C36: -0.07 | D36: 0.37 | E36: =SUM(H36:K36) -> 0.98933749 | F36: =F32*1000/F40 -> 1.1234948 | G36: =G32*1000/G40 -> 1.3129358 | H36: 0.23 | I36: 0.35 | J36: =J32*1000/J40 -> 0.18998527 | K36: =K32*1000/K40 -> 0.21935222 | L36: =L32*1000/L40 -> 0.29047536 | M36: =M32*1000/M40 -> 0.27461738 | N36: =N32*1000/N40 -> 0.21792823 | O36: =O32*1000/O40 -> 0.34047642 | P36: =P32*1000/P40 -> 0.27480274 | Q36: =Q32*1000/Q40 -> 0.34898529 | ... X36: =X32*1000/X40 -> 0.79684019
B38: Weighted average number of shares (basic) | C38: 169089325 | D38: 164692954 | E38: 162178499 | F38: 161354507 | G38: 160690206 | H38: 162967375 | I38: 163037628 | J38: 161735939 | K38: 160999542 | L38: 161311231 | M38: 161369447 | N38: 161464487 | O38: 161272556 | P38: 160495965 | Q38: 160661512 | R38: 160799407 | S38: 160799407 | T38: 161028180 | U38: 161028180 | V38: 161028180 | W38: 161028180 | X38: 161028180
E39: =E38/D38-1 -> -0.015267532 | F39: =F38/E38-1 -> -0.0050807721 | G39: =G38/F38-1 -> -0.0041170279 | I39: =I38/H38-1 -> 0.00043108628 | J39: =J38/I38-1 -> -0.007983979 | K39: =K38/J38-1 -> -0.004553082 | L39: =L38/K38-1 -> 0.001935962 | M39: =M38/L38-1 -> 0.00036089242 | N39: =N38/M38-1 -> 0.00058895907 | O39: =O38/N38-1 -> -0.0011886886 | P39: =P38/O38-1 -> -0.0048153946 | ... X39: =X38/W38-1 -> 0
B40: Weighted average number of shares (diluted) | C40: 169089325 | D40: 164850097 | E40: 162356735 | F40: 161441782 | G40: 160773279 | H40: 163249977 | I40: 163172987 | J40: 161902025 | K40: 161206487 | L40: 161425054 | M40: 161486503 | N40: 161553185 | O40: 161347445 | P40: 160558807 | Q40: 160725972 | R40: 160885603 | S40: 160918696 | T40: 161215969 | U40: 161215969 | V40: 161215969 | W40: 161215969 | X40: 161215969
E41: =E40/D40-1 -> -0.015125026 | F41: =F40/E40-1 -> -0.0056354484 | G41: =G40/F40-1 -> -0.0041408302 | I41: =I40/H40-1 -> -0.00047160803 | J41: =J40/I40-1 -> -0.0077890466 | K41: =K40/J40-1 -> -0.0042960426 | L41: =L40/K40-1 -> 0.0013558201 | M41: =M40/L40-1 -> 0.00038066582 | N41: =N40/M40-1 -> 0.00041292615 | O41: =O40/N40-1 -> -0.0012735125 | P41: =P40/O40-1 -> -0.0048878245 | ... X41: =X40/W40-1 -> 0
B44: Adjusted Profit after tax | C44: =C19+C11+C21+C22+C23+C24+C25+C28+C31 -> -26645 | D44: =D19+D11+D21+D22+D23+D24+D25+D28+D31 -> 42927 | E44: =E19+E11+E21+E22+E23+E24+E25+E28+E31 -> 156960 | F44: =F19+F11+F21+F22+F23+F24+F25+F28+F31 -> 153636 | G44: =G19+G11+G21+G22+G23+G24+G25+G28+G31 -> 156991 | H44: =H19+H11+H21+H22+H23+H24+H25+H28+H31 -> 37905 | I44: =I19+I11+I21+I22+I23+I24+I25+I28+I31 -> 57106 | J44: =J19+J11+J21+J22+J23+J24+J25+J28+J31 -> 31175 | ... X44: =X19+X11+X21+X22+X23+X24+X25+X28+X31 -> 128467.36
B45: Diluted Adj. EPS | C45: =C44*1000/C40 -> -0.15757943 | D45: =D44*1000/D40 -> 0.26040021 | E45: =E44*1000/E40 -> 0.96676002 | F45: =F44*1000/F40 -> 0.95164956 | G45: =G44*1000/G40 -> 0.97647446 | H45: =H44*1000/H40 -> 0.23218993 | I45: =I44*1000/I40 -> 0.34997214 | J45: =J44*1000/J40 -> 0.19255473 | ... X45: =X44*1000/X40 -> 0.79686501
A48: x | B48: Operating Days | H48: SCRUBBER | I48: ECO
B49: DHT Mustang | H49: 1 | I49: 1 | J49: 87 | K49: 88 | L49: 88 | M49: 88 | N49: 90 | O49: 91 | P49: 90 | Q49: 90 | R49: 90 | S49: 90 | T49: 90 | U49: 90 | V49: 90 | W49: 90 | X49: 90
B50: DHT Bronco | H50: 1 | I50: 1 | J50: 87 | K50: 88 | L50: 88 | M50: 88 | N50: 90 | O50: 91 | P50: 90 | Q50: 90 | R50: 90 | S50: 90 | T50: 90 | U50: 90 | V50: 90 | W50: 90 | X50: 90
B51: DHT Colt | H51: 1 | I51: 1 | J51: 87 | K51: 88 | L51: 88 | M51: 88 | N51: 90 | O51: 91 | P51: 90 | Q51: 90 | R51: 90 | S51: 90 | T51: 90 | U51: 90 | V51: 90 | W51: 90 | X51: 90
B52: DHT Stallion | H52: 1 | I52: 1 | J52: 87 | K52: 88 | L52: 88 | M52: 88 | N52: 90 | O52: 91 | P52: 90 | Q52: 90 | R52: 90 | S52: 90 | T52: 90 | U52: 90 | V52: 90 | W52: 90 | X52: 90
...

Sheet Balance
B1: DHT (Thousands $) | C1: Q1 2023 | D1: Q2 2023 | E1: Q3 2023 | F1: Q4 2023 | G1: Q1 2024 | H1: Q2 2024 | I1: Q3 2024 | J1: Q4 2024 | K1: Q1 2025 | L1: Q2 2025 | M1: Q3 2025 | N1: Q4 2025 | O1: Q1 2026 | P1: Q2 2026 | Q1: Q3 2026 | R1: Q4 2026 | S1: Q1 2027
B2: Current Assets | C2: =SUM(C3:C8) -> 213214 | D2: =SUM(D3:D8) -> 234317 | E2: =SUM(E3:E8) -> 179227 | F2: =SUM(F3:F8) -> 200498 | G2: =SUM(G3:G8) -> 203397 | H2: =SUM(H3:H8) -> 195748 | I2: =SUM(I3:I8) -> 181528 | J2: =SUM(J3:J9) -> 201889 | K2: =SUM(K3:K9) -> 172035 | L2: =SUM(L3:L9) -> 193704 | M2: =SUM(M3:M9) -> 146592 | N2: =SUM(N3:N9) -> 208914 | O2: =SUM(O3:O9) -> 267109 | P2: =SUM(P3:P9) -> 322257.46 | Q2: =SUM(Q3:Q9) -> 323249.74 | ... S2: =SUM(S3:S9) -> 265121.02
B3: Cash and cash equivalents | C3: 117549 | D3: 130649 | E3: 73920 | F3: 74738 | G3: 73076 | H3: 72642 | I3: 73829 | J3: 78143 | K3: 80510 | L3: 82660 | M3: 81250 | N3: 79034 | O3: 126246 | P3: =CashFlow!U63 -> 181394.46 | Q3: =CashFlow!V63 -> 182386.74 | R3: =CashFlow!W63 -> 170104.44 | S3: =CashFlow!X63 -> 124258.02
B4: Accounts receivable and accrued revenues | C4: 55010 | D4: 56831 | E4: 55684 | F4: 75848 | G4: 80561 | H4: 70355 | I4: 58553 | J4: 53715 | K4: 50520 | L4: 40047 | M4: 33953 | N4: 53338 | O4: 85288 | P4: 85288 | Q4: 85288 | R4: 85288 | S4: 85288
B5: Capitalized voyage expenses | C5: 3487 | D5: 2192 | E5: 2817 | F5: 2549 | G5: 4679 | H5: 6051 | I5: 2848 | J5: 2450 | K5: 2645 | L5: 1568 | M5: 1465 | N5: 1684 | O5: 1701 | P5: 1701 | Q5: 1701 | R5: 1701 | S5: 1701
B6: Prepaid expenses | C6: 9440 | D6: 10287 | E6: 9023 | F6: 13557 | G6: 7650 | H6: 9894 | I6: 12999 | J6: 7200 | K6: 5327 | L6: 4326 | M6: 6426 | N6: 9678 | O6: 6501 | P6: 6501 | Q6: 6501 | R6: 6501 | S6: 6501
B7: Derivative financial assets | C7: 70 | E7: 0 | F7: 0 | G7: 0 | H7: 0 | I7: 0 | J7: 0 | K7: 0 | L7: 0 | M7: 0 | N7: 10 | O7: 355 | P7: 355 | Q7: 355 | R7: 355 | S7: 355
B8: Inventories | C8: 27658 | D8: 34358 | E8: 37783 | F8: 33806 | G8: 37431 | H8: 36806 | I8: 33299 | J8: 37688 | K8: 33033 | L8: 30679 | M8: 23498 | N8: 24682 | O8: 30241 | P8: 30241 | Q8: 30241 | R8: 30241 | S8: 30241
B9: Assets held for sale | J9: 22693 | L9: 34424 | M9: 0 | N9: 40488 | O9: 16777 | P9: 16777 | Q9: 16777 | R9: 16777 | S9: 16777
B11: Non-Current Assets | C11: =SUM(C12:C18) -> 1264323 | D11: =SUM(D12:D18) -> 1255535 | E11: =SUM(E12:E18) -> 1318248 | F11: =SUM(F12:F18) -> 1291725 | G11: =SUM(G12:G18) -> 1268933 | H11: =SUM(H12:H18) -> 1292295 | I11: =SUM(I12:I18) -> 1293022 | J11: =SUM(J12:J18) -> 1284699 | ... S11: =SUM(S12:S18) -> 1492893
B12: Vessels | C12: 1254056 | D12: 1237411 | E12: 1311892 | F12: 1283710 | G12: 1261388 | H12: 1233164 | I12: 1207533 | J12: 1185576 | K12: 1158750 | L12: 1067472 | M12: 1042035 | N12: 1083891 | O12: 1452955 | P12: =O12+'P&L'!U11+Balance!P59 -> 1504808 | Q12: =P12+'P&L'!V11+Balance!Q59 -> 1479161 | R12: =Q12+'P&L'!W11+Balance!R59 -> 1453514 | S12: =R12+'P&L'!X11+Balance!S59 -> 1427867
B13: Advances for vessels under construction | G13: 43 | H13: 51866 | I13: 78870 | J13: 93178 | K13: 120679 | L13: 161326 | M13: 190884 | N13: 301651 | O13: 55676 | P13: 55676 | Q13: 55676 | R13: 55676 | S13: 55676
B14: Advances for vessel upgrades | C14: 4594 | D14: 11369 | E14: 15 | F14: 10 | G14: 160 | H14: 382 | I14: 0 | J14: 0 | K14: 0 | L14: 0 | M14: 11924 | N14: 7117 | O14: 7399 | P14: 7399 | Q14: 7399 | R14: 7399 | S14: 7399
B15: Other PPE | C15: 4317 | D15: 5399 | E15: 4985 | F15: 6649 | G15: 5986 | H15: 5527 | I15: 5263 | J15: 4589 | K15: 5218 | L15: 6549 | M15: 5256 | N15: 1356 | O15: 1356 | P15: 1356 | Q15: 1356 | R15: 1356 | S15: 1356
B16: Investment in associate company
B17: Goodwill | C17: 1356 | D17: 1356 | E17: 1356 | F17: 1356 | G17: 1356 | H17: 1356 | I17: 1356 | J17: 1356 | K17: 1356 | L17: 1356 | M17: 1356 | N17: 19 | O17: 595 | P17: 595 | Q17: 595 | R17: 595 | S17: 595
B18: Derivative financial assets
B20: Total Assets | C20: =SUM(C2+C11) -> 1477537 | D20: =SUM(D2+D11) -> 1489852 | E20: =SUM(E2+E11) -> 1497475 | F20: =SUM(F2+F11) -> 1492223 | G20: =SUM(G2+G11) -> 1472330 | H20: =SUM(H2+H11) -> 1488043 | I20: =SUM(I2+I11) -> 1474550 | J20: =SUM(J2+J11) -> 1486588 | ... S20: =SUM(S2+S11) -> 1758014
B23: Current liabilities | C23: =SUM(C24:C28) -> 61243 | D23: =SUM(D24:D28) -> 75160 | E23: =SUM(E24:E28) -> 78755 | F23: =SUM(F24:F28) -> 56605 | G23: =SUM(G24:G28) -> 61723 | H23: =SUM(H24:H28) -> 68204 | I23: =SUM(I24:I28) -> 75271 | J23: =SUM(J24:J28) -> 109613 | ... S23: =SUM(S24:S28) -> 41440
B24: Accounts payable and accrued expenses | C24: 22020 | D24: 29302 | E24: 25111 | F24: 20493 | G24: 24150 | H24: 21495 | I24: 22711 | J24: 23436 | K24: 20303 | L24: 25092 | M24: 21505 | N24: 22761 | O24: 33933 | P24: 33933 | Q24: 33933 | R24: 33933 | S24: 33933
B25: Derivative financial liabilities | M25: 111 | N25: 68 | O25: 0
B26: Current portion long-term debt | C26: 33109 | D26: 38947 | E26: 47933 | F26: 30300 | G26: 36161 | H26: 42025 | I26: 48340 | J26: 78649 | K26: 78774 | L26: 49074 | M26: 31551 | N26: 39500 | O26: 104647
B27: Other current liabilities | C27: 1022 | D27: 1401 | E27: 1317 | F27: 1418 | G27: 1412 | H27: 1437 | I27: 1509 | J27: 1389 | K27: 1350 | L27: 1150 | M27: 925 | N27: 994 | O27: 914 | P27: 914 | Q27: 914 | R27: 914 | S27: 914
B28: Deferred shipping revenues | C28: 5092 | D28: 5510 | E28: 4394 | F28: 4394 | G28: 0 | H28: 3247 | I28: 2711 | J28: 6139 | K28: 7501 | L28: 7963 | M28: 6710 | N28: 11397 | O28: 6593 | P28: 6593 | Q28: 6593 | R28: 6593 | S28: 6593
B30: Non-Current Liabilities | C30: =SUM(C31:C33) -> 365740 | D30: =SUM(D31:D33) -> 353152 | E30: =SUM(E31:E33) -> 392204 | F30: =SUM(F31:F33) -> 403952 | G30: =SUM(G31:G33) -> 366547 | H30: =SUM(H31:H33) -> 377113 | I30: =SUM(I31:I33) -> 363594 | J30: =SUM(J31:J33) -> 334272 | ... S30: =SUM(S31:S33) -> 406224
B31: Long-term debt | C31: 362616 | D31: 349352 | E31: 388647 | F31: 398425 | G31: 361619 | H31: 372579 | I31: 359289 | J31: 330775 | K31: 285298 | L31: 253731 | M31: 236976 | N31: 389244 | O31: 400696 | P31: =(O31+O26)-(104647/4) -> 479181.25 | Q31: =(P31+P26)-(104647/4) -> 453019.5 | R31: =(Q31+Q26)-(104647/4) -> 426857.75 | S31: =(R31+R26)-(104647/4) -> 400696
B32: Derivative financial liabilities | M32: 243 | N32: 131 | O32: 0
B33: Other non-current liabilities | C33: 3124 | D33: 3800 | E33: 3557 | F33: 5527 | G33: 4928 | H33: 4534 | I33: 4305 | J33: 3497 | K33: 3355 | L33: 4457 | M33: 4357 | N33: 5598 | O33: 5528 | P33: 5528 | Q33: 5528 | R33: 5528 | S33: 5528
B35: Total Liabilities | C35: =C23+C30 -> 426983 | D35: =D23+D30 -> 428312 | E35: =E23+E30 -> 470959 | F35: =F23+F30 -> 460557 | G35: =G23+G30 -> 428270 | H35: =H23+H30 -> 445317 | I35: =I23+I30 -> 438865 | J35: =J23+J30 -> 443885 | ... S35: =S23+S30 -> 447664
B38: Equity | C38: 1050553 | D38: 1061542 | E38: 1026515 | F38: 1031667 | G38: 1044060 | H38: 1042727 | I38: 1035686 | J38: 1042701 | K38: 1061457 | L38: 1088938 | M38: 1095669 | N38: 1133257 | O38: 1232779 | P38: =O38+'P&L'!U29+CashFlow!U45+CashFlow!U50+CashFlow!U10+CashFlow!U33 -> 1365907 | Q38: =P38+'P&L'!V29+CashFlow!V45+CashFlow!V50+CashFlow!V10+CashFlow!V33 -> 1367414 | R38: =Q38+'P&L'!W29+CashFlow!W45+CashFlow!W50+CashFlow!W10+CashFlow!W33 -> 1355646.4 | S38: =R38+'P&L'!X29+CashFlow!X45+CashFlow!X50+CashFlow!X10+CashFlow!X33 -> 1310314.8
B40: Total Equity and Liabilities | C40: =C38+C35 -> 1477536 | D40: =D38+D35 -> 1489854 | E40: =E38+E35 -> 1497474 | F40: =F38+F35 -> 1492224 | G40: =G38+G35 -> 1472330 | H40: =H38+H35 -> 1488044 | I40: =I38+I35 -> 1474551 | J40: =J38+J35 -> 1486586 | ... S40: =S38+S35 -> 1757978.8
B41: Check | C41: =C20-C40 -> 1 | D41: =D20-D40 -> -2 | E41: =E20-E40 -> 1 | F41: =F20-F40 -> -1 | G41: =G20-G40 -> 0 | H41: =H20-H40 -> -1 | I41: =I20-I40 -> -1 | J41: =J20-J40 -> 2 | ... S41: =S20-S40 -> 35.24906
A44: x | B44: Debt
B45: Financial Debt | C45: =C26+C31 -> 395725 | D45: =D26+D31 -> 388299 | E45: =E26+E31 -> 436580 | F45: =F26+F31 -> 428725 | G45: =G26+G31 -> 397780 | H45: =H26+H31 -> 414604 | I45: =I26+I31 -> 407629 | J45: =J26+J31 -> 409424 | ... S45: =S26+S31 -> 400696
B46: Growth rate YoY % | C46: =C45/#REF!-1 -> #REF! | D46: =D45/C45-1 -> -0.018765557 | E46: =E45/D45-1 -> 0.12433975 | F46: =F45/E45-1 -> -0.017992121 | G46: =G45/F45-1 -> -0.072179136 | H46: =H45/G45-1 -> 0.042294736 | I46: =I45/H45-1 -> -0.016823282 | J46: =J45/I45-1 -> 0.004403514 | K46: =K45/J45-1 -> -0.11077025 | ... S46: =S45/R45-1 -> -0.061289153
B47: Net Financial Debt | C47: =C45-C3 -> 278176 | D47: =D45-D3 -> 257650 | E47: =E45-E3 -> 362660 | F47: =F45-F3 -> 353987 | G47: =G45-G3 -> 324704 | H47: =H45-H3 -> 341962 | I47: =I45-I3 -> 333800 | J47: =J45-J3 -> 331281 | ... S47: =S45-S3 -> 276437.98
B48: Growth rate YoY%
A51: x | B51: Working Capital
B53: Working Capital | C53: =(C4+C5+C6+C8+C13+C14)-(C24+C28-C27-C33) -> 77223 | D53: =(D4+D5+D6+D8+D13+D14)-(D24+D28-D27-D33) -> 85426 | E53: =(E4+E5+E6+E8+E13+E14)-(E24+E28-E27-E33) -> 80691 | F53: =(F4+F5+F6+F8+F13+F14)-(F24+F28-F27-F33) -> 107828 | G53: =(G4+G5+G6+G8+G13+G14)-(G24+G28-G27-G33) -> 112714 | H53: =(H4+H5+H6+H8+H13+H14)-(H24+H28-H27-H33) -> 156583 | I53: =(I4+I5+I6+I8+I13+I14)-(I24+I28-I27-I33) -> 166961 | J53: =(J4+J5+J6+J8+J13+J14)-(J24+J28-J27-J33) -> 169542 | ... S53: =(S4+S5+S6+S8+S13+S14)-(S24+S28-S27-S33) -> 152722
B54: WC as % of RevenuesYoY%
...

Sheet CashFlow
B1: DHT (Thousands $) | C1: =D1-1 -> 2021 | D1: 2022 | E1: 2023 | F1: 2024 | G1: 2025 | H1: Q1 2023 | I1: Q2 2023 | J1: Q3 2023 | K1: Q4 2023 | L1: Q1 2024 | M1: Q2 2024 | N1: Q3 2024 | O1: Q4 2024 | P1: Q1 2025 | Q1: Q2 2025 | R1: Q3 2025 | S1: Q4 2025 | T1: Q1 2026 | U1: Q2 2026 | V1: Q3 2026 | W1: Q4 2026 | X1: Q1 2027
B2: Profit/(loss) after tax | C2: ='P&L'!C29 -> -11506 | D2: ='P&L'!D29 -> 61980 | E2: =SUM(H2:K2) -> 161397 | F2: =SUM(L2:O2) -> 181462 | G2: =SUM(P2:S2) -> 210994 | H2: ='P&L'!H29 -> 38041 | I2: ='P&L'!I29 -> 57081 | J2: ='P&L'!J29 -> 30967 | K2: ='P&L'!K29 -> 35308 | L2: ='P&L'!L29 -> 47071 | M2: ='P&L'!M29 -> 44490 | N2: ='P&L'!N29 -> 35190 | O2: ='P&L'!O29 -> 54711 | ... X2: ='P&L'!X29 -> 128465.36
B4: items included in net income not affecting cash flows | C4: =SUM(C5:C17) -> 103606 | D4: =SUM(D5:D17) -> 94232 | E4: =SUM(E5:E17) -> 114902 | F4: =SUM(F5:F17) -> 90902 | G4: =SUM(G5:G17) -> 60748 | H4: =SUM(H5:H17) -> 27204 | I4: =SUM(I5:I17) -> 28140 | J4: =SUM(J5:J17) -> 29705 | ... S4: =SUM(S5:S17) -> 28002 | T4: -35959 | U4: =SUM(U5:U17) -> -8553 | V4: =SUM(V5:V17) -> 25647 | W4: =SUM(W5:W17) -> 25647 | X4: =SUM(X5:X17) -> 25647
B5: D&A | C5: 128639 | D5: 123255 | E5: =SUM(H5:K5) -> 108903 | F5: =SUM(L5:O5) -> 111884 | G5: =SUM(P5:S5) -> 106369 | H5: 25726 | I5: 26376 | J5: 28326 | K5: 28475 | L5: 28250 | M5: =-'P&L'!M11 -> 27878 | N5: =-'P&L'!N11 -> 28135 | O5: =-'P&L'!O11 -> 27621 | P5: =-'P&L'!P11 -> 27270 | Q5: 26139 | R5: =-'P&L'!R11 -> 25969 | S5: 26991 | T5: =-'P&L'!T11 -> 25647 | U5: =-'P&L'!U11 -> 25647 | V5: =-'P&L'!V11 -> 25647 | W5: =-'P&L'!W11 -> 25647 | X5: =-'P&L'!X11 -> 25647
B6: Impairment charges | E6: =SUM(H6:K6) -> 0 | F6: =SUM(L6:O6) -> -27909 | G6: =SUM(P6:S6) -> 0 | O6: -27909 | U6: 0 | V6: 0 | W6: 0 | X6: 0
B7: Amortization of upfront fees | C7: 2550 | D7: 2281 | E7: =SUM(H7:K7) -> 0 | F7: =SUM(L7:O7) -> 0 | G7: =SUM(P7:S7) -> 0 | T7: 581 | U7: 0 | V7: 0 | W7: 0 | X7: 0
B8: Amortization of deferred debt issuance cost | D8: 621 | E8: =SUM(H8:K8) -> 2971 | F8: =SUM(L8:O8) -> 2627 | G8: =SUM(P8:S8) -> 2452 | H8: 836 | I8: 722 | J8: 664 | K8: 749 | L8: 680 | M8: 662 | N8: 652 | O8: 633 | P8: 601 | Q8: 816 | R8: 544 | S8: 491 | T8: 0 | U8: 0 | V8: 0 | W8: 0 | X8: 0
B9: (Gain)/loss, disposal of PPE | E9: =SUM(H9:K9) -> 17 | F9: =SUM(L9:O9) -> 0 | G9: =SUM(P9:S9) -> 0 | H9: 9 | J9: 8 | L9: 0 | M9: 0 | N9: 0 | O9: 0 | P9: 0 | Q9: 0 | R9: 0 | S9: 0 | T9: 0 | U9: 0 | V9: 0 | W9: 0 | X9: 0
B10: (Gain)/loss, disposal of vessel | C10: -15153 | D10: -19512 | E10: =SUM(H10:K10) -> 0 | F10: =SUM(L10:O10) -> 0 | G10: =SUM(P10:S10) -> -52942 | L10: 0 | M10: 0 | N10: 0 | O10: 0 | P10: -19795 | Q10: -17459 | R10: -15688 | S10: 0 | T10: -59994 | U10: -34200 | V10: 0 | W10: 0 | X10: 0
B11: Capitalized interest | F11: =SUM(L11:O11) -> 0 | G11: =SUM(P11:S11) -> 0 | T11: -2170 | U11: 0 | V11: 0 | W11: 0 | X11: 0
B12: Fair value (gain)/loss on derivative financial instruments | C12: -12450 | D12: -14983 | E12: =SUM(H12:K12) -> 503 | F12: =SUM(L12:O12) -> 0 | G12: =SUM(P12:S12) -> 169 | H12: 433 | I12: 70 | L12: 0 | M12: 0 | N12: 0 | O12: 0 | P12: 0 | Q12: 0 | R12: 354 | S12: -185 | T12: -1119 | U12: 0 | V12: 0 | W12: 0 | X12: 0
B13: Impairment of equity accounted investment | D13: 637 | E13: =SUM(H13:K13) -> 0 | F13: =SUM(L13:O13) -> 0 | G13: =SUM(P13:S13) -> 0 | U13: 0 | V13: 0 | W13: 0 | X13: 0
B14: Compensation related to options and restricted stock | C14: 4347 | D14: 4133 | E14: =SUM(H14:K14) -> 3233 | F14: =SUM(L14:O14) -> 4291 | G14: =SUM(P14:S14) -> 4380 | H14: 891 | I14: 976 | J14: 716 | K14: 650 | L14: 991 | M14: 1005 | N14: 903 | O14: 1392 | P14: 1850 | Q14: 1208 | R14: 661 | S14: 661 | T14: 989 | U14: 0 | V14: 0 | W14: 0 | X14: 0
B15: Net foreign exchange differences | D15: -204 | E15: =SUM(H15:K15) -> -32 | F15: =SUM(L15:O15) -> 9 | G15: =SUM(P15:S15) -> 320 | H15: 2 | I15: -4 | J15: -9 | K15: -21 | L15: 35 | M15: 9 | N15: -58 | O15: 23 | P15: 70 | Q15: 296 | R15: -90 | S15: 44 | T15: 108 | U15: 0 | V15: 0 | W15: 0 | X15: 0
B16: (Gain)/loss modification of debt | C16: -3049 | D16: -669 | E16: =SUM(H16:K16) -> -693 | F16: =SUM(L16:O16) -> 0 | G16: =SUM(P16:S16) -> 0 | H16: -693 | L16: 0
B17: Share of profit in associated companies | C17: -1278 | D17: -1327 | E17: =SUM(H17:K17) -> 0 | F17: =SUM(L17:O17) -> 0 | G17: =SUM(P17:S17) -> 0
B18: Income adjusted for non-cash items | C18: =C2+C4 -> 92100 | D18: =D2+D4 -> 156212 | E18: =E2+E4 -> 276299 | F18: =F2+F4 -> 272364 | G18: =G2+G4 -> 271742 | H18: =H2+H4 -> 65245 | I18: =I2+I4 -> 85221 | J18: =J2+J4 -> 60672 | ... X18: =X2+X4 -> 154112.36
B20: Changes in operating assets and liabilities: | C20: =SUM(C21:C27) -> -31538 | D20: =SUM(D21:D27) -> -28436 | E20: =SUM(E21:E27) -> -24890 | F20: =SUM(F21:F27) -> 26293 | G20: =SUM(G21:G27) -> 4941 | H20: =SUM(H21:H27) -> 1209 | I20: =SUM(I21:I27) -> 1744 | J20: =SUM(J21:J27) -> -4948 | ... X20: =SUM(X21:X27) -> 0
B21: Accounts receivable and accrued revenues | C21: -301 | D21: -28702 | E21: =SUM(H21:K21) -> -16383 | F21: =SUM(L21:O21) -> 22133 | G21: =SUM(P21:S21) -> -405 | H21: 4454 | I21: -1820 | J21: 1147 | K21: -20164 | L21: -4713 | M21: 10206 | N21: 11802 | O21: 4838 | P21: 2517 | Q21: 10655 | R21: 6153 | S21: -19730 | T21: -30418
B22: Capitalized voyage expenses | C22: -356 | D22: -1403 | E22: =SUM(H22:K22) -> 250 | F22: =SUM(L22:O22) -> 99 | G22: =SUM(P22:S22) -> 767 | H22: -688 | I22: 1295 | J22: -625 | K22: 268 | L22: -2129 | M22: -1373 | N22: 3203 | O22: 398 | P22: -195 | Q22: 1078 | R22: 106 | S22: -222 | T22: -18
B23: Prepaid expenses | C23: 523 | D23: -3538 | E23: =SUM(H23:K23) -> -3009 | F23: =SUM(L23:O23) -> 6358 | G23: =SUM(P23:S23) -> -2478 | H23: 1109 | I23: -847 | J23: 1264 | K23: -4535 | L23: 5907 | M23: -2244 | N23: -3105 | O23: 5800 | P23: 1873 | Q23: 1001 | R23: -2100 | S23: -3252 | T23: 3177
B24: Accounts payable and accrued expenses | C24: 1510 | D24: 5641 | E24: =SUM(H24:K24) -> -4938 | F24: =SUM(L24:O24) -> 33 | G24: =SUM(P24:S24) -> -11206 | H24: -9932 | I24: 9506 | J24: -2214 | K24: -2298 | L24: 1894 | M24: -1626 | N24: 410 | O24: -645 | P24: -5047 | Q24: 995 | R24: -5745 | S24: -1409 | T24: 7792
B25: Deferred shipping revenues | C25: -11372 | D25: -692 | E25: =SUM(H25:K25) -> 222 | F25: =SUM(L25:O25) -> 1745 | G25: =SUM(P25:S25) -> 5258 | H25: 920 | I25: 418 | J25: -1116 | K25: 0 | L25: -4394 | M25: 3247 | N25: -535 | O25: 3427 | P25: 1362 | Q25: 462 | R25: -1253 | S25: 4687 | T25: -4804
B26: Bunker inventory | C26: -21542 | D26: 327 | E26: =SUM(H26:K26) -> -737 | F26: =SUM(L26:O26) -> -3881 | G26: =SUM(P26:S26) -> 13005 | H26: 5411 | I26: -6700 | J26: -3425 | K26: 3977 | L26: -3625 | M26: 625 | N26: 3508 | O26: -4389 | P26: 4655 | Q26: 2354 | R26: 7180 | S26: -1184 | T26: -5559
B27: Pension liability | D27: -69 | E27: =SUM(H27:K27) -> -295 | F27: =SUM(L27:O27) -> -194 | G27: =SUM(P27:S27) -> 0 | H27: -65 | I27: -108 | J27: 21 | K27: -143 | L27: -100 | M27: -20 | N27: 40 | O27: -114 | P27: 0
A28: x | B28: Net Cash provided by operating activities | C28: =C18+C20 -> 60562 | D28: =D18+D20 -> 127776 | E28: =E18+E20 -> 251409 | F28: =F18+F20 -> 298657 | G28: =G18+G20 -> 276683 | H28: =H18+H20 -> 66454 | I28: =I18+I20 -> 86965 | J28: =J18+J20 -> 55724 | ... X28: =X18+X20 -> 154112.36
B31: Investment in vessels | C31: -174558 | D31: -9902 | E31: =SUM(H31:K31) -> -128082 | F31: =SUM(L31:O31) -> -6688 | G31: =SUM(P31:S31) -> -136934 | H31: -14829 | I31: -18125 | J31: -92943 | K31: -2185 | L31: -3832 | M31: -798 | N31: -2004 | O31: -54 | P31: -25809 | Q31: -1146 | R31: -12350 | S31: -97629 | T31: -2849 | U31: =-Balance!P59 -> -77500 | V31: =-Balance!Q59 -> 0 | W31: =-Balance!R59 -> 0 | X31: =-Balance!S59 -> 0
B32: Investment in vessels under construction | F32: =SUM(L32:O32) -> -90195 | G32: =SUM(P32:S32) -> -172702 | L32: -43 | M32: -51454 | N32: -25840 | O32: -12858 | Q32: -38714 | R32: -26167 | S32: -107821 | T32: -159971 | U32: 0 | V32: 0 | W32: 0 | X32: 0
B33: Proceeds from sale of vessels | C33: 87062 | D33: 112399 | E33: =SUM(H33:K33) -> 0 | F33: =SUM(L33:O33) -> 0 | G33: =SUM(P33:S33) -> 143521 | L33: 0 | P33: 42489 | Q33: 50942 | R33: 50090 | S33: 0 | T33: 101009 | U33: 51500 | V33: 0 | W33: 0 | X33: 0
B34: Investment in subsidiaries | D34: -2 | E34: =SUM(H34:K34) -> 0 | F34: =SUM(L34:O34) -> 0 | G34: =SUM(P34:S34) -> 0 | U34: 0 | V34: 0 | W34: 0 | X34: 0
B35: Acquisition of subsidiary, net of cash paid | D35: 8267 | E35: =SUM(H35:K35) -> 0 | F35: =SUM(L35:O35) -> 0 | G35: =SUM(P35:S35) -> 0 | U35: 0 | V35: 0 | W35: 0 | X35: 0
B36: Dividend received from associated company | C36: 1031 | D36: 0 | E36: =SUM(H36:K36) -> 0 | F36: =SUM(L36:O36) -> 0 | G36: =SUM(P36:S36) -> 0 | U36: 0 | V36: 0 | W36: 0 | X36: 0
B37: Investment in other PPE | C37: -48 | D37: -243 | E37: =SUM(H37:K37) -> -151 | F37: =SUM(L37:O37) -> -149 | G37: =SUM(P37:S37) -> -306 | H37: -35 | I37: -10 | J37: -89 | K37: -17 | L37: -3 | M37: -19 | N37: -47 | O37: -80 | P37: -5 | Q37: -18 | R37: -65 | S37: -218 | T37: -166 | U37: 0 | V37: 0 | W37: 0 | X37: 0
A38: x | B38: Investing Cash Flow | C38: =SUM(C31:C37) -> -86513 | D38: =SUM(D31:D37) -> 110519 | E38: =SUM(E31:E37) -> -128233 | F38: =SUM(F31:F37) -> -97032 | G38: =SUM(G31:G37) -> -166421 | H38: =SUM(H31:H37) -> -14864 | I38: =SUM(I31:I37) -> -18135 | J38: =SUM(J31:J37) -> -93032 | ... X38: =SUM(X31:X37) -> 0
B41: Levered FCF | C41: =C28+C31+C37 -> -114044 | D41: =D28+D31+D37 -> 117631 | E41: =SUM(H41:K41) -> 123176 | F41: =SUM(I41:L41) -> 137618 | G41: =SUM(J41:M41) -> 150830 | H41: =H28+H31+H37 -> 51590 | I41: =I28+I31+I37 -> 68830 | J41: =J28+J31+J37 -> -37308 | K41: =K28+K31+K37 -> 40064 | L41: =L28+L31+L37 -> 66032 | M41: =M28+M31+M37 -> 82042 | N41: =N28+N31+N37 -> 78094 | O41: =O28+O31+O37 -> 65652 | ... X41: =X28+X31+X37 -> 154112.36
B42: UnLevered FCF | C42: =C41-'P&L'!C23-'P&L'!C22 -> -88323 | D42: =D41-'P&L'!D23-'P&L'!D22 -> 140043 | E42: =E41-'P&L'!E23-'P&L'!E22 -> 151752 | F42: =F41-'P&L'!F23-'P&L'!F22 -> 164098 | G42: =G41-'P&L'!G23-'P&L'!G22 -> 161859 | H42: =H41-'P&L'!H23-'P&L'!H22 -> 58778 | I42: =I41-'P&L'!I23-'P&L'!I22 -> 74356 | J42: =J41-'P&L'!J23-'P&L'!J22 -> -29732 | ... X42: =X41-'P&L'!X23-'P&L'!X22 -> 157752.36
B45: Cash dividends paid | C45: -22083 | D45: -19678 | E45: =SUM(H45:K45) -> -186673 | F45: =SUM(L45:O45) -> -161395 | G45: =SUM(P45:S45) -> -118912.75 | H45: -61935 | I45: -37487 | J45: -56661 | K45: -30590 | L45: -35492 | M45: -46786 | N45: -43595 | O45: -35522 | P45: -27286 | Q45: -24091 | R45: =-(0.24*('P&L'!R38/1000)) -> -38591.858 | S45: =-(0.18*('P&L'!S38/1000)) -> -28943.893 | T45: -66027 | U45: =-(0.64*('P&L'!U38/1000)) -> -103058.04 | V45: =-('P&L'!U45*('P&L'!V38/1000)) -> -184472.87 | W45: =-('P&L'!V45*('P&L'!W38/1000)) -> -185765.26 | X45: =-('P&L'!W45*('P&L'!X38/1000)) -> -173797.03
B46: Acquisition of non-controlling interest | F46: =SUM(L46:O46) -> 0 | G46: =SUM(P46:S46) -> -6131 | Q46: -6131 | R46: 0
B47: Dividends paid to non-controlling interest | D47: 0 | E47: =SUM(H47:K47) -> -590 | F47: =SUM(L47:O47) -> 0 | G47: =SUM(P47:S47) -> 0 | I47: -590 | K47: 0 | R47: 0
B48: Repayment principal element of lease liability | C48: -611 | D48: -1089 | E48: =SUM(H48:K48) -> -1424 | F48: =SUM(L48:O48) -> -1391 | G48: =SUM(P48:S48) -> -1406 | H48: -386 | I48: -350 | J48: -346 | K48: -342 | L48: -340 | M48: -340 | N48: -354 | O48: -357 | P48: -353 | Q48: -351 | R48: -364 | S48: -338 | T48: -340
...

Sheet Notes
B1: WEB
B35: Q3 2023
B82: Presentation Q3 2023
K94: 17/01/24: Sacan update bajando su cash breakeven rates a $18600 y a 13800 en spot
B108: Interesting geneal information
B177: Q4 2023
B340: Press release 28/02/24
B359: 20-F 2023
B386: Q1 2024
B497: Update 11/07/24
B514: Q2 2024
B607: Q3 2024
B711: Update 14/01/25
B729: Q4 2024
B816: Update 14/04/25
B833: Release 15/04/25
... B1360: Q1 2026
