Workbook

Sheet Cover
A3: DHT Holdings, Inc. | F3: Copyright:
A4: DHT | F4: Ourios Analytics
F5: ourios.com
F6: info@ourios.com
A10: DISCLAIMER
A11: The financial models and projections provided herein are based on internal assumptions, historical data, and current market trends (such as charter rates, fuel costs, and vessel valuations) which are subject to high volatility and change without notice.
A12: These models are intended for illustrative and informational purposes only. They do not constitute financial, investment, or legal advice. While we strive for accuracy, we make no guarantees regarding the future performance of any asset or the realization of the projected returns.
A16: COPYRIGHT
A17: This Excel model and its contents are the exclusive property of Ourios Analytics. No part of this file may be reproduced, distributed, transmitted, or shared in any form or by any means, without the prior written permission of Ourios Analytics.
A18: Authorized use must strictly include a clear citation of the source: "Source: Ourios Analytics".
A22: COLORS USED IN FINANCIAL DATA
A23: In green: | B23: Data copied from last quarter or reported by company
A24: In blue: | B24: Our own assumption
A25: In black: | B25: Automatically filled
A26: In yellow | B26: Yellow cells can be changed to make assumptions
A30: NAV Tab Content
A31: Fleet list: | B31: Vessel name, type of vessel, year built, Yard, Country, scrubber, neutral value and corrected value by premium coefficient
A32: Price to update: | B32: Share price, that it´s update from Valuations_Master
A33: NAV calculation: | B33: Net Asset Value calculation
A34: Adjusted fleet value: | B34: Change this coefficient if you think the value is going up or down. Default we leave it in 1.
A35: Value growth in %: | B35: Change in % between quarters
A36: Scrubbers: | B36: How many scrubbers are installed in the vessels, reported by the company.
A37: Fleet : | B37: How many vessels has the company
A38: % Fleet with scrubber: | B38: As it titles says, % fleet with scrubber
A39: TCE: | B39: Time Charter Equivalent, based in data reported by the company or own assumptions
A40: Financial data: | B40: Market Cap, Enterprise Value, Adjusted Earnings, Adjusted EBITDA, Levered FCF, Adjusted P/E, Adjusted EV/EBITDA and P/FCF
A41: Linear Estimation: | B41: Don´t remove or change this data. It´s to automatically calculate vessels value from the Master
A42: Coefficient added by premium: | B42: Correction factor depending on the country of construction or others
A44: Fleet colours by status:
A45: No color: | B45: In the fleet list
A46: Pink: | B46: Sold vessel reported by the company
A47: Orange: | B47: Newbuilding or acquired vessel reported by the company
A48: Blue: | B48: Chartered-in or Bareboat-in
A50: Remember: If you want to make assumptions, just change yellow cells
A53: P&L Tab Content
A54: P&L from company reports
A55: Operating days: | B55: You can change it on your own
A56: TCE revenue per vessel: | B56: Operating days x TCE assumption
A58: Notes:
A59: Estimating revenues are from TCE and operating days. For that reason, voyage expenses use to be in grey background. We prepare the TCE revenues looking at what the company say about it.
...

Sheet NAV
B1: Vessel | C1: Type | D1: Yard | E1: Country | F1: Ownership | G1: Built | H1: Age | I1: Value | J1: Premium | K1: Scrub. | M1: Price:
B2: DHT Mustang | C2: VLCC | D2: Hyundai | E2: S. Korea | F2: 1 | G2: 43101 | H2: =(TODAY()-G2)/365 -> 8.6136986 | I2: =$C$34*H2^3+$D$34*H2^2+$E$34*H2+$F$34 -> 111.84376 | J2: =I2*$C$39 -> 120.79126 | K2: 1 | M2: ='[1]Stock Master'!$C$4 -> 17.84
B3: DHT Bronco | C3: VLCC | D3: Hyundai | E3: S. Korea | F3: 1 | G3: 43101 | H3: =(TODAY()-G3)/365 -> 8.6136986 | I3: =$C$34*H3^3+$D$34*H3^2+$E$34*H3+$F$34 -> 111.84376 | J3: =I3*$C$39 -> 120.79126 | K3: 1
B4: DHT Colt | C4: VLCC | D4: Daewoo | E4: S. Korea | F4: 1 | G4: 43101 | H4: =(TODAY()-G4)/365 -> 8.6136986 | I4: =$C$34*H4^3+$D$34*H4^2+$E$34*H4+$F$34 -> 111.84376 | J4: =I4*$C$39 -> 120.79126 | K4: 1 | M4: Net Asset Value | N4: Q1 2026 | O4: Q2 2026 | P4: Q3 2026 | Q4: Q4 2026 | R4: Q1 2027 | S4: Q2 2027
B5: DHT Stallion | C5: VLCC | D5: Daewoo | E5: S. Korea | F5: 1 | G5: 43101 | H5: =(TODAY()-G5)/365 -> 8.6136986 | I5: =$C$34*H5^3+$D$34*H5^2+$E$34*H5+$F$34 -> 111.84376 | J5: =I5*$C$39 -> 120.79126 | K5: 1 | M5: Fleet Value | N5: 2387.56 | O5: 2598.91 | P5: =P21*(SUM($J$2:$J$24)) -> 2587.7803 | Q5: =Q21*(SUM($J$2:$J$24)) -> 2574.8414 | R5: =R21*(SUM($J$2:$J$24)) -> 2561.9025 | S5: =S21*(SUM($J$2:$J$24)) -> 2548.9636
B6: DHT Tiger | C6: VLCC | D6: Hyundai | E6: S. Korea | F6: 1 | G6: 42736 | H6: =(TODAY()-G6)/365 -> 9.6136986 | I6: =$C$34*H6^3+$D$34*H6^2+$E$34*H6+$F$34 -> 107.41696 | J6: =I6*$C$39 -> 116.01032 | K6: 1 | M6: Financial Debt | N6: =-Balance!Q45/1000 -> -505.343 | O6: =-Balance!R45/1000 -> -434.804 | P6: =-Balance!S45/1000 -> -423.446 | Q6: =-Balance!T45/1000 -> -412.088 | R6: =-Balance!U45/1000 -> -400.73 | S6: =-Balance!V45/1000 -> -389.372
B7: DHT Harrier | C7: VLCC | D7: Daewoo | E7: S. Korea | F7: 1 | G7: 42370 | H7: =(TODAY()-G7)/365 -> 10.616438 | I7: =$C$34*H7^3+$D$34*H7^2+$E$34*H7+$F$34 -> 102.61781 | J7: =I7*$C$39 -> 110.82723 | K7: 1 | M7: Cash | N7: =Balance!Q3/1000 -> 126.246 | O7: =Balance!R3/1000 -> 161.683 | P7: =Balance!S3/1000 -> 245.72897 | Q7: =Balance!T3/1000 -> 264.50154 | R7: =Balance!U3/1000 -> 226.62464 | S7: =Balance!V3/1000 -> 199.58805
B8: DHT Osprey | C8: VLCC | D8: Daewoo | E8: S. Korea | F8: 1 | G8: 42370 | H8: =(TODAY()-G8)/365 -> 10.616438 | I8: =$C$34*H8^3+$D$34*H8^2+$E$34*H8+$F$34 -> 102.61781 | J8: =I8*$C$39 -> 110.82723 | K8: 1 | M8: Payments on NB | N8: =Balance!Q13/1000 -> 55.676 | O8: =Balance!R13/1000 -> 56.974 | P8: =Balance!S13/1000 -> 56.974 | Q8: =Balance!T13/1000 -> 56.974 | R8: =Balance!U13/1000 -> 56.974 | S8: =Balance!V13/1000 -> 56.974
B9: DHT Puma | C9: VLCC | D9: Hyundai | E9: S. Korea | F9: 1 | G9: 42370 | H9: =(TODAY()-G9)/365 -> 10.616438 | I9: =$C$34*H9^3+$D$34*H9^2+$E$34*H9+$F$34 -> 102.61781 | J9: =I9*$C$39 -> 110.82723 | K9: 1 | M9: Bunker
B10: DHT Panther | C10: VLCC | D10: Hyundai | E10: S. Korea | F10: 1 | G10: 42370 | H10: =(TODAY()-G10)/365 -> 10.616438 | I10: =$C$34*H10^3+$D$34*H10^2+$E$34*H10+$F$34 -> 102.61781 | J10: =I10*$C$39 -> 110.82723 | K10: 1 | M10: Working Capital | N10: =Balance!Q53/1000 -> 163.971 | O10: =Balance!R53/1000 -> 165.111 | P10: =Balance!S53/1000 -> 165.111 | Q10: =Balance!T53/1000 -> 165.111 | R10: =Balance!U53/1000 -> 165.111 | S10: =Balance!V53/1000 -> 165.111
B11: DHT Lion | C11: VLCC | D11: Hyundai | E11: S. Korea | F11: 1 | G11: 42370 | H11: =(TODAY()-G11)/365 -> 10.616438 | I11: =$C$34*H11^3+$D$34*H11^2+$E$34*H11+$F$34 -> 102.61781 | J11: =I11*$C$39 -> 110.82723 | K11: 1 | M11: Scrubbers | N11: =N23*1.5 -> 0 | O11: =O23*1.5 -> 34.5 | P11: =P23*1.5 -> 34.5 | Q11: =Q23*1.5 -> 34.5 | R11: =R23*1.5 -> 34.5 | S11: =S23*1.5 -> 34.5
B12: DHT Leopard | C12: VLCC | D12: Hyundai | E12: S. Korea | F12: 1 | G12: 42370 | H12: =(TODAY()-G12)/365 -> 10.616438 | I12: =$C$34*H12^3+$D$34*H12^2+$E$34*H12+$F$34 -> 102.61781 | J12: =I12*$C$39 -> 110.82723 | K12: 1 | M12: Net Assets | N12: =SUM(N5:N11) -> 2228.11 | O12: =SUM(O5:O11) -> 2582.374 | P12: =SUM(P5:P11) -> 2666.6483 | Q12: =SUM(Q5:Q11) -> 2683.84 | R12: =SUM(R5:R11) -> 2644.3822 | S12: =SUM(S5:S11) -> 2615.7647
B13: DHT Jaguar | C13: VLCC | D13: Hyundai | E13: S. Korea | F13: 1 | G13: 42005 | H13: =(TODAY()-G13)/365 -> 11.616438 | I13: =$C$34*H13^3+$D$34*H13^2+$E$34*H13+$F$34 -> 97.525089 | J13: =I13*$C$39 -> 105.3271 | K13: 1
B14: DHT Opal | C14: VLCC | D14: Daewoo | E14: S. Korea | F14: 1 | G14: 40909 | H14: =(TODAY()-G14)/365 -> 14.619178 | I14: =$C$34*H14^3+$D$34*H14^2+$E$34*H14+$F$34 -> 80.918348 | J14: =I14*$C$39 -> 87.391816 | K14: 1 | M14: Shares Outstanding | N14: ='P&L'!R40/1000000 -> 161.21597 | O14: ='P&L'!S40/1000000 -> 161.26584 | P14: ='P&L'!T40/1000000 -> 161.21597 | Q14: ='P&L'!U40/1000000 -> 161.21597 | R14: ='P&L'!V40/1000000 -> 161.21597 | S14: ='P&L'!W40/1000000 -> 161.21597
B15: DHT Sundarbans | C15: VLCC | D15: Hyundai | E15: S. Korea | F15: 1 | G15: 40909 | H15: =(TODAY()-G15)/365 -> 14.619178 | I15: =$C$34*H15^3+$D$34*H15^2+$E$34*H15+$F$34 -> 80.918348 | J15: =I15*$C$39 -> 87.391816 | K15: 1
B16: DHT Taiga | C16: VLCC | D16: Hyundai | E16: S. Korea | F16: 1 | G16: 40909 | H16: =(TODAY()-G16)/365 -> 14.619178 | I16: =$C$34*H16^3+$D$34*H16^2+$E$34*H16+$F$34 -> 80.918348 | J16: =I16*$C$39 -> 87.391816 | K16: 1 | M16: Net Asset Value $/sh | N16: =N12/N14 -> 13.820653 | O16: =O12/O14 -> 16.013149 | P16: =P12/P14 -> 16.540845 | Q16: =Q12/Q14 -> 16.647482 | R16: =R12/R14 -> 16.402731 | S16: =S12/S14 -> 16.225221
B17: DHT Amazon | C17: VLCC | D17: Hyundai | E17: S. Korea | F17: 1 | G17: 40544 | H17: =(TODAY()-G17)/365 -> 15.619178 | I17: =$C$34*H17^3+$D$34*H17^2+$E$34*H17+$F$34 -> 75.125038 | J17: =I17*$C$39 -> 81.135041 | K17: 1 | M17: Más DIVI | N17: ='P&L'!Q35 -> 0.41087838 | O17: 0.64 | P17: 1.22 | Q17: ='P&L'!T45 -> 1.3187914 | R17: ='P&L'!U45 -> 1.3320216 | S17: ='P&L'!V45 -> 0.99384772
B18: DHT Redwood | C18: VLCC | D18: Hyundai | E18: S. Korea | F18: 1 | G18: 40544 | H18: =(TODAY()-G18)/365 -> 15.619178 | I18: =$C$34*H18^3+$D$34*H18^2+$E$34*H18+$F$34 -> 75.125038 | J18: =I18*$C$39 -> 81.135041 | K18: 1 | M18: P / NAV | N18: =SUM($M$2/(N16)) -> 1.2908218 | O18: =SUM($M$2/(O16)) -> 1.1140844 | P18: =SUM($M$2/(P16)) -> 1.0785423 | Q18: =SUM($M$2/(Q16+Q17)) -> 0.99297163 | R18: =SUM($M$2/(R16+R17)) -> 1.0059345 | S18: =SUM($M$2/(S16+S17)) -> 1.0360607
B19: DHT Appaloosa | C19: VLCC | D19: Hyundai | E19: S. Korea | F19: 1 | G19: 43101 | H19: =(TODAY()-G19)/365 -> 8.6136986 | I19: =$C$34*H19^3+$D$34*H19^2+$E$34*H19+$F$34 -> 111.84376 | J19: =I19*$C$39 -> 120.79126 | K19: 1
B20: DHT Nokota | C20: VLCC | D20: Hyundai | E20: S. Korea | F20: 1 | G20: 43101 | H20: =(TODAY()-G20)/365 -> 8.6136986 | I20: =$C$34*H20^3+$D$34*H20^2+$E$34*H20+$F$34 -> 111.84376 | J20: =I20*$C$39 -> 120.79126 | K20: 1
B21: DHT Antelope | C21: VLCC | D21: Hanwha | E21: S. Korea | F21: 1 | G21: 46054 | H21: =(TODAY()-G21)/365 -> 0.52328767 | I21: =$C$34*H21^3+$D$34*H21^2+$E$34*H21+$F$34 -> 127.9779 | J21: =I21*$C$39 -> 138.21613 | K21: 1 | M21: Asjusted Fleet Value | P21: 1 | Q21: 0.995 | R21: 0.99 | S21: 0.985
B22: DHT Addax | C22: VLCC | D22: Hanwha | E22: S. Korea | F22: 1 | G22: 46082 | H22: =(TODAY()-G22)/365 -> 0.44657534 | I22: =$C$34*H22^3+$D$34*H22^2+$E$34*H22+$F$34 -> 127.91302 | J22: =I22*$C$39 -> 138.14606 | K22: 1 | M22: Value Growth in % | O22: =O5/N5-1 -> 0.088521336 | P22: =P5/O5-1 -> -0.0042824388 | Q22: =Q5/P5-1 -> -0.005 | R22: =R5/Q5-1 -> -0.0050251256 | S22: =S5/R5-1 -> -0.0050505051
B23: DHT Gazelle | C23: VLCC | D23: Hyundai | E23: S. Korea | F23: 1 | G23: 46082 | H23: =(TODAY()-G23)/365 -> 0.44657534 | I23: =$C$34*H23^3+$D$34*H23^2+$E$34*H23+$F$34 -> 127.91302 | J23: =I23*$C$39 -> 138.14606 | K23: 1 | M23: Scrubber | O23: =COUNT($K$2:$K$24) -> 23 | P23: =COUNT($K$2:$K$24) -> 23 | Q23: =COUNT($K$2:$K$24) -> 23 | R23: =COUNT($K$2:$K$24) -> 23 | S23: =COUNT($K$2:$K$24) -> 23
B24: DHT Impala | C24: VLCC | D24: Hyundai | E24: S. Korea | F24: 1 | G24: 46204 | H24: =(TODAY()-G24)/365 -> 0.11232877 | I24: =$C$34*H24^3+$D$34*H24^2+$E$34*H24+$F$34 -> 127.57238 | J24: =I24*$C$39 -> 137.77818 | K24: 1 | M24: Fleet | O24: =COUNT($H$2:$H$27) -> 23 | P24: =COUNT($H$2:$H$24) -> 23 | Q24: =COUNT($H$2:$H$24) -> 23 | R24: =COUNT($H$2:$H$24) -> 23 | S24: =COUNT($H$2:$H$24) -> 23
B25: DHT Oryx | C25: VLCC | D25: Hanwha | E25: S. Korea | G25: 46753 | K25: 1 | M25: % Fleet with scrubber | O25: 1 | P25: 1 | Q25: 1 | R25: 1 | S25: 1
M27: TCE VLCC | N27: 78800 | O27: 126700 | P27: =152700*0.9 -> 137430 | Q27: =P27*0.98 -> 134681.4 | R27: =Q27*0.8 -> 107745.12 | S27: =R27*0.8 -> 86196.096
B28: Sold | M28: Spot | N28: 14 | O28: 14 | P28: 14 | Q28: 14 | R28: 14 | S28: 14
B29: Newbuilding | M29: % Spot | P29: =P28/P24 -> 0.60869565 | Q29: =Q28/Q24 -> 0.60869565 | R29: =R28/R24 -> 0.60869565 | S29: =S28/S24 -> 0.60869565
M31: *in millions USD, except multiples | Q31: FY 2026 | S31: NTM
M32: Market Value | Q32: =$M$2*Q14 -> 2876.0929 | S32: =$M$2*S14 -> 2876.0929
B33: Linear Estimation: | M33: EV | Q33: =Q32-Q6-Q7-Q8 -> 2966.7054 | S33: =S32-S6-S7-S8 -> 3008.9028
B34: VLCC | C34: ='[2]Cleaves Vessels Value'!$C$11 -> 0.0087407407 | D34: ='[2]Cleaves Vessels Value'!$D$11 -> -0.43149206 | E34: ='[2]Cleaves Vessels Value'!$E$11 -> 1.2579894 | F34: ='[2]Cleaves Vessels Value'!$F$11 -> 127.43651 | M34: Diluted Adj. EPS | Q34: =SUM('P&L'!R45:U45) -> 4.529105 | S34: =SUM('P&L'!T45:W45) -> 4.3679694
M35: Adj. EBITDA | Q35: =SUM('P&L'!R19:U19)/1000 -> 859.39039 | S35: =SUM('P&L'!T19:W19)/1000 -> 839.67441
M36: Dividend | Q36: =SUM(N17:Q17) -> 3.5896698 | S36: =SUM(P17:S17) -> 4.8646608
M37: FCF | Q37: =SUM(CashFlow!R62:U62)/1000 -> 790.74939 | S37: =SUM(CashFlow!T62:W62)/1000 -> 815.18641
B38: Premium by Country: | M38: Adjusted P/E | Q38: =$M$2/Q34 -> 3.938968 | S38: =$M$2/S34 -> 4.0842777
B39: Korea | C39: 1.08 | M39: EV/Adj. EBITDA | Q39: =Q33/Q35 -> 3.4521044 | S39: =S33/S35 -> 3.5834161
B40: Japan | C40: 1.07 | M40: P/FCF | Q40: =$M$2/(Q37/Q14) -> 3.6371737 | S40: =$M$2/(S37/S14) -> 3.5281413
B41: Phillippines | C41: 1.02 | M41: Dividend Yield | Q41: =Q36/$M$2 -> 0.20121468 | S41: =S36/$M$2 -> 0.27268278
B42: Neutral | C42: 1

Sheet P&L
B1: DHT (Thousands $) | C1: =D1-1 -> 2021 | D1: 2022 | E1: 2023 | F1: Q1 2023 | G1: Q2 2023 | H1: Q3 2023 | I1: Q4 2023 | J1: Q1 2024 | K1: Q2 2024 | L1: Q3 2024 | M1: Q4 2024 | N1: Q1 2025 | O1: Q2 2025 | P1: Q3 2025 | Q1: Q4 2025 | R1: Q1 2026 | S1: Q2 2026 | T1: Q3 2026 | U1: Q4 2026 | V1: Q1 2027 | W1: Q2 2027
B2: Shipping Revenues | C2: 295853 | D2: 450382 | E2: =SUM(F2:I2) -> 556075 | F2: 131468 | G2: 151993 | H2: 130322 | I2: 142292 | J2: 145876 | K2: 150066 | L2: 141125 | M2: 130768 | N2: 118165 | O2: 127950 | P2: 107151 | Q2: 143931 | R2: 186285 | S2: 284819 | T2: =SUM(T81:T109)/1000 -> 270462.24 | U2: =SUM(U81:U109)/1000 -> 272595.15 | V2: =SUM(V81:V109)/1000 -> 218076.12 | W2: =SUM(W81:W109)/1000 -> 174460.9
B3: Other revenues | D3: 3765 | F3: 1100 | G3: 1054 | H3: 1243 | I3: 1084 | J3: 1162 | K3: 1171 | L3: 982 | M3: 623 | N3: 409 | O3: 366 | P3: 197 | Q3: 232 | R3: 191 | S3: 193 | T3: 193 | U3: 193 | V3: 193 | W3: 193
B4: Total Revenues | C4: =SUM(C2:C3) -> 295853 | D4: =SUM(D2:D3) -> 454147 | E4: =SUM(E2:E3) -> 556075 | F4: =SUM(F2:F3) -> 132568 | G4: =SUM(G2:G3) -> 153047 | H4: =SUM(H2:H3) -> 131565 | I4: =SUM(I2:I3) -> 143376 | J4: =SUM(J2:J3) -> 147038 | ... W4: =SUM(W2:W3) -> 174653.9
B6: Other income | C6: 4612 | D6: 0 | E6: 0 | F6: 0 | G6: 0 | H6: 0 | I6: 0 | J6: 0 | K6: 0 | L6: 0 | M6: 0 | N6: 0 | O6: 0 | P6: 0 | Q6: 0 | R6: 0 | S6: 0 | T6: 0 | U6: 0 | V6: 0 | W6: 0
B8: Operating expenses
B9: Voyage expenses | C9: -92405 | D9: -185502 | E9: =SUM(F9:I9) -> -165667 | F9: -37569 | G9: -39092 | H9: -41235 | I9: -47771 | J9: -39537 | K9: -46370 | L9: -48484 | M9: -45233 | N9: -38828 | O9: -35131 | P9: -28047 | Q9: -26081 | R9: -29083 | S9: -29856
B10: Vessel operating expenses | C10: -77807 | D10: -73808 | E10: =SUM(F10:I10) -> -75430 | F10: -18417 | G10: -19687 | H10: -18608 | I10: -18718 | J10: -19172 | K10: -20393 | L10: -19048 | M10: -19980 | N10: -17828 | O10: -19605 | P10: -18436 | Q10: -17126 | R10: -19126 | S10: -18579 | T10: -18579 | U10: -18579 | V10: -18579 | W10: -18579
B11: D&A | C11: -128639 | D11: -123255 | E11: =SUM(F11:I11) -> -108903 | F11: -25726 | G11: -26376 | H11: -28326 | I11: -28475 | J11: -28250 | K11: -27878 | L11: -28135 | M11: -27621 | N11: -27270 | O11: -26139 | P11: -25969 | Q11: -26991 | R11: -25647 | S11: -27752 | T11: -27752 | U11: -27752 | V11: -27752 | W11: -27752
B12: Impairment charges | C12: 0 | D12: 0 | E12: 0 | F12: 0 | G12: 0 | H12: 0 | I12: 0 | J12: 0 | K12: 0 | L12: 0 | M12: 0 | N12: 0 | O12: 0 | P12: 0 | Q12: 0 | R12: 0 | S12: 0 | T12: 0 | U12: 0 | V12: 0 | W12: 0
B13: Gain/(loss) sale of vessels | C13: 15153 | D13: 19512 | E13: =SUM(F13:I13) -> 0 | F13: 0 | G13: 0 | H13: 0 | I13: 0 | J13: 0 | K13: 0 | L13: 0 | M13: 27909 | N13: 19795 | O13: 17459 | P13: =15688+970 -> 16658 | R13: 59994 | S13: 0 | T13: 34200 | U13: 0 | V13: 0 | W13: 0
B14: G&A | C14: -16565 | D14: -16890 | E14: =SUM(F14:I14) -> -17448 | F14: -4637 | G14: -4515 | H14: -4303 | I14: -3993 | J14: -4664 | K14: -4521 | L14: -4169 | M14: -5589 | N14: -5548 | O14: -4587 | P14: -4132 | Q14: -5623 | R14: -4957 | S14: -5594 | T14: -5594 | U14: -5594 | V14: -5594 | W14: -5594
B15: Total operating expenses | C15: =SUM(C9:C14) -> -300263 | D15: =SUM(D9:D14) -> -379943 | E15: =SUM(E9:E14) -> -367448 | F15: =SUM(F9:F14) -> -86349 | G15: =SUM(G9:G14) -> -89670 | H15: =SUM(H9:H14) -> -92472 | I15: =SUM(I9:I14) -> -98957 | J15: =SUM(J9:J14) -> -91623 | ... W15: =SUM(W9:W14) -> -51925
B17: Operating (loss)/income | C17: =C4+C6+C15 -> 202 | D17: =D4+D6+D15 -> 74204 | E17: =E4+E6+E15 -> 188627 | F17: =F4+F6+F15 -> 46219 | G17: =G4+G6+G15 -> 63377 | H17: =H4+H6+H15 -> 39093 | I17: =I4+I6+I15 -> 44419 | J17: =J4+J6+J15 -> 55415 | ... W17: =W4+W6+W15 -> 122728.9
B18: EBITDA | C18: =C17-C11 -> 128841 | D18: =D17-D11 -> 197459 | E18: =E17-E11 -> 297530 | F18: =F17-F11 -> 71945 | G18: =G17-G11 -> 89753 | H18: =H17-H11 -> 67419 | I18: =I17-I11 -> 72894 | J18: =J17-J11 -> 83665 | ... W18: =W17-W11 -> 150480.9
B19: Adjusted EBITDA | C19: =C18-C13 -> 113688 | D19: =D18-D13 -> 177947 | E19: =E18-E13 -> 297530 | F19: =F18-F13 -> 71945 | G19: =G18-G13 -> 89753 | H19: =H18-H13 -> 67419 | I19: =I18-I13 -> 72894 | J19: =J18-J13 -> 83665 | ... W19: =W18-W13 -> 150480.9
B21: Share of profit from associated companies | C21: 1278 | D21: 1407 | E21: =SUM(F21:I21) -> 0 | G21: 0 | H21: 0 | I21: 0 | J21: 0 | K21: 0 | L21: 0 | M21: 0 | N21: 0 | O21: 0 | P21: 0 | Q21: 0 | R21: 0 | S21: 0 | T21: 0 | U21: 0 | V21: 0 | W21: 0
B22: Interest income | C22: 6 | D22: -5941 | E22: =SUM(F22:I22) -> 4485 | F22: 398 | G22: 1966 | H22: 1213 | I22: 908 | J22: 1091 | K22: 935 | L22: 1035 | M22: 857 | N22: 793 | O22: 820 | P22: 936 | Q22: 590 | R22: 784 | S22: 1006 | T22: 1006 | U22: 1006 | V22: 1006 | W22: 1006
B23: Interest expense | C23: -25727 | D23: -16471 | E23: =SUM(F23:I23) -> -33061 | F23: -7586 | G23: -7492 | H23: -8789 | I23: -9194 | J23: -8775 | K23: -7921 | L23: -7318 | M23: -6384 | N23: -5106 | O23: -4186 | P23: -2586 | Q23: -2290 | R23: -4424 | S23: -6400 | T23: -6400 | U23: -6400 | V23: -6400 | W23: -6400
B24: Fair value gain/(loss) on derivative financial liabilities | C24: 12450 | D24: 11726 | E24: =SUM(F24:I24) -> -503 | F24: -433 | G24: -70 | H24: 0 | I24: 0 | J24: 0 | K24: 0 | L24: 0 | M24: 0 | N24: 0 | O24: 0 | P24: -354 | Q24: 185 | R24: 1119 | S24: 1290 | T24: 0 | U24: 0 | V24: 0 | W24: 0
B25: Other financial (expense)/income | C25: 645 | D25: -2357 | E25: =SUM(F25:I25) -> -1984 | F25: -366 | G25: -606 | H25: -413 | I25: -599 | J25: -454 | K25: -470 | L25: -719 | M25: -445 | N25: -447 | O25: -885 | P25: -520 | Q25: -544 | R25: -485 | S25: -728 | T25: -728 | U25: -728 | V25: -728 | W25: -728
B26: Profit/(loss) before tax | C26: =C17+SUM(C21:C25) -> -11146 | D26: =D17+SUM(D21:D25) -> 62568 | E26: =E17+SUM(E21:E25) -> 157564 | F26: =F17+SUM(F21:F25) -> 38232 | G26: =G17+SUM(G21:G25) -> 57175 | H26: =H17+SUM(H21:H25) -> 31104 | I26: =I17+SUM(I21:I25) -> 35534 | J26: =J17+SUM(J21:J25) -> 47277 | ... W26: =W17+SUM(W21:W25) -> 116606.9
B28: Income tax expense | C28: -360 | D28: -588 | E28: =SUM(F28:I28) -> -648 | F28: -191 | G28: -94 | H28: -137 | I28: -226 | J28: -206 | K28: -129 | L28: -79 | M28: -194 | N28: -84 | O28: 0 | P28: -93 | Q28: -207 | R28: -126 | S28: -62 | T28: 0 | U28: 0 | V28: 0 | W28: 0
B29: Profit/(loss) after tax | C29: =C26+C28 -> -11506 | D29: =D26+D28 -> 61980 | E29: =E26+E28 -> 156916 | F29: =F26+F28 -> 38041 | G29: =G26+G28 -> 57081 | H29: =H26+H28 -> 30967 | I29: =I26+I28 -> 35308 | J29: =J26+J28 -> 47071 | ... W29: =W26+W28 -> 116606.9
B31: Attributable to owners of non-controlling interest | C31: 14 | D31: 459 | E31: =SUM(F31:I31) -> 44 | F31: -136 | G31: 25 | H31: 208 | I31: -53 | J31: 181 | K31: 143 | L31: -17 | M31: -224 | N31: -71 | O31: -29 | P31: 2 | Q31: 7 | R31: 2 | S31: 2 | T31: 2 | U31: 2 | V31: 2 | W31: 2
B32: Attributable to the owners of parent | C32: =C29-C31 -> -11520 | D32: =D29-D31 -> 61521 | E32: =SUM(F32:I32) -> 161353 | F32: =F29-F31 -> 38177 | G32: =G29-G31 -> 57056 | H32: =H29-H31 -> 30759 | I32: =I29-I31 -> 35361 | J32: =J29-J31 -> 46890 | K32: =K29-K31 -> 44347 | L32: =L29-L31 -> 35207 | M32: =M29-M31 -> 54935 | ... W32: =W29-W31 -> 116604.9
B34: Attributable to the owners of parent
B35: Basic earnings/(loss) per share | C35: -0.07 | D35: 0.37 | E35: =SUM(F35:I35) -> 0.98981453 | F35: 0.23 | G35: 0.35 | H35: =H32*1000/H38 -> 0.19018037 | I35: =I32*1000/I38 -> 0.21963417 | J35: =J32*1000/J38 -> 0.29068032 | K35: =K32*1000/K38 -> 0.27481658 | L35: =L32*1000/L38 -> 0.21804795 | M35: =M32*1000/M38 -> 0.34063452 | N35: =N32*1000/N38 -> 0.27491034 | O35: =O32*1000/O38 -> 0.34912531 | ... W35: =W32*1000/W38 -> 0.72412728
B36: Diluted earnings/(loss) per share | C36: -0.07 | D36: 0.37 | E36: =SUM(F36:I36) -> 0.98933749 | F36: 0.23 | G36: 0.35 | H36: =H32*1000/H40 -> 0.18998527 | I36: =I32*1000/I40 -> 0.21935222 | J36: =J32*1000/J40 -> 0.29047536 | K36: =K32*1000/K40 -> 0.27461738 | L36: =L32*1000/L40 -> 0.21792823 | M36: =M32*1000/M40 -> 0.34047642 | N36: =N32*1000/N40 -> 0.27480274 | O36: =O32*1000/O40 -> 0.34898529 | ... W36: =W32*1000/W40 -> 0.7232838
B38: Weighted average number of shares (basic) | C38: 169089325 | D38: 164692954 | F38: 162967375 | G38: 163037628 | H38: 161735939 | I38: 160999542 | J38: 161311231 | K38: 161369447 | L38: 161464487 | M38: 161272556 | N38: 160495965 | O38: 160661512 | P38: 160799407 | Q38: 160799407 | R38: 161028180 | S38: 161089331 | T38: 161028180 | U38: 161028180 | V38: 161028180 | W38: 161028180
G39: =G38/F38-1 -> 0.00043108628 | H39: =H38/G38-1 -> -0.007983979 | I39: =I38/H38-1 -> -0.004553082 | J39: =J38/I38-1 -> 0.001935962 | K39: =K38/J38-1 -> 0.00036089242 | L39: =L38/K38-1 -> 0.00058895907 | M39: =M38/L38-1 -> -0.0011886886 | N39: =N38/M38-1 -> -0.0048153946 | ... W39: =W38/V38-1 -> 0
B40: Weighted average number of shares (diluted) | C40: 169089325 | D40: 164850097 | F40: 163249977 | G40: 163172987 | H40: 161902025 | I40: 161206487 | J40: 161425054 | K40: 161486503 | L40: 161553185 | M40: 161347445 | N40: 160558807 | O40: 160725972 | P40: 160885603 | Q40: 160918696 | R40: 161215969 | S40: 161265840 | T40: 161215969 | U40: 161215969 | V40: 161215969 | W40: 161215969
G41: =G40/F40-1 -> -0.00047160803 | H41: =H40/G40-1 -> -0.0077890466 | I41: =I40/H40-1 -> -0.0042960426 | J41: =J40/I40-1 -> 0.0013558201 | K41: =K40/J40-1 -> 0.00038066582 | L41: =L40/K40-1 -> 0.00041292615 | M41: =M40/L40-1 -> -0.0012735125 | N41: =N40/M40-1 -> -0.0048878245 | ... W41: =W40/V40-1 -> 0
B44: Adjusted Profit after tax | F44: =F19+F11+F21+F22+F23+F24+F25+F28+F31 -> 37905 | G44: =G19+G11+G21+G22+G23+G24+G25+G28+G31 -> 57106 | H44: =H19+H11+H21+H22+H23+H24+H25+H28+H31 -> 31175 | I44: =I19+I11+I21+I22+I23+I24+I25+I28+I31 -> 35255 | J44: =J19+J11+J21+J22+J23+J24+J25+J28+J31 -> 47252 | K44: =K19+K11+K21+K22+K23+K24+K25+K28+K31 -> 44633 | L44: =L19+L11+L21+L22+L23+L24+L25+L28+L31 -> 35173 | M44: =M19+M11+M21+M22+M23+M24+M25+M28+M31 -> 26578 | ... W44: =W19+W11+W21+W22+W23+W24+W25+W28+W31 -> 116608.9
B45: Diluted Adj. EPS | F45: =F44*1000/F40 -> 0.23218993 | G45: =G44*1000/G40 -> 0.34997214 | H45: =H44*1000/H40 -> 0.19255473 | I45: =I44*1000/I40 -> 0.21869467 | J45: =J44*1000/J40 -> 0.29271788 | K45: =K44*1000/K40 -> 0.27638842 | L45: =L44*1000/L40 -> 0.21771778 | M45: =M44*1000/M40 -> 0.16472526 | ... W45: =W44*1000/W40 -> 0.72330861
A48: x | B48: Operating Days | F48: SCRUBBER | G48: ECO
B49: DHT Mustang | F49: 1 | G49: 1 | H49: 87 | I49: 88 | J49: 88 | K49: 88 | L49: 90 | M49: 91 | N49: 90 | O49: 90 | P49: 90 | Q49: 90 | T49: 88 | U49: 88 | V49: 88 | W49: 88
B50: DHT Bronco | F50: 1 | G50: 1 | H50: 87 | I50: 88 | J50: 88 | K50: 88 | L50: 90 | M50: 91 | N50: 90 | O50: 90 | P50: 90 | Q50: 90 | T50: 88 | U50: 88 | V50: 88 | W50: 88
B51: DHT Colt | F51: 1 | G51: 1 | H51: 87 | I51: 88 | J51: 88 | K51: 88 | L51: 90 | M51: 91 | N51: 90 | O51: 90 | P51: 90 | Q51: 90 | T51: 88 | U51: 88 | V51: 88 | W51: 88
B52: DHT Stallion | F52: 1 | G52: 1 | H52: 87 | I52: 88 | J52: 88 | K52: 88 | L52: 90 | M52: 91 | N52: 90 | O52: 90 | P52: 90 | Q52: 90 | T52: 88 | U52: 88 | V52: 88 | W52: 88
...

Sheet Balance
B1: DHT (Thousands $) | C1: =D1-1 -> 2021 | D1: 2022 | E1: Q1 2023 | F1: Q2 2023 | G1: Q3 2023 | H1: Q4 2023 | I1: Q1 2024 | J1: Q2 2024 | K1: Q3 2024 | L1: Q4 2024 | M1: Q1 2025 | N1: Q2 2025 | O1: Q3 2025 | P1: Q4 2025 | Q1: Q1 2026 | R1: Q2 2026 | S1: Q3 2026 | T1: Q4 2026 | U1: Q1 2027 | V1: Q2 2027
B2: Current Assets | C2: =SUM(C3:C9) -> 131972 | D2: =SUM(D3:D9) -> 235590 | E2: =SUM(E3:E9) -> 213214 | F2: =SUM(F3:F9) -> 234317 | G2: =SUM(G3:G9) -> 179227 | H2: =SUM(H3:H9) -> 200498 | I2: =SUM(I3:I9) -> 203397 | J2: =SUM(J3:J9) -> 195748 | ... V2: =SUM(V3:V9) -> 340632.05
B3: Cash and cash equivalents | C3: 60658 | D3: 125948 | E3: 117549 | F3: 130649 | G3: 73920 | H3: 74738 | I3: 73076 | J3: 72642 | K3: 73829 | L3: 78143 | M3: 80510 | N3: 82660 | O3: 81250 | P3: 79034 | Q3: 126246 | R3: 161683 | S3: =CashFlow!T59 -> 245728.97 | T3: =CashFlow!U59 -> 264501.54 | U3: =CashFlow!V59 -> 226624.64 | V3: =CashFlow!W59 -> 199588.05
B4: Accounts receivable and accrued revenues | C4: 30361 | D4: 59465 | E4: 55010 | F4: 56831 | G4: 55684 | H4: 75848 | I4: 80561 | J4: 70355 | K4: 58553 | L4: 53715 | M4: 50520 | N4: 40047 | O4: 33953 | P4: 53338 | Q4: 85288 | R4: 87059 | S4: 87059 | T4: 87059 | U4: 87059 | V4: 87059
B5: Capitalized voyage expenses | C5: 1395 | D5: 2799 | E5: 3487 | F5: 2192 | G5: 2817 | H5: 2549 | I5: 4679 | J5: 6051 | K5: 2848 | L5: 2450 | M5: 2645 | N5: 1568 | O5: 1465 | P5: 1684 | Q5: 1701 | R5: 2826 | S5: 2826 | T5: 2826 | U5: 2826 | V5: 2826
B6: Prepaid expenses | C6: 6162 | D6: 10550 | E6: 9440 | F6: 10287 | G6: 9023 | H6: 13557 | I6: 7650 | J6: 9894 | K6: 12999 | L6: 7200 | M6: 5327 | N6: 4326 | O6: 6426 | P6: 9678 | Q6: 6501 | R6: 6624 | S6: 6624 | T6: 6624 | U6: 6624 | V6: 6624
B7: Derivative financial assets | C7: 0 | D7: 3759 | E7: 70 | G7: 0 | H7: 0 | I7: 0 | J7: 0 | K7: 0 | L7: 0 | M7: 0 | N7: 0 | O7: 0 | P7: 10 | Q7: 355 | R7: 923 | S7: 923 | T7: 923 | U7: 923 | V7: 923
B8: Inventories | C8: 33396 | D8: 33069 | E8: 27658 | F8: 34358 | G8: 37783 | H8: 33806 | I8: 37431 | J8: 36806 | K8: 33299 | L8: 37688 | M8: 33033 | N8: 30679 | O8: 23498 | P8: 24682 | Q8: 30241 | R8: 26835 | S8: 26835 | T8: 26835 | U8: 26835 | V8: 26835
B9: Assets held for sale | C9: 0 | D9: 0 | E9: 0 | F9: 0 | G9: 0 | H9: 0 | I9: 0 | J9: 0 | K9: 0 | L9: 22693 | N9: 34424 | O9: 0 | P9: 40488 | Q9: 16777 | R9: 16777 | S9: 16777 | T9: 16777 | U9: 16777 | V9: 16777
B11: Non-Current Assets | C11: =SUM(C12:C18) -> 1477390 | D11: =SUM(D12:D18) -> 1272886 | E11: =SUM(E12:E18) -> 1264323 | F11: =SUM(F12:F18) -> 1255535 | G11: =SUM(G12:G18) -> 1318248 | H11: =SUM(H12:H18) -> 1291725 | I11: =SUM(I12:I18) -> 1268890 | J11: =SUM(J12:J18) -> 1292295 | ... P11: =SUM(P12:P18) -> 1394034 | Q11: =SUM(Q12:Q19) -> 1517981 | R11: =SUM(R12:R19) -> 1505249 | S11: =SUM(S12:S19) -> 1460197 | T11: =SUM(T12:T19) -> 1432445 | U11: =SUM(U12:U19) -> 1404693 | V11: =SUM(V12:V19) -> 1376941
B12: Vessels | C12: 1467846 | D12: 1261998 | E12: 1254056 | F12: 1237411 | G12: 1311892 | H12: 1283710 | I12: 1261388 | J12: 1233164 | K12: 1207533 | L12: 1185576 | M12: 1158750 | N12: 1067472 | O12: 1042035 | P12: 1083891 | Q12: 1452955 | R12: 1433693 | S12: =R12+'P&L'!T11+Balance!S59-CashFlow!T10-CashFlow!T33 -> 1388641 | T12: =S12+'P&L'!U11+Balance!T59-CashFlow!U10-CashFlow!U33 -> 1360889 | U12: =T12+'P&L'!V11+Balance!U59-CashFlow!V10-CashFlow!V33 -> 1333137 | V12: =U12+'P&L'!W11+Balance!V59-CashFlow!W10-CashFlow!W33 -> 1305385
B13: Advances for vessels under construction | C13: 0 | D13: 0 | E13: 0 | F13: 0 | G13: 0 | H13: 0 | I13: 0 | J13: 51866 | K13: 78870 | L13: 93178 | M13: 120679 | N13: 161326 | O13: 190884 | P13: 301651 | Q13: 55676 | R13: 56974 | S13: 56974 | T13: 56974 | U13: 56974 | V13: 56974
B14: Advances for vessel upgrades | C14: 372 | D14: 4583 | E14: 4594 | F14: 11369 | G14: 15 | H14: 10 | I14: 160 | J14: 382 | K14: 0 | L14: 0 | M14: 0 | N14: 0 | O14: 11924 | P14: 7117 | Q14: 7399 | R14: 3245 | S14: 3245 | T14: 3245 | U14: 3245 | V14: 3245
B15: Other PPE | C15: 3766 | D15: 4949 | E15: 4317 | F15: 5399 | G15: 4985 | H15: 6649 | I15: 5986 | J15: 5527 | K15: 5263 | L15: 4589 | M15: 5218 | N15: 6549 | O15: 5256 | P15: 1356 | Q15: 1356 | R15: 6673 | S15: 6673 | T15: 6673 | U15: 6673 | V15: 6673
B16: Investment in associate company | C16: 5406 | D16: 0 | E16: 0 | F16: 0 | G16: 0 | H16: 0 | I16: 0 | J16: 0 | K16: 0 | L16: 0 | M16: 0 | N16: 0 | O16: 0 | P16: 0 | Q16: 0 | R16: 0 | S16: 0 | T16: 0 | U16: 0 | V16: 0
B17: Prepaid expenses | Q17: 0 | R17: 1991 | S17: 1991 | T17: 1991 | U17: 1991 | V17: 1991
B18: Goodwill | C18: 0 | D18: 1356 | E18: 1356 | F18: 1356 | G18: 1356 | H18: 1356 | I18: 1356 | J18: 1356 | K18: 1356 | L18: 1356 | M18: 1356 | N18: 1356 | O18: 1356 | P18: 19 | Q18: 595 | R18: 1356 | S18: 1356 | T18: 1356 | U18: 1356 | V18: 1356
B19: Derivative financial assets | Q19: 0 | R19: 1317 | S19: 1317 | T19: 1317 | U19: 1317 | V19: 1317
B21: Total Assets | C21: =SUM(C2+C11) -> 1609362 | D21: =SUM(D2+D11) -> 1508476 | E21: =SUM(E2+E11) -> 1477537 | F21: =SUM(F2+F11) -> 1489852 | G21: =SUM(G2+G11) -> 1497475 | H21: =SUM(H2+H11) -> 1492223 | I21: =SUM(I2+I11) -> 1472287 | J21: =SUM(J2+J11) -> 1488043 | ... V21: =SUM(V2+V11) -> 1717573.1
B24: Current liabilities | C24: =SUM(C25:C29) -> 41945 | D24: =SUM(D25:D29) -> 64374 | E24: =SUM(E25:E29) -> 61243 | F24: =SUM(F25:F29) -> 75160 | G24: =SUM(G25:G29) -> 78755 | H24: =SUM(H25:H29) -> 56605 | I24: =SUM(I25:I29) -> 61723 | J24: =SUM(J25:J29) -> 68204 | ... V24: =SUM(V25:V29) -> 37677
B25: Accounts payable and accrued expenses | C25: 19662 | D25: 29398 | E25: 22020 | F25: 29302 | G25: 25111 | H25: 20493 | I25: 24150 | J25: 21495 | K25: 22711 | L25: 23436 | M25: 20303 | N25: 25092 | O25: 21505 | P25: 22761 | Q25: 33933 | R25: 24077 | S25: 24077 | T25: 24077 | U25: 24077 | V25: 24077
B26: Derivative financial liabilities | C26: 7002 | D26: 29626 | E26: 0 | F26: 0 | G26: 0 | H26: 0 | I26: 0 | J26: 0 | K26: 0 | L26: 0 | M26: 0 | N26: 0 | O26: 111 | P26: 68 | Q26: 0 | R26: 0 | S26: 0 | T26: 0 | U26: 0 | V26: 0
B27: Current portion long-term debt | C27: 9792 | D27: 1178 | E27: 33109 | F27: 38947 | G27: 47933 | H27: 30300 | I27: 36161 | J27: 42025 | K27: 48340 | L27: 78649 | M27: 78774 | N27: 49074 | O27: 31551 | P27: 39500 | Q27: 104647 | R27: 45432
B28: Other current liabilities | C28: 624 | D28: 4172 | E28: 1022 | F28: 1401 | G28: 1317 | H28: 1418 | I28: 1412 | J28: 1437 | K28: 1509 | L28: 1389 | M28: 1350 | N28: 1150 | O28: 925 | P28: 994 | Q28: 914 | R28: 1224 | S28: 1224 | T28: 1224 | U28: 1224 | V28: 1224
B29: Deferred shipping revenues | C29: 4865 | D29: 0 | E29: 5092 | F29: 5510 | G29: 4394 | H29: 4394 | I29: 0 | J29: 3247 | K29: 2711 | L29: 6139 | M29: 7501 | N29: 7963 | O29: 6710 | P29: 11397 | Q29: 6593 | R29: 12376 | S29: 12376 | T29: 12376 | U29: 12376 | V29: 12376
B31: Non-Current Liabilities | C31: =SUM(C32:C34) -> 520059 | D31: =SUM(D32:D34) -> 370614 | E31: =SUM(E32:E34) -> 365740 | F31: =SUM(F32:F34) -> 353152 | G31: =SUM(G32:G34) -> 392204 | H31: =SUM(H32:H34) -> 403952 | I31: =SUM(I32:I34) -> 366547 | J31: =SUM(J32:J34) -> 377113 | ... V31: =SUM(V32:V34) -> 395205
B32: Long-term debt | C32: 512507 | D32: 367069 | E32: 362616 | F32: 349352 | G32: 388647 | H32: 398425 | I32: 361619 | J32: 372579 | K32: 359289 | L32: 330775 | M32: 285298 | N32: 253731 | O32: 236976 | P32: 389244 | Q32: 400696 | R32: 389372 | S32: =(R32+R27)-(45432/4) -> 423446 | T32: =(S32+S27)-(45432/4) -> 412088 | U32: =(T32+T27)-(45432/4) -> 400730 | V32: =(U32+U27)-(45432/4) -> 389372
B33: Derivative financial liabilities | C33: 4222 | D33: 0 | E33: 0 | F33: 0 | G33: 0 | H33: 0 | I33: 0 | J33: 0 | K33: 0 | L33: 0 | M33: 0 | N33: 0 | O33: 0 | P33: 0 | Q33: 0 | R33: 0 | S33: 0 | T33: 0 | U33: 0 | V33: 0
B34: Other non-current liabilities | C34: 3330 | D34: 3545 | E34: 3124 | F34: 3800 | G34: 3557 | H34: 5527 | I34: 4928 | J34: 4534 | K34: 4305 | L34: 3497 | M34: 3355 | N34: 4457 | O34: 4357 | P34: 5598 | Q34: 5528 | R34: 5833 | S34: 5833 | T34: 5833 | U34: 5833 | V34: 5833
B36: Total Liabilities | C36: =C24+C31 -> 562004 | D36: =D24+D31 -> 434988 | E36: =E24+E31 -> 426983 | F36: =F24+F31 -> 428312 | G36: =G24+G31 -> 470959 | H36: =H24+H31 -> 460557 | I36: =I24+I31 -> 428270 | J36: =J24+J31 -> 445317 | ... V36: =V24+V31 -> 432882
B38: Total Equity | C38: 1047359 | D38: 1073486 | E38: 1050553 | F38: 1061542 | G38: 1026515 | H38: 1031667 | I38: 1044060 | J38: 1042727 | K38: 1035686 | L38: 1042701 | M38: 1061457 | N38: 1088938 | O38: 1095669 | P38: 1133257 | Q38: 1232779 | R38: 1329663 | S38: =R38+'P&L'!T29+CashFlow!T41+CashFlow!T46 -> 1380016.9 | T38: =S38+'P&L'!U29+CashFlow!U41+CashFlow!U46 -> 1382395.4 | U38: =T38+'P&L'!V29+CashFlow!V41+CashFlow!V46 -> 1328124.5 | V38: =U38+'P&L'!W29+CashFlow!W41+CashFlow!W46 -> 1284693.9
B40: Total Equity and Liabilities | C40: =C38+C36 -> 1609363 | D40: =D38+D36 -> 1508474 | E40: =E38+E36 -> 1477536 | F40: =F38+F36 -> 1489854 | G40: =G38+G36 -> 1497474 | H40: =H38+H36 -> 1492224 | I40: =I38+I36 -> 1472330 | J40: =J38+J36 -> 1488044 | ... V40: =V38+V36 -> 1717575.9
B41: Check | C41: =C21-C40 -> -1 | D41: =D21-D40 -> 2 | E41: =E21-E40 -> 1 | F41: =F21-F40 -> -2 | G41: =G21-G40 -> 1 | H41: =H21-H40 -> -1 | I41: =I21-I40 -> -43 | J41: =J21-J40 -> -1 | ... V41: =V21-V40 -> -2.89326
A44: x | B44: Debt
B45: Financial Debt | C45: =C27+C32 -> 522299 | D45: =D27+D32 -> 368247 | E45: =E27+E32 -> 395725 | F45: =F27+F32 -> 388299 | G45: =G27+G32 -> 436580 | H45: =H27+H32 -> 428725 | I45: =I27+I32 -> 397780 | J45: =J27+J32 -> 414604 | ... V45: =V27+V32 -> 389372
B46: Growth rate YoY % | D46: =D45/C45-1 -> -0.29494983 | E46: =E45/D45-1 -> 0.074618395 | F46: =F45/E45-1 -> -0.018765557 | G46: =G45/F45-1 -> 0.12433975 | H46: =H45/G45-1 -> -0.017992121 | I46: =I45/H45-1 -> -0.072179136 | J46: =J45/I45-1 -> 0.042294736 | K46: =K45/J45-1 -> -0.016823282 | ... V46: =V45/U45-1 -> -0.028343274
B47: Net Financial Debt | C47: =C45-C3 -> 461641 | D47: =D45-D3 -> 242299 | E47: =E45-E3 -> 278176 | F47: =F45-F3 -> 257650 | G47: =G45-G3 -> 362660 | H47: =H45-H3 -> 353987 | I47: =I45-I3 -> 324704 | J47: =J45-J3 -> 341962 | ... V47: =V45-V3 -> 189783.95
B48: Growth rate YoY%
A51: x | B51: Working Capital
B53: Working Capital | C53: =(C4+C5+C6+C8+C13+C14+C9)-(C25+C29-C28) -> 47783 | D53: =(D4+D5+D6+D8+D13+D14+D9)-(D25+D29-D28) -> 85240 | E53: =(E4+E5+E6+E8+E13+E14+E9)-(E25+E29-E28) -> 74099 | F53: =(F4+F5+F6+F8+F13+F14+F9)-(F25+F29-F28) -> 81626 | G53: =(G4+G5+G6+G8+G13+G14+G9)-(G25+G29-G28) -> 77134 | H53: =(H4+H5+H6+H8+H13+H14+H9)-(H25+H29-H28) -> 102301 | I53: =(I4+I5+I6+I8+I13+I14+I9)-(I25+I29-I28) -> 107743 | J53: =(J4+J5+J6+J8+J13+J14+J9)-(J25+J29-J28) -> 152049 | ... V53: =(V4+V5+V6+V8+V13+V14+V9)-(V25+V29-V28) -> 165111
...

Sheet CashFlow
B1: DHT (Thousands $) | C1: =D1-1 -> 2021 | D1: 2022 | E1: 2023 | F1: Q1 2023 | G1: Q2 2023 | H1: Q3 2023 | I1: Q4 2023 | J1: Q1 2024 | K1: Q2 2024 | L1: Q3 2024 | M1: Q4 2024 | N1: Q1 2025 | O1: Q2 2025 | P1: Q3 2025 | Q1: Q4 2025 | R1: Q1 2026 | S1: Q2 2026 | T1: Q3 2026 | U1: Q4 2026 | V1: Q1 2027 | W1: Q2 2027
B2: Profit/(loss) after tax | C2: ='P&L'!C29 -> -11506 | D2: ='P&L'!D29 -> 61980 | E2: ='P&L'!E29 -> 156916 | F2: ='P&L'!F29 -> 38041 | G2: ='P&L'!G29 -> 57081 | H2: ='P&L'!H29 -> 30967 | I2: ='P&L'!I29 -> 35308 | J2: ='P&L'!J29 -> 47071 | ... N2: ='P&L'!N29 -> 44051 | O2: 56032 | P2: ='P&L'!P29 -> 44805 | Q2: ='P&L'!Q29 -> 66076 | R2: ='P&L'!R29 -> 164525 | S2: 198339 | T2: ='P&L'!T29 -> 246808.24 | U2: ='P&L'!U29 -> 214741.15 | V2: ='P&L'!V29 -> 160222.12 | W2: ='P&L'!W29 -> 116606.9
B4: Items included in net income not affecting cash flows | C4: =SUM(C5:C17) -> 103606 | D4: =SUM(D5:D17) -> 94232 | E4: =SUM(E5:E17) -> 114902 | F4: =SUM(F5:F17) -> 27204 | G4: =SUM(G5:G17) -> 28140 | H4: =SUM(H5:H17) -> 29705 | I4: =SUM(I5:I17) -> 29853 | J4: =SUM(J5:J17) -> 29956 | ... Q4: =SUM(Q5:Q17) -> 28002 | R4: -35959 | S4: 28481 | T4: =SUM(T5:T17) -> -6448 | U4: =SUM(U5:U17) -> 27752 | V4: =SUM(V5:V17) -> 27752 | W4: =SUM(W5:W17) -> 27752
B5: D&A | C5: 128639 | D5: 123255 | E5: =SUM(F5:I5) -> 108903 | F5: 25726 | G5: 26376 | H5: 28326 | I5: 28475 | J5: 28250 | K5: =-'P&L'!K11 -> 27878 | L5: =-'P&L'!L11 -> 28135 | M5: =-'P&L'!M11 -> 27621 | N5: =-'P&L'!N11 -> 27270 | O5: 26139 | P5: =-'P&L'!P11 -> 25969 | Q5: 26991 | R5: =-'P&L'!R11 -> 25647 | S5: 27752 | T5: =-'P&L'!T11 -> 27752 | U5: =-'P&L'!U11 -> 27752 | V5: =-'P&L'!V11 -> 27752 | W5: =-'P&L'!W11 -> 27752
B6: Impairment charges | C6: 0 | D6: 0 | E6: 0 | F6: 0 | G6: 0 | H6: 0 | I6: 0 | J6: 0 | K6: 0 | L6: 0 | M6: -27909 | N6: 0 | O6: 0 | P6: 0 | Q6: 0 | R6: 0 | S6: 0 | T6: 0 | U6: 0 | V6: 0 | W6: 0
B7: Amortization of upfront fees | C7: 2550 | D7: 2281 | E7: =SUM(F7:I7) -> 0 | R7: 581 | S7: 0 | T7: 0 | U7: 0 | V7: 0 | W7: 0
B8: Amortization of deferred debt issuance cost | C8: 0 | D8: 621 | E8: =SUM(F8:I8) -> 2971 | F8: 836 | G8: 722 | H8: 664 | I8: 749 | J8: 680 | K8: 662 | L8: 652 | M8: 633 | N8: 601 | O8: 816 | P8: 544 | Q8: 491 | R8: 0 | S8: 1039 | T8: 0 | U8: 0 | V8: 0 | W8: 0
B9: (Gain)/loss, disposal of PPE | C9: 0 | D9: 0 | E9: =SUM(F9:I9) -> 17 | F9: 9 | H9: 8 | J9: 0 | K9: 0 | L9: 0 | M9: 0 | N9: 0 | O9: 0 | P9: 0 | Q9: 0 | R9: 0 | S9: 28 | T9: 0 | U9: 0 | V9: 0 | W9: 0
B10: (Gain)/loss, disposal of vessel | C10: -15153 | D10: -19512 | E10: =SUM(F10:I10) -> 0 | F10: 0 | G10: 0 | H10: 0 | I10: 0 | J10: 0 | K10: 0 | L10: 0 | M10: 0 | N10: -19795 | O10: -17459 | P10: -15688 | Q10: 0 | R10: -59994 | S10: 0 | T10: -34200 | U10: 0 | V10: 0 | W10: 0
B11: Capitalized interest | C11: 0 | D11: 0 | E11: 0 | F11: 0 | G11: 0 | H11: 0 | I11: 0 | J11: 0 | K11: 0 | L11: 0 | M11: 0 | N11: 0 | O11: 0 | P11: 0 | Q11: 0 | R11: -2170 | S11: -665 | T11: 0 | U11: 0 | V11: 0 | W11: 0
B12: Fair value (gain)/loss on derivative financial instruments | C12: -12450 | D12: -14983 | E12: =SUM(F12:I12) -> 503 | F12: 433 | G12: 70 | J12: 0 | K12: 0 | L12: 0 | M12: 0 | N12: 0 | O12: 0 | P12: 354 | Q12: -185 | R12: -1119 | S12: -1290 | T12: 0 | U12: 0 | V12: 0 | W12: 0
B13: Impairment of equity accounted investment | D13: 637 | E13: =SUM(F13:I13) -> 0 | S13: 0 | T13: 0 | U13: 0 | V13: 0 | W13: 0
B14: Compensation related to options and restricted stock | C14: 4347 | D14: 4133 | E14: =SUM(F14:I14) -> 3233 | F14: 891 | G14: 976 | H14: 716 | I14: 650 | J14: 991 | K14: 1005 | L14: 903 | M14: 1392 | N14: 1850 | O14: 1208 | P14: 661 | Q14: 661 | R14: 989 | S14: 1620 | T14: 0 | U14: 0 | V14: 0 | W14: 0
B15: Net foreign exchange differences | D15: -204 | E15: =SUM(F15:I15) -> -32 | F15: 2 | G15: -4 | H15: -9 | I15: -21 | J15: 35 | K15: 9 | L15: -58 | M15: 23 | N15: 70 | O15: 296 | P15: -90 | Q15: 44 | R15: 108 | S15: -2 | T15: 0 | U15: 0 | V15: 0 | W15: 0
B16: (Gain)/loss modification of debt | C16: -3049 | D16: -669 | E16: =SUM(F16:I16) -> -693 | F16: -693 | G16: 0 | H16: 0 | I16: 0 | J16: 0 | K16: 0 | L16: 0 | M16: 0 | N16: 0 | O16: 0 | P16: 0 | Q16: 0 | R16: 0 | S16: 0 | T16: 0 | U16: 0 | V16: 0 | W16: 0
B17: Share of profit in associated companies | C17: -1278 | D17: -1327 | E17: =SUM(F17:I17) -> 0 | F17: 0 | G17: 0 | H17: 0 | I17: 0 | J17: 0 | K17: 0 | L17: 0 | M17: 0 | N17: 0 | O17: 0 | P17: 0 | Q17: 0 | R17: 0 | S17: 0 | T17: 0 | U17: 0 | V17: 0 | W17: 0
B18: Income adjusted for non-cash items | C18: =C2+C4 -> 92100 | D18: =D2+D4 -> 156212 | E18: =E2+E4 -> 271818 | F18: =F2+F4 -> 65245 | G18: =G2+G4 -> 85221 | H18: =H2+H4 -> 60672 | I18: =I2+I4 -> 65161 | J18: =J2+J4 -> 77027 | ... W18: =W2+W4 -> 144358.9
B20: Changes in operating assets and liabilities: | C20: =SUM(C21:C27) -> -31538 | D20: =SUM(D21:D27) -> -28436 | E20: =SUM(E21:E27) -> -24890 | F20: =SUM(F21:F27) -> 1209 | G20: =SUM(G21:G27) -> 1744 | H20: =SUM(H21:H27) -> -4948 | I20: =SUM(I21:I27) -> -22895 | J20: =SUM(J21:J27) -> -7160 | ... S20: =SUM(S21:S27) -> -7285 | T20: =-(Balance!S53-Balance!R53) -> 0 | U20: =-(Balance!T53-Balance!S53) -> 0 | V20: =-(Balance!U53-Balance!T53) -> 0 | W20: =-(Balance!V53-Balance!U53) -> 0
B21: Accounts receivable and accrued revenues | C21: -301 | D21: -28702 | E21: =SUM(F21:I21) -> -16383 | F21: 4454 | G21: -1820 | H21: 1147 | I21: -20164 | J21: -4713 | K21: 10206 | L21: 11802 | M21: 4838 | N21: 2517 | O21: 10655 | P21: 6153 | Q21: -19730 | R21: -30418 | S21: -1771
B22: Capitalized voyage expenses | C22: -356 | D22: -1403 | E22: =SUM(F22:I22) -> 250 | F22: -688 | G22: 1295 | H22: -625 | I22: 268 | J22: -2129 | K22: -1373 | L22: 3203 | M22: 398 | N22: -195 | O22: 1078 | P22: 106 | Q22: -222 | R22: -18 | S22: -1124
B23: Prepaid expenses | C23: 523 | D23: -3538 | E23: =SUM(F23:I23) -> -3009 | F23: 1109 | G23: -847 | H23: 1264 | I23: -4535 | J23: 5907 | K23: -2244 | L23: -3105 | M23: 5800 | N23: 1873 | O23: 1001 | P23: -2100 | Q23: -3252 | R23: 3177 | S23: -2115
B24: Accounts payable and accrued expenses | C24: 1510 | D24: 5641 | E24: =SUM(F24:I24) -> -4938 | F24: -9932 | G24: 9506 | H24: -2214 | I24: -2298 | J24: 1894 | K24: -1626 | L24: 410 | M24: -645 | N24: -5047 | O24: 995 | P24: -5745 | Q24: -1409 | R24: 7792 | S24: -11464
B25: Deferred shipping revenues | C25: -11372 | D25: -692 | E25: =SUM(F25:I25) -> 222 | F25: 920 | G25: 418 | H25: -1116 | I25: 0 | J25: -4394 | K25: 3247 | L25: -535 | M25: 3427 | N25: 1362 | O25: 462 | P25: -1253 | Q25: 4687 | R25: -4804 | S25: 5783
B26: Bunker inventory | C26: -21542 | D26: 327 | E26: =SUM(F26:I26) -> -737 | F26: 5411 | G26: -6700 | H26: -3425 | I26: 3977 | J26: -3625 | K26: 625 | L26: 3508 | M26: -4389 | N26: 4655 | O26: 2354 | P26: 7180 | Q26: -1184 | R26: -5559 | S26: 3406
B27: Pension liability | D27: -69 | E27: =SUM(F27:I27) -> -295 | F27: -65 | G27: -108 | H27: 21 | I27: -143 | J27: -100 | K27: -20 | L27: 40 | M27: -114 | N27: 0 | O27: 0 | P27: 0 | Q27: 0 | R27: 0 | S27: 0
A28: x | B28: Net Cash provided by operating activities | C28: =C18+C20 -> 60562 | D28: =D18+D20 -> 127776 | E28: =E18+E20 -> 246928 | F28: =F18+F20 -> 66454 | G28: =G18+G20 -> 86965 | H28: =H18+H20 -> 55724 | I28: =I18+I20 -> 42266 | J28: =J18+J20 -> 69867 | ... W28: =W18+W20 -> 144358.9
B31: Investment in vessels | C31: -174558 | D31: -9902 | E31: =SUM(F31:I31) -> -128082 | F31: -14829 | G31: -18125 | H31: -92943 | I31: -2185 | J31: -3832 | K31: -798 | L31: -2004 | M31: -54 | N31: -25809 | O31: -1146 | P31: -12350 | Q31: -97629 | R31: -2849 | S31: -7202 | T31: =-Balance!S59 -> 0 | U31: =-Balance!T59 -> 0 | V31: =-Balance!U59 -> 0 | W31: =-Balance!V59 -> 0
B32: Investment in vessels under construction | C32: 0 | D32: 0 | E32: 0 | F32: 0 | G32: 0 | H32: 0 | I32: 0 | J32: -43 | K32: -51454 | L32: -25840 | M32: -12858 | O32: -38714 | P32: -26167 | Q32: -107821 | R32: -159971 | S32: -1283 | T32: 0 | U32: 0 | V32: 0 | W32: 0
B33: Proceeds from sale of vessels | C33: 87062 | D33: 112399 | E33: =SUM(F33:I33) -> 0 | F33: 0 | G33: 0 | H33: 0 | I33: 0 | J33: 0 | K33: 0 | L33: 0 | M33: 0 | N33: 42489 | O33: 50942 | P33: 50090 | Q33: 0 | R33: 101009 | S33: -522 | T33: 51500 | U33: 0 | V33: 0 | W33: 0
B34: Investment in subsidiaries | D34: -2 | E34: =SUM(F34:I34) -> 0 | F34: 0 | G34: 0 | H34: 0 | I34: 0 | J34: 0 | K34: 0 | L34: 0 | M34: 0 | N34: 0 | O34: 0 | P34: 0 | Q34: 0 | R34: 0 | S34: 0 | T34: 0 | U34: 0 | V34: 0 | W34: 0
B35: Acquisition of subsidiary, net of cash paid | D35: 8267 | E35: =SUM(F35:I35) -> 0 | F35: 0 | G35: 0 | H35: 0 | I35: 0 | J35: 0 | K35: 0 | L35: 0 | M35: 0 | N35: 0 | O35: 0 | P35: 0 | Q35: 0 | R35: 0 | S35: 0 | T35: 0 | U35: 0 | V35: 0 | W35: 0
B36: Dividend received from associated company | C36: 1031 | D36: 0 | E36: =SUM(F36:I36) -> 0 | F36: 0 | G36: 0 | H36: 0 | I36: 0 | J36: 0 | K36: 0 | L36: 0 | M36: 0 | N36: 0 | O36: 0 | P36: 0 | Q36: 0 | R36: 0 | S36: 0 | T36: 0 | U36: 0 | V36: 0 | W36: 0
B37: Investment in other PPE | C37: -48 | D37: -243 | E37: =SUM(F37:I37) -> -151 | F37: -35 | G37: -10 | H37: -89 | I37: -17 | J37: -3 | K37: -19 | L37: -47 | M37: -80 | N37: -5 | O37: -18 | P37: -65 | Q37: -218 | R37: -166 | S37: -158 | T37: 0 | U37: 0 | V37: 0 | W37: 0
A38: x | B38: Investing Cash Flow | C38: =SUM(C31:C37) -> -86513 | D38: =SUM(D31:D37) -> 110519 | E38: =SUM(E31:E37) -> -128233 | F38: =SUM(F31:F37) -> -14864 | G38: =SUM(G31:G37) -> -18135 | H38: =SUM(H31:H37) -> -93032 | I38: =SUM(I31:I37) -> -2202 | J38: =SUM(J31:J37) -> -3878 | ... W38: =SUM(W31:W37) -> 0
B41: Cash dividends paid | C41: -22083 | D41: -19678 | E41: =SUM(F41:I41) -> -186673 | F41: -61935 | G41: -37487 | H41: -56661 | I41: -30590 | J41: -35492 | K41: -46786 | L41: -43595 | M41: -35522 | N41: -27286 | O41: -24091 | P41: =-(0.24*('P&L'!P38/1000)) -> -38591.858 | Q41: =-(0.18*('P&L'!Q38/1000)) -> -28943.893 | R41: -66027 | S41: -103067 | T41: =-(1.22*('P&L'!T38/1000)) -> -196454.38 | U41: =-('P&L'!T45*('P&L'!U38/1000)) -> -212362.59 | V41: =-('P&L'!U45*('P&L'!V38/1000)) -> -214493.01 | W41: =-('P&L'!V45*('P&L'!W38/1000)) -> -160037.49
B42: Acquisition of non-controlling interest | C42: 0 | D42: 0 | E42: 0 | F42: 0 | G42: 0 | H42: 0 | I42: 0 | J42: 0 | K42: 0 | L42: 0 | M42: 0 | N42: 0 | O42: -6131 | P42: 0 | S42: 0 | T42: 0 | U42: 0 | V42: 0 | W42: 0
B43: Dividends paid to non-controlling interest | C43: 0 | D43: 0 | E43: =SUM(F43:I43) -> -590 | G43: -590 | I43: 0 | P43: 0 | S43: 0 | T43: 0 | U43: 0 | V43: 0 | W43: 0
B44: Repayment principal element of lease liability | C44: -611 | D44: -1089 | E44: =SUM(F44:I44) -> -1424 | F44: -386 | G44: -350 | H44: -346 | I44: -342 | J44: -340 | K44: -340 | L44: -354 | M44: -357 | N44: -353 | O44: -351 | P44: -364 | Q44: -338 | R44: -340 | S44: -306 | T44: 0 | U44: 0 | V44: 0 | W44: 0
B45: Issuance of long-term debt | C45: 355840 | D45: 4008 | E45: =SUM(F45:I45) -> 339633 | F45: 216399 | G45: -208 | H45: 99492 | I45: 23950 | J45: 49999 | K45: 25000 | L45: 0 | M45: 10000 | N45: 10000 | O45: 54663 | P45: 0 | Q45: 233360 | R45: 316462 | S45: -22 | T45: 0 | U45: 0 | V45: 0 | W45: 0
B46: Purchase of treasury shares | C46: -32178 | D46: -24758 | E46: =SUM(F46:I46) -> -18808 | F46: 0 | G46: -8866 | H46: -9942 | M46: -13196 | P46: 0 | S46: 0 | T46: 0 | U46: 0 | V46: 0 | W46: 0
...
