Workbook

Sheet Cover
A3: Okeanis Eco Tankers Corp. | F3: Copyright:
A4: OET, ECO | F4: Ourios Analytics
F5: ourios.com
F6: info@ourios.com
A10: DISCLAIMER
A11: The financial models and projections provided herein are based on internal assumptions, historical data, and current market trends (such as charter rates, fuel costs, and vessel valuations) which are subject to high volatility and change without notice.
A12: These models are intended for illustrative and informational purposes only. They do not constitute financial, investment, or legal advice. While we strive for accuracy, we make no guarantees regarding the future performance of any asset or the realization of the projected returns.
A16: COPYRIGHT
A17: This Excel model and its contents are the exclusive property of Ourios Analytics. No part of this file may be reproduced, distributed, transmitted, or shared in any form or by any means, without the prior written permission of Ourios Analytics.
A18: Authorized use must strictly include a clear citation of the source: "Source: Ourios Analytics".
A22: COLORS USED IN FINANCIAL DATA
A23: In green: | B23: Data copied from last quarter or reported by company
A24: In blue: | B24: Our own assumption
A25: In black: | B25: Automatically filled
A26: In yellow | B26: Yellow cells can be changed to make assumptions
A30: NAV Tab Content
A31: Fleet list: | B31: Vessel name, type of vessel, year built, Yard, Country, scrubber, neutral value and corrected value by premium coefficient
A32: Price to update: | B32: Share price, that it´s update from Valuations_Master
A33: NAV calculation: | B33: Net Asset Value calculation
A34: Adjusted fleet value: | B34: Change this coefficient if you think the value is going up or down. Default we leave it in 1.
A35: Value growth in %: | B35: Change in % between quarters
A36: Scrubbers: | B36: How many scrubbers are installed in the vessels, reported by the company.
A37: Fleet : | B37: How many vessels has the company
A38: % Fleet with scrubber: | B38: As it titles says, % fleet with scrubber
A39: TCE: | B39: Time Charter Equivalent, based in data reported by the company or own assumptions
A40: Financial data: | B40: Market Cap, Enterprise Value, Adjusted Earnings, Adjusted EBITDA, Levered FCF, Adjusted P/E, Adjusted EV/EBITDA and P/FCF
A41: Linear Estimation: | B41: Don´t remove or change this data. It´s to automatically calculate vessels value from the Master
A42: Coefficient added by premium: | B42: Correction factor depending on the country of construction or others
A44: Fleet colours by status:
A45: No color: | B45: In the fleet list
A46: Pink: | B46: Sold vessel reported by the company
A47: Orange: | B47: Newbuilding or acquired vessel reported by the company
A48: Blue: | B48: Chartered-in or Bareboat-in
A50: Remember: If you want to make assumptions, just change yellow cells
A53: P&L Tab Content
A54: P&L from company reports
A55: Operating days: | B55: You can change it on your own
A56: TCE revenue per vessel: | B56: Operating days x TCE assumption
A58: Notes:
A59: Estimating revenues are from TCE and operating days. For that reason, voyage expenses use to be in grey background. We prepare the TCE revenues looking at what the company say about it.
...

Sheet NAV
B1: Vessel | C1: Type | D1: Yard | E1: Country | F1: Ownership | G1: Built | H1: Age | I1: Value | J1: Premium | K1: Scrub. | M1: Price:
B2: Milos | C2: Suezmax | D2: Sungdong | E2: S. Korea | F2: 1 | G2: 42644 | H2: =(TODAY()-G2)/365 -> 9.8767123 | I2: =$C$38*H2^3+$D$38*H2^2+$E$38*H2+$F$38 -> 76.377824 | J2: =I2*$C$29 -> 82.48805 | K2: 1 | M2: ='[1]Stock Master'!$C$2 -> 59.9
B3: Poliegos | C3: Suezmax | D3: Sungdong | E3: S. Korea | F3: 1 | G3: 42736 | H3: =(TODAY()-G3)/365 -> 9.6246575 | I3: =$C$38*H3^3+$D$38*H3^2+$E$38*H3+$F$38 -> 77.101385 | J3: =I3*$C$29 -> 83.269496 | K3: 1
B4: Kimolos | C4: Suezmax | D4: Japan Marine | E4: Japan | F4: 1 | G4: 43221 | H4: =(TODAY()-G4)/365 -> 8.2958904 | I4: =$C$38*H4^3+$D$38*H4^2+$E$38*H4+$F$38 -> 80.806053 | J4: =I4*$C$29 -> 87.270537 | K4: 1 | M4: Net Asset Value | N4: Q1 2026 | O4: Q2 2026 | P4: Q3 2026 | Q4: Q4 2026 | R4: Q1 2027 | S4: Q2 2027
B5: Folegandros | C5: Suezmax | D5: Japan Marine | E5: Japan | F5: 1 | G5: 43344 | H5: =(TODAY()-G5)/365 -> 7.9589041 | I5: =$C$38*H5^3+$D$38*H5^2+$E$38*H5+$F$38 -> 81.718404 | J5: =I5*$C$29 -> 88.255877 | K5: 1 | M5: Fleet Value | N5: 1733.13 | O5: 1877.43 | P5: =SUM($J$2:$J$19)*P19 -> 2028.7464 | Q5: =SUM($J$2:$J$19)*Q19 -> 2018.6026 | R5: =SUM($J$2:$J$19)*R19 -> 2008.4589 | S5: =SUM($J$2:$J$19)*S19 -> 1998.3152
B6: Nissos Sikinos | C6: Suezmax | D6: Hyundai Samho | E6: S. Korea | F6: 1 | G6: 44075 | H6: =(TODAY()-G6)/365 -> 5.9561644 | I6: =$C$38*H6^3+$D$38*H6^2+$E$38*H6+$F$38 -> 86.947983 | J6: =I6*$C$29 -> 93.903822 | K6: 1 | M6: Financial Debt | N6: =-Balance!I45/1000000 -> -683.14896 | O6: =-Balance!J45/1000000 -> -722.55541 | P6: =-Balance!K45/1000000 -> -709.62882 | Q6: =-Balance!L45/1000000 -> -696.70224 | R6: =-Balance!M45/1000000 -> -683.77565 | S6: =-Balance!N45/1000000 -> -670.84906
B7: Nissos Sifnos | C7: Suezmax | D7: Hyundai Samho | E7: S. Korea | F7: 1 | G7: 44075 | H7: =(TODAY()-G7)/365 -> 5.9561644 | I7: =$C$38*H7^3+$D$38*H7^2+$E$38*H7+$F$38 -> 86.947983 | J7: =I7*$C$29 -> 93.903822 | K7: 1 | M7: Cash | N7: =(Balance!I8+Balance!I17+Balance!I18)/1000000 -> 176.5197 | O7: =(Balance!J8+Balance!J17+Balance!J18)/1000000 -> 247.8069 | P7: =(Balance!K8+Balance!K17+Balance!K18)/1000000 -> 205.31073 | Q7: =(Balance!L8+Balance!L17+Balance!L18)/1000000 -> 182.00598 | R7: =(Balance!M8+Balance!M17+Balance!M18)/1000000 -> 130.75527 | S7: =(Balance!N8+Balance!N17+Balance!N18)/1000000 -> 89.716395
B8: Nissos Piperi | C8: Suezmax | D8: Daehan | E8: S. Korea | F8: 1 | G8: 46023 | H8: =(TODAY()-G8)/365 -> 0.61917808 | I8: =$C$38*H8^3+$D$38*H8^2+$E$38*H8+$F$38 -> 99.873943 | J8: =I8*$C$29 -> 107.86386 | K8: 1 | M8: Working Capital | N8: =Balance!I53/1000000 -> 127.02728 | O8: =Balance!J53/1000000 -> 159.99267 | P8: =Balance!K53/1000000 -> 139.85941 | Q8: =Balance!L53/1000000 -> 139.85941 | R8: =Balance!M53/1000000 -> 139.85941 | S8: =Balance!N53/1000000 -> 139.85941
B9: Nissos Serifopoula | C9: Suezmax | D9: Daehan | E9: S. Korea | F9: 1 | G9: 46023 | H9: =(TODAY()-G9)/365 -> 0.61917808 | I9: =$C$38*H9^3+$D$38*H9^2+$E$38*H9+$F$38 -> 99.873943 | J9: =I9*$C$29 -> 107.86386 | K9: 1 | M9: Scrubbers | N9: =N21*2 -> 0 | O9: =O21*2 -> 0 | P9: =P21*2 -> 36 | Q9: =Q21*2 -> 36 | R9: =R21*2 -> 36 | S9: =S21*2 -> 36
B10: Nissos Tigani | C10: Suezmax | D10: Daehan | E10: S. Korea | F10: 1 | G10: 46143 | H10: =(TODAY()-G10)/365 -> 0.29041096 | I10: =$C$38*H10^3+$D$38*H10^2+$E$38*H10+$F$38 -> 100.65068 | J10: =I10*$C$29 -> 108.70273 | K10: 1 | M10: Net Assets | N10: =SUM(N5:N9) -> 1353.528 | O10: =SUM(O5:O9) -> 1562.6742 | P10: =SUM(P5:P9) -> 1700.2877 | Q10: =SUM(Q5:Q9) -> 1679.7658 | R10: =SUM(R5:R9) -> 1631.2979 | S10: =SUM(S5:S9) -> 1593.0419
B11: Nissos Vous | C11: Suezmax | D11: Daehan | E11: S. Korea | F11: 1 | G11: 46204 | H11: 0 | I11: =$C$38*H11^3+$D$38*H11^2+$E$38*H11+$F$38 -> 101.33705 | J11: =I11*$C$29 -> 109.44401 | K11: 1
B12: Nissos Rhenia | C12: VLCC | D12: Hyundai HI | E12: S. Korea | F12: 1 | G12: 43586 | H12: =(TODAY()-G12)/365 -> 7.2958904 | I12: =$C$37*H12^3+$D$37*H12^2+$E$37*H12+$F$37 -> 119.13901 | J12: =I12*$C$29 -> 128.67013 | K12: 1 | M12: Shares Outstanding | N12: ='P&L'!I43/1000000 -> 38.161939 | O12: ='P&L'!J43/1000000 -> 39.044655 | P12: ='P&L'!K43/1000000 -> 39.044655 | Q12: ='P&L'!L43/1000000 -> 39.044655 | R12: ='P&L'!M43/1000000 -> 39.044655 | S12: ='P&L'!N43/1000000 -> 39.044655
B13: Nissos Despotiko | C13: VLCC | D13: Hyundai HI | E13: S. Korea | F13: 1 | G13: 43617 | H13: =(TODAY()-G13)/365 -> 7.2109589 | I13: =$C$37*H13^3+$D$37*H13^2+$E$37*H13+$F$37 -> 119.52057 | J13: =I13*$C$29 -> 129.08221 | K13: 1
B14: Nissos Donoussa | C14: VLCC | D14: Hyundai HI | E14: S. Korea | F14: 1 | G14: 43678 | H14: =(TODAY()-G14)/365 -> 7.0438356 | I14: =$C$37*H14^3+$D$37*H14^2+$E$37*H14+$F$37 -> 120.26943 | J14: =I14*$C$29 -> 129.89099 | K14: 1 | M14: Net Asset Value $/sh | N14: =N10/N12 -> 35.46801 | O14: =O10/O12 -> 40.022742 | P14: =P10/P12 -> 43.547259 | Q14: =Q10/Q12 -> 43.021658 | R14: =R10/R12 -> 41.780314 | S14: =S10/S12 -> 40.800512
B15: Nissos Kythnos | C15: VLCC | D15: Hyundai HI | E15: S. Korea | F15: 1 | G15: 43709 | H15: =(TODAY()-G15)/365 -> 6.9589041 | I15: =$C$37*H15^3+$D$37*H15^2+$E$37*H15+$F$37 -> 120.64902 | J15: =I15*$C$29 -> 130.30094 | K15: 1 | M15: Más DIVI | N15: 1.55 | O15: 2 | P15: 5.25 | Q15: ='P&L'!K39 -> 6.1941015 | R15: ='P&L'!L39 -> 5.6021332 | S15: ='P&L'!M39 -> 4.2944213
B16: Nissos Keros | C16: VLCC | D16: Hyundai HI | E16: S. Korea | F16: 1 | G16: 43739 | H16: =(TODAY()-G16)/365 -> 6.8767123 | I16: =$C$37*H16^3+$D$37*H16^2+$E$37*H16+$F$37 -> 121.01573 | J16: =I16*$C$29 -> 130.69699 | K16: 1 | M16: P / NAV | N16: =SUM($M$2/(N12)) -> 1.5696267 | O16: =SUM($M$2/(O14)) -> 1.4966491 | P16: =SUM($M$2/(P14)) -> 1.3755171 | Q16: =SUM($M$2/(Q14+Q15)) -> 1.2170898 | R16: =SUM($M$2/(R14+R15)) -> 1.2641812 | S16: =SUM($M$2/(S14+S15)) -> 1.3283089
B17: Nissos Anafi | C17: VLCC | D17: Hyundai HI | E17: S. Korea | F17: 1 | G17: 43831 | H17: =(TODAY()-G17)/365 -> 6.6246575 | I17: =$C$37*H17^3+$D$37*H17^2+$E$37*H17+$F$37 -> 122.13644 | J17: =I17*$C$29 -> 131.90735 | K17: 1
B18: Nissos Kea | C18: VLCC | D18: Hyundai HI | E18: S. Korea | F18: 1 | G18: 44621 | H18: =(TODAY()-G18)/365 -> 4.460274 | I18: =$C$37*H18^3+$D$37*H18^2+$E$37*H18+$F$37 -> 131.51937 | J18: =I18*$C$29 -> 142.04092 | K18: 1
B19: Nissos Nikouria | C19: VLCC | D19: HHI-Ulsan | E19: S. Korea | F19: 1 | G19: 44713 | H19: =(TODAY()-G19)/365 -> 4.2082192 | I19: =$C$37*H19^3+$D$37*H19^2+$E$37*H19+$F$37 -> 132.58405 | J19: =I19*$C$29 -> 143.19077 | K19: 1 | M19: Asjusted Fleet Value | P19: 1 | Q19: 0.995 | R19: 0.99 | S19: 0.985
M20: Value Growth in % | P20: =P5/O5-1 -> 0.080597611 | Q20: =Q5/P5-1 -> -0.005 | R20: =R5/Q5-1 -> -0.0050251256 | S20: =S5/R5-1 -> -0.0050505051
M21: Scrubber | P21: =COUNT($K$2:$K$19) -> 18 | Q21: =COUNT($K$2:$K$19) -> 18 | R21: =COUNT($K$2:$K$19) -> 18 | S21: =COUNT($K$2:$K$19) -> 18
M22: Fleet | P22: =COUNT($H$2:$H$19) -> 18 | Q22: =COUNT($H$2:$H$19) -> 18 | R22: =COUNT($H$2:$H$19) -> 18 | S22: =COUNT($H$2:$H$19) -> 18
B23: Sold | M23: % Fleet with scrubber | P23: =(P22/P21) -> 1 | Q23: =(Q22/Q21) -> 1 | R23: =(R22/R21) -> 1 | S23: =(S22/S21) -> 1
B24: Newbuilding
M25: TCE VLCC | O25: 187700 | P25: =206000*0.85 -> 175100 | Q25: =P25*0.9 -> 157590 | R25: =Q25*0.8 -> 126072 | S25: =R25*0.8 -> 100857.6
M26: TCE Suezmax | O26: 174900 | P26: =133000*0.9 -> 119700 | Q26: =P26*0.9 -> 107730 | R26: =Q26*0.8 -> 86184 | S26: =R26*0.8 -> 68947.2
M27: % Spot | O27: 0.91 | P27: 0.94
B28: Premium by Country:
B29: Korea | C29: 1.08 | M29: *in millions USD, except multiples | Q29: FY 2026 | S29: NTM
B30: Japan | C30: 1.07 | M30: Market Value | Q30: =$M$2*Q12 -> 2338.7748 | S30: =$M$2*S12 -> 2338.7748
B31: Phillippines | C31: 1.02 | M31: EV | Q31: =Q30-Q6-Q7 -> 2853.4711 | S31: =S30-S6-S7 -> 2919.9075
B32: Neutral | C32: 1 | M32: Diluted Adj. EPS | Q32: =SUM('P&L'!I48:L48) -> 20.04289 | S32: =SUM('P&L'!K48:N48) -> 19.338908
M33: Adj. EBITDA | Q33: =SUM('P&L'!I18:L18)/1000000 -> 865.78062 | S33: =SUM('P&L'!K18:N18)/1000000 -> 841.7631
M34: Dividend | Q34: =SUM(N15:Q15) -> 14.994102 | S34: =SUM(P15:S15) -> 21.340656
M35: Levered FCF | Q35: =SUM(CashFlow!I64:L64)/1000000 -> 428.34938 | S35: =SUM(CashFlow!K64:N64)/1000000 -> 726.85439
B36: Linear Estimation: | M36: Adjusted P/E | Q36: =$M$2/Q32 -> 2.988591 | S36: =$M$2/S32 -> 3.0973828
B37: VLCC | C37: ='[1]Vessels Values Master'!$D$90 -> 4.4444444e-06 | D37: ='[1]Vessels Values Master'!$E$90 -> -0.046066667 | E37: ='[1]Vessels Values Master'!$F$90 -> -3.8249206 | F37: ='[1]Vessels Values Master'!$G$90 -> 149.49562 | M37: EV/Adj. EBITDA | Q37: =Q31/Q33 -> 3.2958362 | S37: =S31/S33 -> 3.4687996
B38: Suezmax | C38: ='[1]Vessels Values Master'!$D$91 -> -0.0019955556 | D38: ='[1]Vessels Values Master'!$E$91 -> 0.0032190476 | E38: ='[1]Vessels Values Master'!$F$91 -> -2.3642063 | F38: ='[1]Vessels Values Master'!$G$91 -> 101.33705 | M38: P/FCF | Q38: =$M$2/(Q35/Q12) -> 5.4599701 | S38: =$M$2/(S35/S12) -> 3.2176662
M39: Dividend Yield | Q39: =Q34/$M$2 -> 0.25031889 | S39: =S34/$M$2 -> 0.35627139

Sheet P&L
B1: Okeanis (in US Dollars) | C1: 2023 | D1: 2024 | E1: Q1 2025 | F1: Q2 2025 | G1: Q3 2025 | H1: Q4 2025 | I1: Q1 2026 | J1: Q2 2026 | K1: Q3 2026 | L1: Q4 2026 | M1: Q1 2027 | N1: Q2 2027
B2: Revenue | C2: 413096606 | D2: 393229831 | E2: 80147652 | F2: 93947134 | G2: 90602272 | H2: 126851761 | I2: 170165016 | J2: 318852577 | K2: =SUM(K73:K90) -> 278409000 | L2: =SUM(L73:L90) -> 255295800 | M2: =SUM(M73:M90) -> 204236640 | N2: =SUM(N73:N90) -> 163389312
B4: Operating expenses
B5: Commisions | C5: -5757159 | D5: -3997596 | E5: -674183 | F5: -1334189 | G5: -994764 | H5: -1259509 | I5: -1703196 | J5: -2557297
B6: Voyage expenses | C6: -109559239 | D6: -127196305 | E6: -30917090 | F6: -28600049 | G6: -29661111 | H6: -32692334 | I6: -36241351 | J6: -48155183
B7: Vessel operating expenses | C7: -41742285 | D7: -42434258 | E7: -10499058 | F7: -11546813 | G7: -11739327 | H7: -11455249 | I7: -12231071 | J7: -13336181 | K7: -13336181 | L7: -13336181 | M7: -13336181 | N7: -13336181
B8: Management fees - related party | C8: -4599000 | D8: -4611600 | E8: -1134000 | F8: -1146600 | G8: -1159200 | H8: -1159200 | I8: -1391600 | J8: -1459220
B9: D&A | C9: -40382628 | D9: -41134237 | E9: -10222121 | F9: -10343401 | G9: -10436705 | H9: -10438324 | I9: -12013349 | J9: -12735038 | K9: -12735038 | L9: -12735038 | M9: -12735038 | N9: -12735038
B10: G&A | C10: -9933373 | D10: -10910862 | E10: -4421136 | F10: -4041931 | G10: -1882078 | H10: -1259755 | I10: -8527108 | J10: -1555733 | K10: -1555733 | L10: -1555733 | M10: -1555733 | N10: -1555733
B11: Impairment loss on classification of vessels as held for sale | C11: 0 | D11: 0 | E11: 0 | F11: 0 | G11: 0 | H11: 0 | I11: 0 | J11: 0 | K11: 0 | L11: 0 | M11: 0 | N11: 0
B12: Net gain on disposal of vessels | C12: 0 | D12: 0 | E12: 0 | F12: 0 | G12: 0 | H12: 0 | I12: 0 | J12: 0 | K12: 0 | L12: 0 | M12: 0 | N12: 0
B13: Total operating expenses | C13: =SUM(C5:C12) -> -211973684 | D13: =SUM(D5:D12) -> -230284858 | E13: =SUM(E5:E12) -> -57867588 | F13: =SUM(F5:F12) -> -57012983 | G13: =SUM(G5:G12) -> -55873185 | H13: =SUM(H5:H12) -> -58264371 | I13: =SUM(I5:I12) -> -72107675 | J13: =SUM(J5:J12) -> -79798652 | ... N13: =SUM(N5:N12) -> -27626952
B15: Operating (loss)/profit | C15: =C2+C13 -> 201122922 | D15: =D2+D13 -> 162944973 | E15: =E2+E13 -> 22280064 | F15: =F2+F13 -> 36934151 | G15: =G2+G13 -> 34729087 | H15: =H2+H13 -> 68587390 | I15: =I2+I13 -> 98057341 | J15: =J2+J13 -> 239053925 | ... N15: =N2+N13 -> 135762360
B17: EBITDA | C17: =C15-C9 -> 241505550 | D17: =D15-D9 -> 204079210 | E17: =E15-E9 -> 32502185 | F17: =F15-F9 -> 47277552 | G17: =G15-G9 -> 45165792 | H17: =H15-H9 -> 79025714 | I17: =I15-I9 -> 110070690 | J17: =J15-J9 -> 251788963 | ... N17: =N15-N9 -> 148497398
B18: Adjusted EBITDA | C18: =C17-C11-C12 -> 241505550 | D18: =D17-D11-D12 -> 204079210 | E18: =E17-E11-E12 -> 32502185 | F18: =F17-F11-F12 -> 47277552 | G18: =G17-G11-G12 -> 45165792 | H18: =H17-H11-H12 -> 79025714 | I18: =I17-I11-I12 -> 110070690 | J18: =J17-J11-J12 -> 251788963 | ... N18: =N17-N11-N12 -> 148497398
B20: Other income / (expenses)
B21: Interest income | C21: 4104564 | D21: 3445203 | E21: 408133 | F21: 407470 | G21: 563460 | H21: 812677 | I21: 1051202 | J21: 1379880 | K21: 1000000 | L21: 1000000 | M21: 1000000 | N21: 1000000
B22: Interest expense and other finance costs | C22: -61179066 | D22: -57052680 | E22: -11405292 | F22: -11632771 | G22: -11008312 | H22: -10194138 | I22: -10330556 | J22: -9935491 | K22: -9935491 | L22: -9935491 | M22: -9935491 | N22: -9935491
B23: Unrealized (loss) / gain, net on derivatives | C23: 229373 | D23: -291873 | E23: 1114601 | F23: 1351339 | G23: -372070 | H23: -440406 | I23: -627457 | J23: 905854 | K23: 0 | L23: 0 | M23: 0 | N23: 0
B24: Realized gain / (loss), net on derivatives | C24: 300262 | D24: -1264750 | E24: -92329 | F24: 489497 | G24: 207772 | H24: 722457 | I24: 345830 | J24: 319460 | K24: 0 | L24: 0 | M24: 0 | N24: 0
B25: Gain / (loss) on debt extinguishment | F25: -1125951 | G25: -257817 | H25: 0 | I25: 0 | J25: -1363059 | K25: 0 | L25: 0 | M25: 0 | N25: 0
B26: Gain from modification of loans | D26: 1828959 | E26: 0 | F26: 0 | G26: 0 | H26: 0 | I26: 0 | J26: 0 | K26: 0 | L26: 0 | M26: 0 | N26: 0
B27: Foreign exchange gain / (loss) | C27: 672969 | D27: -746562 | E27: 250756 | F27: 463174 | G27: 188453 | H27: -29852 | I27: -178657 | J27: -49321 | K27: 0 | L27: 0 | M27: 0 | N27: 0
B28: Total other income / (expenses) | C28: =SUM(C21:C27) -> -55871898 | D28: =SUM(D21:D27) -> -54081703 | E28: =SUM(E21:E27) -> -9724131 | F28: =SUM(F21:F27) -> -10047242 | G28: =SUM(G21:G27) -> -10678514 | H28: =SUM(H21:H27) -> -9129262 | I28: =SUM(I21:I27) -> -9739638 | J28: =SUM(J21:J27) -> -8742677 | ... N28: =SUM(N21:N27) -> -8935491
B30: Profit/(loss) after tax | C30: =C15+C28 -> 145251024 | D30: =D15+D28 -> 108863270 | E30: =E15+E28 -> 12555933 | F30: =F15+F28 -> 26886909 | G30: =G15+G28 -> 24050573 | H30: =H15+H28 -> 59458128 | I30: =I15+I28 -> 88317703 | J30: =J15+J28 -> 230311248 | ... N30: =N15+N28 -> 126826869
B32: Other comprehensive income / (loss)
B33: Items that will not be reclassified to profit or loss: | C33: 0 | D33: 0 | E33: 0 | F33: 0 | G33: 0 | H33: 0 | I33: 0 | J33: 0 | K33: 0 | L33: 0 | M33: 0 | N33: 0
B34: Re-measurement of post-employment benefit obligations | C34: -1302 | D34: -6005 | E34: 0 | F34: 0 | G34: 0 | H34: 0 | I34: 0 | J34: 0 | K34: 0 | L34: 0 | M34: 0 | N34: 0
B35: Total comprehensive (loss)/income for the year | C35: =C30+C34 -> 145249722 | D35: =D30+D34 -> 108857265 | E35: =E30+E34 -> 12555933 | F35: =F30+F34 -> 26886909 | G35: =G30+G34 -> 24050573 | H35: =H30+H34 -> 59458128 | I35: =I30+I34 -> 88317703 | J35: =J30+J34 -> 230311248 | ... N35: =N30+N34 -> 126826869
B38: Basic earnings/(loss) per share | C38: =C35/C41 -> 4.5116865 | D38: =D35/D41 -> 3.3812791 | E38: =E35/E41 -> 0.39000717 | F38: =F35/F41 -> 0.83514999 | G38: =G35/G41 -> 0.7470489 | H38: =H35/H41 -> 1.7639074 | I38: =I35/I41 -> 2.3142876 | J38: =J35/J41 -> 5.8986626 | ... N38: =N35/N41 -> 3.2482518
B39: Diluted earnings/(loss) per share | C39: =C35/C43 -> 4.5116865 | D39: =D35/D43 -> 3.3812791 | E39: =E35/E43 -> 0.39000717 | F39: =F35/F43 -> 0.83514999 | G39: =G35/G43 -> 0.7470489 | H39: =H35/H43 -> 1.7639074 | I39: =I35/I43 -> 2.3142876 | J39: =J35/J43 -> 5.8986626 | ... N39: =N35/N43 -> 3.2482518
B41: Weighted average number of shares (basic) | C41: 32194108 | D41: 32194108 | E41: 32194108 | F41: 32194108 | G41: 32194108 | H41: 33708192 | I41: 38161939 | J41: 39044655 | K41: 39044655 | L41: 39044655 | M41: 39044655 | N41: 39044655
F42: =F41/E41-1 -> 0 | G42: =G41/F41-1 -> 0 | H42: =H41/G41-1 -> 0.047029848 | I42: =I41/H41-1 -> 0.13212655 | J42: =J41/I41-1 -> 0.023130795 | K42: =K41/J41-1 -> 0 | L42: =L41/K41-1 -> 0 | M42: =M41/L41-1 -> 0 | N42: =N41/M41-1 -> 0
B43: Weighted average number of shares (diluted) | C43: 32194108 | D43: 32194108 | E43: 32194108 | F43: 32194108 | G43: 32194108 | H43: 33708192 | I43: 38161939 | J43: 39044655 | K43: 39044655 | L43: 39044655 | M43: 39044655 | N43: 39044655
F44: =F43/E43-1 -> 0 | G44: =G43/F43-1 -> 0 | H44: =H43/G43-1 -> 0.047029848 | I44: =I43/H43-1 -> 0.13212655 | J44: =J43/I43-1 -> 0.023130795 | K44: =K43/J43-1 -> 0 | L44: =L43/K43-1 -> 0 | M44: =M43/L43-1 -> 0 | N44: =N43/M43-1 -> 0
B47: Adjusted Profit after tax | C47: =C15-C11-C12+-C23-C24-C25-C26-C27+C34+C21+C22 -> 142844514 | D47: =D15-D11-D12+-D23-D24-D25-D26-D27+D34+D21+D22 -> 109805717 | E47: =E15-E11-E12+-E23-E24-E25-E26-E27+E34+E21+E22 -> 10009877 | F47: =F15-F11-F12+-F23-F24-F25-F26-F27+F34+F21+F22 -> 24530791 | G47: =G15-G11-G12+-G23-G24-G25-G26-G27+G34+G21+G22 -> 24517897 | H47: =H15-H11-H12+-H23-H24-H25-H26-H27+H34+H21+H22 -> 58953730 | I47: =I15-I11-I12+-I23-I24-I25-I26-I27+I34+I21+I22 -> 89238271 | J47: =J15-J11-J12+-J23-J24-J25-J26-J27+J34+J21+J22 -> 230685380 | ... N47: =N15-N11-N12+-N23-N24-N25-N26-N27+N34+N21+N22 -> 126826869
B48: Diluted Adj. EPS | C48: =C47/C43 -> 4.4369769 | D48: =D47/D43 -> 3.4107395 | E48: =E47/E43 -> 0.31092264 | F48: =F47/F43 -> 0.76196523 | G48: =G47/G43 -> 0.76156472 | H48: =H47/H43 -> 1.7489437 | I48: =I47/I43 -> 2.3384103 | J48: =J47/J43 -> 5.9082448 | ... N48: =N47/N43 -> 3.2482518
A51: x | B51: Operating Days
B52: Milos | I52: Suezmax | K52: 90 | L52: 90 | M52: 90 | N52: 90
B53: Poliegos | I53: Suezmax | K53: 90 | L53: 90 | M53: 90 | N53: 90
...

Sheet Balance
B1: Okeanis (in US Dollars) | C1: 2023 | D1: 2024 | E1: Q1 2025 | F1: Q2 2025 | G1: Q3 2025 | H1: Q4 2025 | I1: Q1 2026 | J1: Q2 2026 | K1: Q3 2026 | L1: Q4 2026 | M1: Q1 2027 | N1: Q2 2027
B2: Non-Current Assets | C2: =SUM(C3:C8) -> 991165432 | D2: =SUM(D3:D8) -> 963187726 | E2: =SUM(E3:E8) -> 953664711 | F2: =SUM(F3:F8) -> 946286937 | G2: =SUM(G3:G8) -> 933398139 | H2: =SUM(H3:H8) -> 965700400 | I2: =SUM(I3:I8) -> 1151235754 | J2: =SUM(J3:J8) -> 1223485048 | ... N2: =SUM(N3:N8) -> 1251711637
B3: Vessels, net | C3: 988068180 | D3: 958597520 | E3: 948625667 | F3: 938668044 | G3: 928329593 | H3: 922117179 | I3: 1105213636 | J3: 1193612396 | K3: =J3+'P&L'!K9+Balance!K58 -> 1280177358 | L3: =K3+'P&L'!L9+Balance!L58 -> 1267442320 | M3: =L3+'P&L'!M9+Balance!M58 -> 1254707282 | N3: =M3+'P&L'!N9+Balance!N58 -> 1241972244
B4: Advances for acquisition of vessels | H4: 38894251 | I4: 39737420 | J4: 20133259 | K4: 0 | L4: 0 | M4: 0 | N4: 0
B5: Other non-current assets | C5: 0 | D5: 0 | E5: 0 | F5: 2240841 | G5: 63800 | H5: 58332 | I5: 1274698 | J5: 3529393 | K5: 3529393 | L5: 3529393 | M5: 3529393 | N5: 3529393
B6: Other fixed assets | C6: 87252 | D6: 80206 | E6: 74738 | F6: 0 | G6: 0 | H6: 0 | I6: 0 | J6: 0 | K6: 0 | L6: 0 | M6: 0 | N6: 0
B7: Derivative financial instruments | C7: 0 | D7: 0 | E7: 454306 | F7: 868052 | G7: 494746 | H7: 120638 | I7: 0 | J7: 0 | K7: 0 | L7: 0 | M7: 0 | N7: 0
B8: Restricted cash | C8: 3010000 | D8: 4510000 | E8: 4510000 | F8: 4510000 | G8: 4510000 | H8: 4510000 | I8: 5010000 | J8: 6210000 | K8: 6210000 | L8: 6210000 | M8: 6210000 | N8: 6210000
B10: Current Assets | C10: =SUM(C11:C18) -> 137949616 | D10: =SUM(D11:D18) -> 118911883 | E10: =SUM(E11:E18) -> 115700771 | F10: =SUM(F11:F18) -> 136833282 | G10: =SUM(G11:G18) -> 133703239 | H10: =SUM(H11:H18) -> 234944340 | I10: =SUM(I11:I18) -> 295816411 | J10: =SUM(J11:J18) -> 425770942 | ... N10: =SUM(N11:N18) -> 2.6768043e+08
B11: Inventories | C11: 25354017 | D11: 24341665 | E11: 25974839 | F11: 21977229 | G11: 20809128 | H11: 17273715 | I11: 24351319 | J11: 29662719 | K11: 29662719 | L11: 29662719 | M11: 29662719 | N11: 29662719
B12: Trade and other receivables | C12: 57336089 | D12: 39755029 | E12: 46941953 | F12: 44415012 | G12: 51303526 | H12: 85091040 | I12: 78658818 | J12: 133974496 | K12: 133974496 | L12: 133974496 | M12: 133974496 | N12: 133974496
B13: Claims receivable | C13: 115528 | D13: 242576 | E13: 320097 | F13: 320097 | G13: 320097 | H13: 320097 | I13: 590016 | J13: 612402 | K13: 612402 | L13: 612402 | M13: 612402 | N13: 612402
B14: Prepaid expenses and other current assets | C14: 3037366 | D14: 4794022 | E14: 2970334 | F14: 6927636 | G14: 5685670 | H14: 6466709 | I14: 12479166 | J14: 9579615 | K14: 9579615 | L14: 9579615 | M14: 9579615 | N14: 9579615
B15: Current accounts due from related parties | C15: 0 | D15: 0 | E15: 388938 | F15: 623462 | G15: 345103 | H15: 6286469 | I15: 7263886 | J15: 8475446 | K15: 8475446 | L15: 8475446 | M15: 8475446 | N15: 8475446
B16: Derivative financial instruments | C16: 229373 | D16: 0 | E16: 612671 | F16: 1744055 | G16: 1562196 | H16: 1470326 | I16: 963507 | J16: 1869361 | K16: 1869361 | L16: 1869361 | M16: 1869361 | N16: 1869361
B17: Current portion of restricted cash | C17: 1884852 | D17: 434927 | E17: 1345947 | F17: 1072372 | G17: 1033311 | H17: 1399243 | I17: 45937603 | J17: 19005431 | K17: 19005431 | L17: 19005431 | M17: 19005431 | N17: 19005431
B18: Cash and cash equivalents | C18: 49992391 | D18: 49343664 | E18: 37145992 | F18: 59753419 | G18: 52644208 | H18: 116636741 | I18: 125572096 | J18: 222591472 | K18: =CashFlow!K61 -> 180095300 | L18: =CashFlow!L61 -> 1.5679055e+08 | M18: =CashFlow!M61 -> 1.0553984e+08 | N18: =CashFlow!N61 -> 64500964
B20: Total Assets | C20: =SUM(C2+C10) -> 1129115048 | D20: =SUM(D2+D10) -> 1082099609 | E20: =SUM(E2+E10) -> 1069365482 | F20: =SUM(F2+F10) -> 1083120219 | G20: =SUM(G2+G10) -> 1067101378 | H20: =SUM(H2+H10) -> 1200644740 | I20: =SUM(I2+I10) -> 1447052165 | J20: =SUM(J2+J10) -> 1649255990 | ... N20: =SUM(N2+N10) -> 1.5193921e+09
B23: Non-Current liabilities | C23: =SUM(C24:C26) -> 615366555 | D23: =SUM(D24:D26) -> 599002128 | E23: =SUM(E24:E26) -> 587348935 | F23: =SUM(F24:F26) -> 585029821 | G23: =SUM(G24:G26) -> 570368691 | H23: =SUM(H24:H26) -> 558687042 | I23: =SUM(I24:I26) -> 547877094 | J23: =SUM(J24:J26) -> 675723219 | ... N23: =SUM(N24:N26) -> 675723219
B24: Long-term borrowings, net of current portion | C24: 615333863 | D24: 598957333 | E24: 587298805 | F24: 583947802 | G24: 570314541 | H24: 558625413 | I24: 546218974 | J24: 670787434 | K24: =J24+J34-(51706349/4) -> 7.095672e+08 | L24: =K24+K34-(51706349/4) -> 6.9664061e+08 | M24: =L24+L34-(51706349/4) -> 6.8371402e+08 | N24: =M24+M34-(51706349/4) -> 670787434
B25: Retirement benefit obligations | C25: 32692 | D25: 44795 | E25: 50130 | F25: 50130 | G25: 54150 | H25: 61629 | I25: 61629 | J25: 61629 | K25: 61629 | L25: 61629 | M25: 61629 | N25: 61629
B26: Other non-current liabilities | F26: 1031889 | G26: 0 | I26: 1596491 | J26: 4874156 | K26: 4874156 | L26: 4874156 | M26: 4874156 | N26: 4874156
B28: Current Liabilities | C28: =SUM(C29:C34) -> 105616345 | D28: =SUM(D29:D34) -> 72670565 | E28: =SUM(E29:E34) -> 70301635 | F28: =SUM(F29:F34) -> 69790692 | G28: =SUM(G29:G34) -> 66918284 | H28: =SUM(H29:H34) -> 68866460 | I28: =SUM(I29:I34) -> 173885212 | J28: =SUM(J29:J34) -> 96020974 | ... N28: =SUM(N29:N34) -> 44314625
B29: Trade payables | C29: 23522506 | D29: 19479005 | E29: 18902263 | F29: 16784076 | G29: 15165027 | H29: 13748183 | I29: 21595404 | J29: 32303193 | K29: 32303193 | L29: 32303193 | M29: 32303193 | N29: 32303193
B30: Accrued expenses | C30: 3485042 | D30: 5909316 | E30: 4612329 | F30: 5848205 | G30: 5394433 | H30: 8643793 | I30: 12721427 | J30: 9186092 | K30: 9186092 | L30: 9186092 | M30: 9186092 | N30: 9186092
B31: Deferred revenue | C31: 0 | D31: 0 | E31: 0 | F31: 0 | G31: 0 | H31: 0 | I31: 2700023 | J31: 2825340 | K31: 2825340 | L31: 2825340 | M31: 2825340 | N31: 2825340
B32: Derivative financial instruments | C32: 0 | D32: 62500 | E32: 14877 | F32: 208667 | G32: 25572 | H32: 0 | I32: 0 | J32: 0 | K32: 0 | L32: 0 | M32: 0 | N32: 0
B33: Current accounts due to related parties | C33: 659974 | D33: 530030 | E33: 0 | F33: 0 | G33: 0 | H33: 0 | I33: 0 | J33: 0 | K33: 0 | L33: 0 | M33: 0 | N33: 0
B34: Current portion of long-term borrowings | C34: 77948823 | D34: 46689714 | E34: 46772166 | F34: 46949744 | G34: 46333252 | H34: 46474484 | I34: 136868358 | J34: 51706349
B36: Total Liabilities | C36: =C23+C28 -> 720982900 | D36: =D23+D28 -> 671672693 | E36: =E23+E28 -> 657650570 | F36: =F23+F28 -> 654820513 | G36: =G23+G28 -> 637286975 | H36: =H23+H28 -> 627553502 | I36: =I23+I28 -> 721762306 | J36: =J23+J28 -> 771744193 | ... N36: =N23+N28 -> 720037844
B38: Total shareholders´ Equity | C38: 408132148 | D38: 410426916 | E38: 411714912 | F38: 428299706 | G38: 429814403 | H38: 573091238 | I38: 725289859 | J38: 877511797 | K38: =J38+'P&L'!K30+CashFlow!K50+CashFlow!K54+CashFlow!K53 -> 9.1437392e+08 | L38: =K38+'P&L'!L30+CashFlow!L50+CashFlow!L54+CashFlow!L53 -> 8.9126072e+08 | M38: =L38+'P&L'!M30+CashFlow!M50+CashFlow!M54+CashFlow!M53 -> 8.4020156e+08 | N38: =M38+'P&L'!N30+CashFlow!N50+CashFlow!N54+CashFlow!N53 -> 7.9935423e+08
B40: Total Equity and Liabilities | C40: =C38+C36 -> 1129115048 | D40: =D38+D36 -> 1082099609 | E40: =E38+E36 -> 1069365482 | F40: =F38+F36 -> 1083120219 | G40: =G38+G36 -> 1067101378 | H40: =H38+H36 -> 1200644740 | I40: =I38+I36 -> 1447052165 | J40: =J38+J36 -> 1649255990 | ... N40: =N38+N36 -> 1.5193921e+09
B41: Check | C41: =C20-C40 -> 0 | D41: =D20-D40 -> 0 | E41: =E20-E40 -> 0 | F41: =F20-F40 -> 0 | G41: =G20-G40 -> 0 | H41: =H20-H40 -> 0 | I41: =I20-I40 -> 0 | J41: =J20-J40 -> 0 | ... N41: =N20-N40 -> 0
A44: x | B44: Debt
B45: Financial Debt | C45: =C24+C25+C34 -> 693315378 | D45: =D24+D25+D34 -> 645691842 | E45: =E24+E25+E34 -> 634121101 | F45: =F24+F25+F34 -> 630947676 | G45: =G24+G25+G34 -> 616701943 | H45: =H24+H25+H34 -> 605161526 | I45: =I24+I25+I34 -> 683148961 | J45: =J24+J25+J34 -> 722555412 | ... N45: =N24+N25+N34 -> 670849063
B46: Growth rate YoY % | D46: =D45/C45-1 -> -0.068689571 | E46: =E45/D45-1 -> -0.017919912 | F46: =F45/E45-1 -> -0.0050044463 | G46: =G45/F45-1 -> -0.022578311 | H46: =H45/G45-1 -> -0.018713119 | I46: =I45/H45-1 -> 0.12887044 | J46: =J45/I45-1 -> 0.057683541 | K46: =K45/J45-1 -> -0.017890098 | ... N46: =N45/M45-1 -> -0.01890472
B47: Net Financial Debt | C47: =C45-C8-C18-C17-C16 -> 638198762 | D47: =D45-D8-D18-D17 -> 591403251 | E47: =E45-E8-E18-E17 -> 591119162 | F47: =F45-F8-F18-F17 -> 565611885 | G47: =G45-G8-G18-G17 -> 558514424 | H47: =H45-H8-H18-H17 -> 482615542 | I47: =I45-I17-I18-I8 -> 506629262 | J47: =J45-J8-J18-J17 -> 474748509 | K47: =K45-K8-K18-K17 -> 5.0431809e+08 | L47: =L45-L8-L18-L17 -> 5.1469626e+08 | M47: =M45-M8-M18-M17 -> 5.5302038e+08 | N47: =N45-N8-N18-N17 -> 5.8113267e+08
B48: Growth rate YoY%
A51: x | B51: Working Capital
B53: Working Capital | C53: =C11+C12+C13+C14+C15+C16+C4-C29-C30-C31-C32-C33 -> 58404851 | D53: =D11+D12+D13+D14+D15+D16+D4-D29-D30-D31-D32-D33 -> 43152441 | E53: =E11+E12+E13+E14+E15+E16+E4-E29-E30-E31-E32-E33 -> 53679363 | F53: =F11+F12+F13+F14+F15+F16+F4-F29-F30-F31-F32-F33 -> 53166543 | G53: =G11+G12+G13+G14+G15+G16+G4-G29-G30-G31-G32-G33 -> 59440688 | H53: =H11+H12+H13+H14+H15+H16+H4-H29-H30-H31-H32-H33 -> 133410631 | I53: =I11+I12+I13+I14+I15+I16+I4-I29-I30-I31-I32-I33 -> 127027278 | J53: =J11+J12+J13+J14+J15+J16+J4-J29-J30-J31-J32-J33 -> 159992673 | ... N53: =N11+N12+N13+N14+N15+N16+N4-N29-N30-N31-N32-N33 -> 139859414
...

Sheet CashFlow
B1: Okeanis (in US Dollars) | C1: 2023 | D1: 2024 | E1: Q1 2025 | F1: Q2 2025 | G1: Q3 2025 | H1: Q4 2025 | I1: Q1 2026 | J1: Q2 2026 | K1: Q3 2026 | L1: Q4 2026 | M1: Q1 2027 | N1: Q2 2027
B3: CASH FLOW FROM OPERATING ACTIVITIES
B4: Profit/(loss) for the period | C4: 145251024 | D4: 108863270 | E4: 12555933 | F4: 26886909 | G4: 24050573 | H4: 59458128 | I4: 88317703 | J4: 230311248 | K4: ='P&L'!K30 -> 241846557 | L4: ='P&L'!L30 -> 218733357 | M4: ='P&L'!M30 -> 167674197 | N4: ='P&L'!N30 -> 126826869
B5: Adjustments: | C5: =SUM(C6:C16) -> 96177017 | D5: =SUM(D6:D16) -> 92944825 | E5: =SUM(E6:E16) -> 19715916 | F5: =SUM(F6:F16) -> 20097506 | G5: =SUM(G6:G16) -> 20874899 | H5: =SUM(H6:H16) -> 19857066 | I5: =SUM(I6:I16) -> 21631884 | J5: =SUM(J6:J16) -> 21610457 | ... N5: =SUM(N6:N16) -> 12735038
B6: Depreciation | C6: 40382628 | D6: 41134237 | E6: 10222121 | F6: 10343401 | G6: 10436705 | H6: 10438324 | I6: 12013349 | J6: =-'P&L'!J9 -> 12735038 | K6: =-'P&L'!K9 -> 12735038 | L6: =-'P&L'!L9 -> 12735038 | M6: =-'P&L'!M9 -> 12735038 | N6: =-'P&L'!N9 -> 12735038
B7: Interest expense | C7: 58680985 | D7: 53628356 | E7: 11014592 | F7: 10833146 | G7: 10474518 | H7: 9831332 | I7: 9735336 | J7: 9447565 | K7: 0 | L7: 0 | M7: 0 | N7: 0
B8: Amortization of loan financing fees | C8: 1994191 | D8: 2263416 | E8: 321553 | F8: 316294 | G8: 306213 | H8: 302205 | I8: 314329 | J8: 305885 | K8: 0 | L8: 0 | M8: 0 | N8: 0
B9: Unrealized (loss) / gain, net on derivatives | C9: -20135 | D9: 291873 | E9: -1114601 | F9: -1351339 | G9: 372070 | H9: 440406 | I9: 627457 | J9: -905854 | K9: 0 | L9: 0 | M9: 0 | N9: 0
B10: Interest income | C10: -4104564 | D10: -3445203 | E10: -408133 | F10: -407470 | G10: -563460 | H10: -812677 | I10: -1051202 | J10: -1379880 | K10: 0 | L10: 0 | M10: 0 | N10: 0
B11: (Gain) / loss on debt extinguishment | C11: 0 | D11: 0 | E11: 0 | F11: 1125951 | G11: 257817 | H11: 0 | I11: 0 | J11: 1363059 | K11: 0 | L11: 0 | M11: 0 | N11: 0
B12: Other non-cash items | C12: -43323 | D12: -6005 | E12: 0 | F12: 0 | G12: 0 | H12: 1010 | I12: 0 | J12: 0 | K12: 0 | L12: 0 | M12: 0 | N12: 0
B13: Gain from modification of loans | D13: -1828959 | E13: 0 | F13: 0 | G13: 0 | H13: 0 | I13: 0 | J13: 0 | K13: 0 | L13: 0 | M13: 0 | N13: 0
B14: Net gain on disposal of vessels | C14: 0 | D14: 0 | E14: 0 | F14: 0 | G14: 0 | H14: 0 | I14: 0 | J14: 0 | K14: 0 | L14: 0 | M14: 0 | N14: 0
B15: Impairment loss | C15: 0 | D15: 0 | E15: 0 | F15: 0 | H15: 0 | I15: 0 | J15: 0 | K15: 0 | L15: 0 | M15: 0 | N15: 0
B16: Unrealized foreign exchange (gain) / loss | C16: -712765 | D16: 907110 | E16: -319616 | F16: -762477 | G16: -408964 | H16: -343534 | I16: -7385 | J16: 44644 | K16: 0 | L16: 0 | M16: 0 | N16: 0
B17: Total reconciliation adjustments | C17: =C4+C5 -> 241428041 | D17: =D4+D5 -> 201808095 | E17: =E4+E5 -> 32271849 | F17: =F4+F5 -> 46984415 | G17: =G4+G5 -> 44925472 | H17: =H4+H5 -> 79315194 | I17: =I4+I5 -> 109949587 | J17: =J4+J5 -> 251921705 | ... N17: =N4+N5 -> 139561907
B19: Changes in working capital: | C19: =SUM(C20:C28) -> -7746840 | D19: =SUM(D20:D28) -> 14454869 | E19: =SUM(E20:E28) -> -9439567 | F19: =SUM(F20:F28) -> 1138132 | G19: =SUM(G20:G28) -> -4815999 | H19: =SUM(H20:H28) -> -36893556 | I19: =SUM(I20:I28) -> 7872164 | J19: =SUM(J20:J28) -> -52603900 | K19: =Balance!J53-Balance!K53 -> 20133259 | L19: =Balance!K53-Balance!L53 -> 0 | M19: =Balance!L53-Balance!M53 -> 0 | N19: =Balance!M53-Balance!N53 -> 0
B20: Trade and other receivables | C20: -5853175 | D20: 17674147 | E20: -7088023 | F20: 2517805 | G20: -6866273 | H20: -33884553 | I20: 6582122 | J20: -55653751 | K20: 0 | L20: 0 | M20: 0 | N20: 0
B21: Prepaid expenses and other current assets | C21: -824682 | D21: -1902362 | E21: 1823689 | F21: -6128875 | G21: 3413538 | H21: -781039 | I21: -7234292 | J21: 650324 | K21: 0 | L21: 0 | M21: 0 | N21: 0
B22: Inventories | C22: -8343486 | D22: 1012352 | E22: -1633174 | F22: 3997610 | G22: 1168101 | H22: 3535413 | I22: -7077603 | J22: -5311401 | K22: 0 | L22: 0 | M22: 0 | N22: 0
B23: Trade payables | C23: 10958162 | D23: -4470575 | E23: -106831 | F23: -1248502 | G23: -1415155 | H23: -3202845 | I23: 8878077 | J23: 9614912 | K23: 0 | L23: 0 | M23: 0 | N23: 0
B24: Accrued expenses | C24: -530625 | D24: 2398299 | E24: -1438739 | F24: 2234618 | G24: -1394569 | H24: 3380834 | I24: 5271172 | J24: -795355 | K24: 0 | L24: 0 | M24: 0 | N24: 0
B25: Deferred revenue | C25: -4255500 | D25: 0 | I25: 2700023 | J25: 125317 | K25: 0 | L25: 0 | M25: 0 | N25: 0
B26: Claims receivable | C26: -7137 | D26: -127048 | E26: -77521 | F26: 0 | G26: 0 | H26: 0 | I26: -269918 | J26: -22386 | K26: 0 | L26: 0 | M26: 0 | N26: 0
B27: Collections / (due) from related parties | C27: 1109603 | D27: -129944 | E27: -388938 | F27: -234524 | G27: 0 | H27: -5941366 | I27: -977417 | J27: -1211560 | K27: 0 | L27: 0 | M27: 0 | N27: 0
B28: Due to related parties | E28: -530030 | F28: 0 | G28: 278359 | H28: 0 | I28: 0 | J28: 0 | K28: 0 | L28: 0 | M28: 0 | N28: 0
B30: Interest paid | C30: -59649091 | D30: -53444573 | E30: -10867503 | F30: -10800001 | G30: -10561591 | H30: -9955327 | I30: -9332383 | J30: -8909880 | K30: 0 | L30: 0 | M30: 0 | N30: 0
A31: x | B31: Net Cash provided by operating activities | C31: =C17+C19+C30 -> 174032110 | D31: =D17+D19+D30 -> 162818391 | E31: =E17+E19+E30 -> 11964779 | F31: =F17+F19+F30 -> 37322546 | G31: =G17+G19+G30 -> 29547882 | H31: =H17+H19+H30 -> 32466311 | I31: =I17+I19+I30 -> 108489368 | J31: =J17+J19+J30 -> 190407925 | ... N31: =N17+N19+N30 -> 139561907
B34: CASH FLOWS FROM INVESTING ACTIVITIES
B35: Current accounts due from related parties | C35: 0 | D35: 0 | E35: 0 | F35: 0 | G35: 0 | H35: 0 | I35: 0
B36: Payments for other fixed assets | C36: 0 | D36: 0 | E36: 0 | F36: 0 | G36: 0 | H36: 0 | I36: 0
B37: Proceeds from vessels disposal | C37: 0 | D37: 0 | E37: 0 | F37: 0 | G37: 0 | H37: 0 | I37: 0
B38: Decrease in restricted cash | C38: 2032927 | D38: 1449925 | E38: 0 | F38: 273575 | G38: 39061 | H38: 0 | I38: 0 | J38: 25732172
B39: Increase in restricted cash | D39: -1500000 | E39: -911020 | F39: 0 | G39: 0 | H39: -365932 | I39: -45038360 | J39: 0
B40: Payments for special survey and dry-docking costs | C40: -3306052 | D40: -11189402 | E40: -719608 | F40: -1254975 | G40: -301747 | H40: -1140193 | I40: -851859 | J40: -760088
B41: Payments for vessels and vessels under construction | C41: 0 | D41: 0 | H41: -40193651 | I41: -196131744 | J41: -79687469 | K41: =-Balance!K58 -> -99300000 | L41: =-Balance!L58 -> 0 | M41: =-Balance!M58 -> 0 | N41: =-Balance!N58 -> 0
B42: Interest received | C42: 2233711 | D42: 3299288 | E42: 290720 | F42: 428633 | G42: 544254 | H42: 891124 | I42: 861303 | J42: 1595824
A43: x | B43: Investing Cash Flow | C43: =SUM(C37:C42) -> 960586 | D43: =SUM(D37:D42) -> -7940189 | E43: =SUM(E37:E42) -> -1339908 | F43: =SUM(F37:F42) -> -552767 | G43: =SUM(G37:G42) -> 281568 | H43: =SUM(H37:H42) -> -40808652 | I43: =SUM(I37:I42) -> -241160660 | J43: =SUM(J37:J42) -> -53119561 | ... N43: =SUM(N37:N42) -> 0
B46: CASH FLOWS FROM FINANCING ACTIVITES
B47: Proceeds from long-term borrowings | C47: 197000000 | D47: 199260000 | E47: 0 | F47: 131000000 | G47: 64000000 | H47: 0 | I47: 90000000 | J47: 145000000 | K47: 0 | L47: 0 | M47: 0 | N47: 0
...
