Workbook

Sheet Stock Master
A1: Name | B1: Ticket | C1: Price | D1: P/NAV | E1: NAV/Share | F1: Fleet Coef. | G1: EV/Adj. EBITDA | H1: PER | I1: Currency | J1: Total Divi. | K1: Div. Yield
A2: Okeanis | B2: OET | C2: 65.87 | D2: =[1]ECO!$P$16 -> 1.4075102 | E2: =[1]ECO!$P$14 -> 46.798951 | F2: =[1]ECO!$P$19 -> 1 | G2: =[1]ECO!$S$37 -> 3.7457143 | H2: =[1]ECO!$S$36 -> 3.4060869 | I2: $ | J2: =SUM([1]ECO!$O$15:$R$15) -> 19.046235 | K2: =J2/C2 -> 0.28914885
A3: Frontline | B3: FRO | C3: 43.54 | D3: =[1]FRO!$P$16 -> 1.2908845 | E3: =[1]FRO!$P$14+[1]FRO!$P$15 -> 33.728811 | F3: =[1]FRO!$P$19 -> 1 | G3: =[1]FRO!$R$39 -> 5.4121055 | H3: =[1]FRO!$R$38 -> 5.3172821 | I3: $ | J3: =SUM([1]FRO!$O$15:$R$15) -> 8.4801299 | K3: =J3/C3 -> 0.19476642
A4: DHT | B4: DHT | C4: 19.32 | D4: =[1]DHT!$P$18 -> 1.1709537 | E4: =[1]DHT!$P$16 -> 16.499371 | F4: =[1]DHT!$P$21 -> 1 | G4: =[1]DHT!$S$39 -> 3.8675734 | H4: =[1]DHT!$S$38 -> 4.4231079 | I4: $ | J4: =[1]DHT!$S$36 -> 4.8646608 | K4: =J4/C4 -> 0.25179404
A5: Nordic American Tankers | B5: NAT | C5: 6.87 | D5: =[1]NAT!$O$16 -> 1.4027616 | E5: =[1]NAT!$O$14+[1]NAT!$O$15 -> 4.8974823 | F5: =[1]NAT!$O$19 -> 1 | G5: =[1]NAT!$Q$37 -> 8.3581079 | H5: =[1]NAT!$Q$36 -> 11.696757 | I5: $ | J5: =SUM([1]NAT!$N$15:$Q$15) -> 0.88 | K5: =J5/C5 -> 0.12809316
A6: Teekay Tankers | B6: TNK | C6: 87.24 | D6: =[1]TNK!$O$16 -> 0.99346815 | E6: =[1]TNK!$O$14 -> 87.813585 | F6: =[1]TNK!$O$19 -> 1 | G6: =[1]TNK!$R$39 -> 3.2294322 | H6: =[1]TNK!$R$38 -> 6.1808363 | I6: $ | J6: =[1]TNK!$R$36 -> 2 | K6: =J6/C6 -> 0.022925264
A7: International Seaways | B7: INSW | C7: 99.08 | D7: =[1]INSW!$O$16 -> 1.5363796 | E7: =[1]INSW!$O$14 -> 64.489271 | F7: =[1]INSW!$O$19 -> 1 | G7: =[1]INSW!$R$41 -> 6.249178 | H7: =[1]INSW!$R$40 -> 8.1613325 | I7: $ | J7: =SUM([1]INSW!$N$15:$Q$15) -> 15.567813 | K7: =J7/C7 -> 0.15712366
A8: Torm | B8: TRMD | C8: 31.39 | D8: =[1]TRMD!$N$16 -> 0.95770852 | E8: =[1]TRMD!$N$14 -> 32.776152 | F8: =[1]TRMD!$N$19 -> 1 | G8: =[1]TRMD!$Q$39 -> 3.6612763 | H8: =[1]TRMD!$Q$38 -> 6.0590944 | I8: $ | J8: =[1]TRMD!$Q$36 -> 5.0008035 | K8: =J8/C8 -> 0.15931199
A9: Scorpio Tankers | B9: STNG | C9: 77.25 | D9: =[1]STNG!$P$16 -> 0.73602163 | E9: =[1]STNG!$P$14 -> 104.95615 | F9: =[1]STNG!$P$19 -> 1 | G9: =[1]STNG!$S$38 -> 3.8824469 | H9: =[1]STNG!$S$37 -> 10.481407 | I9: $ | J9: =[1]STNG!$S$35 -> 1.8 | K9: =J9/C9 -> 0.023300971
A10: D´Amico | B10: DIS | C10: 7.29 | D10: =[1]DIS!$O$17 -> 0.79992312 | E10: =[1]DIS!$O$15 -> 9.1133758 | F10: =[1]DIS!$O$20 -> 1 | G10: =[1]DIS!$R$39 -> 5.5373013 | H10: =[1]DIS!$R$38 -> 10.236372 | I10: € | J10: =SUM([1]DIS!$N$16:$Q$16) -> 0.2349 | K10: =J10/C10 -> 0.032222222
A11: Ardmore | B11: ASC | C11: 17.68 | D11: =[1]ASC!$P$16 -> 0.76409479 | E11: =[1]ASC!$P$14 -> 23.138491 | F11: =[1]ASC!$P$19 -> 1 | G11: =[1]ASC!$S$38 -> 5.3959023 | H11: =[1]ASC!$S$37 -> 6.2217015 | I11: $ | J11: =[1]ASC!$S$35 -> 2.2522786 | K11: =J11/C11 -> 0.12739132
A12: Performance Shipping | B12: PSHG | C12: 1.7 | D12: =[1]PSHG!$P$16 -> 0.11490343 | E12: =[1]PSHG!$P$14+[1]PSHG!$P$15 -> 14.795033 | F12: =[1]PSHG!$P$19 -> 1 | G12: =[1]PSHG!$S$36 -> 2.2941908 | H12: =[1]PSHG!$S$35 -> 3.1561534 | I12: $ | J12: =SUM([1]PSHG!$O$15:$R$15) -> 0 | K12: =J12/C12 -> 0
A13: Pyxis Tankers | B13: PXS | C13: 5.2 | D13: =[1]PXS!$P$16 -> 0.33002441 | E13: =[1]PXS!$P$14+[1]PXS!$P$15 -> 15.75641 | F13: =[1]PXS!$P$19 -> 1 | G13: =[1]PXS!$R$37 -> 2.8069942 | H13: =[1]PXS!$R$36 -> 4.4646577 | I13: $ | J13: =SUM([1]PXS!$O$15:$R$15) -> 0 | K13: =J13/C13 -> 0
A14: Imperial Petroleum | B14: IMPP | C14: 4.89 | D14: =[1]IMPP!$N$16 -> 0.34725257 | E14: =[1]IMPP!$N$14+[1]IMPP!$N$15 -> 14.081969 | F14: =[1]IMPP!$N$19 -> 1 | G14: =[1]IMPP!$P$38 -> -0.16481814 | H14: =[1]IMPP!$P$37 -> 1.563512 | I14: $ | J14: =SUM([1]IMPP!$M$15:$P$15) -> 0 | K14: =J14/C14 -> 0
A18: Himalaya Shipping | B18: HSHP | C18: 16.21 | D18: =[1]HSHP!$P$16 -> 2.8416161 | E18: =[1]HSHP!$P$14 -> 5.7045004 | F18: =[1]HSHP!$P$19 -> 1 | G18: =[1]HSHP!$S$37 -> 7.9870987 | H18: =[1]HSHP!$S$36 -> 7.9812095 | I18: $ | J18: =[1]HSHP!$S$34 -> 2.1803093 | K18: =J18/C18 -> 0.13450397
A19: StarBulk Carriers | B19: SBLK | C19: 30.47 | D19: =[1]SBLK!$O$16 -> 0.92290688 | E19: =[1]SBLK!$O$14 -> 33.015249 | F19: =[1]SBLK!$O$19 -> 1 | G19: =[1]SBLK!$R$38 -> 4.058811 | H19: =[1]SBLK!$R$37 -> 4.9238375 | I19: $ | J19: =[1]SBLK!$R$35 -> 3.5287161 | K19: =J19/C19 -> 0.11580952
A20: Genco | B20: GNK | C20: 25.73 | D20: =[1]GNK!$P$16 -> 0.95898482 | E20: =[1]GNK!$P$14 -> 26.830456 | F20: =[1]GNK!$P$19 -> 1 | G20: =[1]GNK!$S$36 -> 2.4124314 | H20: =[1]GNK!$S$35 -> 2.990208 | I20: $ | J20: =[1]GNK!$S$33 -> 4.3894106 | K20: =J20/C20 -> 0.17059505
A21: Safe Bulkers | B21: SB | C21: 8.5 | D21: =[1]SB!$O$16 -> 0.75995464 | E21: =[1]SB!$O$14 -> 11.184878 | F21: =[1]SB!$O$19 -> 1 | G21: =[1]SB!$R$36 -> 4.8853182 | H21: =[1]SB!$R$35 -> 5.5238816 | I21: $ | J21: =SUM([1]SB!$R$33) -> 0.3 | K21: =J21/C21 -> 0.035294118
A22: Eurodry | B22: EDRY | C22: 49.08 | D22: =[1]EDRY!$O$16 -> 0.95990003 | E22: =[1]EDRY!$O$14 -> 51.130325 | F22: =[1]EDRY!$O$19 -> 1 | G22: =[1]EDRY!$R$36 -> 52.997464 | H22: =[1]EDRY!$R$35 -> 4.1409025 | I22: $ | J22: =[1]EDRY!$R$33 -> 0 | K22: =J22/C22 -> 0
A23: Seanergy Maritime | B23: SHIP | C23: 17.58 | D23: =[1]SHIP!$P$16 -> 0.76123141 | E23: =[1]SHIP!$P$14 -> 23.09416 | F23: =[1]SHIP!$P$19 -> 1 | G23: =[1]SHIP!$S$36 -> 3.9891743 | H23: =[1]SHIP!$S$35 -> 4.7905616 | I23: $ | J23: =[1]SHIP!$S$33 -> 1.0085434 | K23: =J23/C23 -> 0.057368793
A24: United Maritime Corp. | B24: USEA | C24: 2.78 | D24: =[1]USEA!$P$16 -> 0.74240812 | E24: =[1]USEA!$P$14 -> 3.7445711 | F24: =[1]USEA!$P$19 -> 1 | G24: =[1]USEA!$S$36 -> 4.9586923 | H24: =[1]USEA!$S$35 -> 6.848247 | I24: $ | J24: =SUM([1]USEA!$O$15:$R$15) -> 0.4 | K24: =J24/C24 -> 0.14388489
A25: Pangaea Logistics Solutions | B25: PANL | C25: 8.03 | D25: =[1]PANL!$P$16 -> 0.89130205 | E25: =[1]PANL!$P$14 -> 9.0092915 | F25: =[1]PANL!$P$19 -> 1 | G25: =[1]PANL!$S$36 -> 3.9781975 | H25: =[1]PANL!$S$35 -> 5.4743961 | I25: $ | J25: =[1]PANL!$S$33 -> 0.4 | K25: =J25/C25 -> 0.0498132
A26: Diana Shipping | B26: DSX | C26: 2.69 | D26: =[1]DSX!$O$16 -> 0.55084315 | E26: =[1]DSX!$O$14 -> 4.8834228 | F26: =[1]DSX!$O$19 -> 1 | G26: =[1]DSX!$R$36 -> 6.2013371 | H26: =[1]DSX!$R$35 -> 15.651929 | I26: $ | J26: =[1]DSX!$R$33 -> 0.04 | K26: =J26/C26 -> 0.014869888
A29: P/NAV and NAV/Share for Q3 2026
A30: EV/Adj. EBITDA, PER and Total Divi and Div. Yield, for NTM (Next Twelve Months)

Sheet Vessels Values Master
A1: x | B1: TANKERS | C1: Newbuild | D1: Resale | E1: 5y | F1: 10y | G1: 15y | H1: 20y | I1: Scrap | J1: DWT
B2: VLCC | C2: 124.1 | D2: =E2*1.08 -> 156.168 | E2: 144.6 | F2: 112.7 | G2: 81.4 | H2: 71.4 | I2: 22 | J2: 200 -320K
B3: Suezmax | C3: 84.6 | D3: =E3*1.08 -> 105.948 | E3: 98.1 | F3: 81.3 | G3: 57.8 | H3: 51.3 | I3: 11 | J3: 120 - 200k
B4: Aframax | C4: 73 | D4: =E4*1.08 -> 84.888 | E4: 78.6 | F4: 64.9 | G4: 45.2 | H4: 35.8 | I4: 8 | J4: 80 - 120k
B5: LR2 | C5: 72.5 | D5: =E5*1.08 -> 85.428 | E5: 79.1 | F5: 65.4 | G5: 45.7 | H5: 36.3 | I5: 9 | J5: 80 - 120k
B6: LR1 | C6: 55.4 | D6: =E6*1.14 -> 57.114 | E6: 50.1 | F6: 39.4 | G6: 26.9 | H6: 18.9 | I6: 6 | J6: 55 - 80k
B7: MR / MR2 | C7: 46.6 | D7: =E7*1.14 -> 53.352 | E7: 46.8 | F7: 36.4 | G7: 23.8 | H7: 16.3 | I7: 5 | J7: 40 - 55k
B10: VLCC | C10: {=LINEST(D11:D16,C11:C16^{1,2,3},1,1)} -> -0.0024622222 | D10: 0.019790476 | E10: -4.2968254 | F10: 158.76133 | H10: Suezmax | I10: {=LINEST(J11:J16,I11:I16^{1,2,3},1,1)} -> -0.0039362963 | J10: 0.061139683 | K10: -2.8357672 | L10: 107.46197 | N10: Aframax | O10: {=LINEST(P11:P16,O11:O16^{1,2,3},1,1)} -> -0.00044740741 | P10: -0.047765079 | Q10: -1.5827513 | R10: 85.725778
C11: 0 | D11: =D2 -> 156.168 | I11: 0 | J11: =D3 -> 105.948 | O11: 0 | P11: =D4 -> 84.888
C12: 5 | D12: =E2 -> 144.6 | I12: 5 | J12: =E3 -> 98.1 | O12: 5 | P12: =E4 -> 78.6
C13: 10 | D13: =F2 -> 112.7 | I13: 10 | J13: =F3 -> 81.3 | O13: 10 | P13: =F4 -> 64.9
C14: 15 | D14: =G2 -> 81.4 | I14: 15 | J14: =G3 -> 57.8 | O14: 15 | P14: =G4 -> 45.2
C15: 20 | D15: =H2 -> 71.4 | I15: 20 | J15: =H3 -> 51.3 | O15: 20 | P15: =H4 -> 35.8
C16: 25 | D16: =I2 -> 22 | I16: 25 | J16: =I3 -> 11 | O16: 25 | P16: =I4 -> 8
B19: LR2 | C19: {=LINEST(D20:D25,C20:C25^{1,2,3},1,1)} -> -0.00027703704 | D19: -0.052225397 | E19: -1.5594709 | F19: 86.248317 | H19: LR1 | I19: {=LINEST(J20:J25,I20:I25^{1,2,3},1,1)} -> 0.00095037037 | J19: -0.048946032 | K19: -1.4085053 | L19: 57.437254 | N19: MR | O19: {=LINEST(P20:P25,O20:O25^{1,2,3},1,1)} -> 0.00164 | P19: -0.070171429 | Q19: -1.1978571 | R19: 53.642
C20: 0 | D20: =D5 -> 85.428 | I20: 0 | J20: =D6 -> 57.114 | O20: 0 | P20: =D7 -> 53.352
C21: 5 | D21: =E5 -> 79.1 | I21: 5 | J21: =E6 -> 50.1 | O21: 5 | P21: =E7 -> 46.8
C22: 10 | D22: =F5 -> 65.4 | I22: 10 | J22: =F6 -> 39.4 | O22: 10 | P22: =F7 -> 36.4
C23: 15 | D23: =G5 -> 45.7 | I23: 15 | J23: =G6 -> 26.9 | O23: 15 | P23: =G7 -> 23.8
C24: 20 | D24: =H5 -> 36.3 | I24: 20 | J24: =H6 -> 18.9 | O24: 20 | P24: =H7 -> 16.3
C25: 25 | D25: =I5 -> 9 | I25: 25 | J25: =I6 -> 6 | O25: 25 | P25: =I7 -> 5
A31: x | B31: DRY BULK | C31: Newbuild | D31: Resale | E31: 5y | F31: 10y | G31: 15y | H31: 20y | I31: Scrap | J31: DWT
B32: NewCastleMax | C32: 78.1 | D32: =E32*1.15 -> 82.11 | E32: 71.4 | F32: 51.7 | G32: 37.1 | H32: 28.2 | I32: 12.1 | J32: 185 - 210k
B33: Capesize | C33: 73.5 | D33: =E33*1.15 -> 77.855 | E33: 67.7 | F33: 47.6 | G33: 32.8 | H33: 24.4 | I33: 10.8 | J33: 100 - 185k
B34: Post Panamax | C34: 38 | D34: =E34*1.15 -> 43.47 | E34: 37.8 | F34: 29.3 | G34: 17.8 | H34: 14.7 | I34: 7.7 | J34: 90 - 100k
B35: Kamsarmax | C35: 36.5 | D35: =E35*1.15 -> 42.435 | E35: 36.9 | F35: 28.6 | G35: 17.4 | H35: 13.9 | I35: 6.8 | J35: 80 - 85k
B36: Panamax | C36: 32.1 | D36: =E36*1.15 -> 35.88 | E36: 31.2 | F36: 24.6 | G36: 15.3 | H36: 12.7 | I36: 6.1 | J36: 65k - 80k
B37: Ultramax | C37: 34.9 | D37: =E37*1.15 -> 42.09 | E37: 36.6 | F37: 28.2 | G37: 17.4 | H37: 13.7 | I37: 5.4 | J37: 60 - 65k
A38: x | B38: Supramax | C38: 30.9 | D38: =E38*1.15 -> 34.385 | E38: 29.9 | F38: 23.3 | G38: 14.7 | H38: 11.6 | I38: 5.9 | J38: 50k - 59k
B41: NewcastleMax | C41: {=LINEST(D42:D47,C42:C47^{1,2,3},1,1)} -> 0.0007962963 | D41: -0.018253968 | E41: -2.8417328 | F41: 83.073889 | H41: Capesize | I41: {=LINEST(J42:J47,I42:I47^{1,2,3},1,1)} -> 0.0020018519 | J41: -0.053944444 | K41: -2.585205 | L41: 78.819484 | N41: Post Panamax | O41: {=LINEST(P42:P47,O42:O47^{1,2,3},1,1)} -> 0.002137037 | P41: -0.069460317 | Q41: -1.0187434 | R41: 43.763254
C42: 0 | D42: =D32 -> 82.11 | I42: 0 | J42: =D33 -> 77.855 | O42: 0 | P42: =D34 -> 43.47
C43: 5 | D43: =E32 -> 71.4 | I43: 5 | J43: =E33 -> 67.7 | O43: 5 | P43: =E34 -> 37.8
C44: 10 | D44: =F32 -> 51.7 | I44: 10 | J44: =F33 -> 47.6 | O44: 10 | P44: =F34 -> 29.3
C45: 15 | D45: =G32 -> 37.1 | I45: 15 | J45: =G33 -> 32.8 | O45: 15 | P45: =G34 -> 17.8
C46: 20 | D46: =H32 -> 28.2 | I46: 20 | J46: =H33 -> 24.4 | O46: 20 | P46: =H34 -> 14.7
C47: 25 | D47: =I32 -> 12.1 | I47: 25 | J47: =I33 -> 10.8 | O47: 25 | P47: =I34 -> 7.7
B50: Kamsarmax | C50: {=LINEST(D51:D56,C51:C56^{1,2,3},1,1)} -> 0.0020462963 | D50: -0.068611111 | E50: -0.97869709 | F50: 42.704246 | H50: Panamax | I50: {=LINEST(J51:J56,I51:I56^{1,2,3},1,1)} -> 0.0013185185 | J50: -0.044873016 | K50: -0.88383598 | L50: 36.114127 | N50: Ultramax | O50: {=LINEST(P51:P56,O51:O56^{1,2,3},1,1)} -> 0.0014851852 | P50: -0.052301587 | Q50: -1.0787169 | R50: 42.40627 | T50: Supramax | U50: {=LINEST(V51:V56,U51:U56^{1,2,3},1,1)} -> 0.001487037 | V50: -0.050103175 | W50: -0.80892196 | X50: 34.587183
C51: 0 | D51: =D35 -> 42.435 | I51: 0 | J51: =D36 -> 35.88 | O51: 0 | P51: =D37 -> 42.09 | U51: 0 | V51: =D38 -> 34.385
C52: 5 | D52: =E35 -> 36.9 | I52: 5 | J52: =E36 -> 31.2 | O52: 5 | P52: =E37 -> 36.6 | U52: 5 | V52: =E38 -> 29.9
C53: 10 | D53: =F35 -> 28.6 | I53: 10 | J53: =F36 -> 24.6 | O53: 10 | P53: =F37 -> 28.2 | U53: 10 | V53: =F38 -> 23.3
...
