Workbook

Sheet Cover
A3: Star Bulk Carriers Corp. | F3: Copyright:
A4: SBLK | F4: Ourios Analytics
F5: ourios.com
F6: info@ourios.com
A10: DISCLAIMER
A11: The financial models and projections provided herein are based on internal assumptions, historical data, and current market trends (such as charter rates, fuel costs, and vessel valuations) which are subject to high volatility and change without notice.
A12: These models are intended for illustrative and informational purposes only. They do not constitute financial, investment, or legal advice. While we strive for accuracy, we make no guarantees regarding the future performance of any asset or the realization of the projected returns.
A16: COPYRIGHT
A17: This Excel model and its contents are the exclusive property of Ourios Analytics. No part of this file may be reproduced, distributed, transmitted, or shared in any form or by any means, without the prior written permission of Ourios Analytics.
A18: Authorized use must strictly include a clear citation of the source: "Source: Ourios Analytics".
A22: COLORS USED IN FINANCIAL DATA
A23: In green: | B23: Data copied from last quarter or reported by company
A24: In blue: | B24: Our own assumption
A25: In black: | B25: Automatically filled
A26: In yellow | B26: Yellow cells can be changed to make assumptions
A30: NAV Tab Content
A31: Fleet list: | B31: Vessel name, type of vessel, year built, Yard, Country, scrubber, neutral value and corrected value by premium coefficient
A32: Price to update: | B32: Share price, that it´s update from Valuations_Master
A33: NAV calculation: | B33: Net Asset Value calculation
A34: Adjusted fleet value: | B34: Change this coefficient if you think the value is going up or down. Default we leave it in 1.
A35: Value growth in %: | B35: Change in % between quarters
A36: Scrubbers: | B36: How many scrubbers are installed in the vessels, reported by the company.
A37: Fleet : | B37: How many vessels has the company
A38: % Fleet with scrubber: | B38: As it titles says, % fleet with scrubber
A39: TCE: | B39: Time Charter Equivalent, based in data reported by the company or own assumptions
A40: Financial data: | B40: Market Cap, Enterprise Value, Adjusted Earnings, Adjusted EBITDA, Levered FCF, Adjusted P/E, Adjusted EV/EBITDA and P/FCF
A41: Linear Estimation: | B41: Don´t remove or change this data. It´s to automatically calculate vessels value from the Master
A42: Coefficient added by premium: | B42: Correction factor depending on the country of construction or others
A44: Fleet colours by status:
A45: No color: | B45: In the fleet list
A46: Pink: | B46: Sold vessel reported by the company
A47: Orange: | B47: Newbuilding or acquired vessel reported by the company
A48: Blue: | B48: Chartered-in or Bareboat-in
A50: Remember: If you want to make assumptions, just change yellow cells
A53: P&L Tab Content
A54: P&L from company reports
A55: Operating days: | B55: You can change it on your own
A56: TCE revenue per vessel: | B56: Operating days x TCE assumption
A58: Notes:
A59: Estimating revenues are from TCE and operating days. For that reason, voyage expenses use to be in grey background. We prepare the TCE revenues looking at what the company say about it.
...

Sheet NAV
B1: Vessel | C1: Type | D1: Yard | E1: Country | F1: Ownership | G1: Built | H1: Age | I1: Value | J1: Premium | L1: Price:
B2: Goliath | C2: Newcastlemax | D2: NACKS | E2: China | F2: 1 | G2: 42005 | H2: =(TODAY()-G2)/365 -> 11.641096 | I2: =$M$45*H2^3+$N$45*H2^2+$O$45*H2+$P$45 -> 48.775509 | J2: =I2*$M$58 -> 48.775509 | L2: ='[1]Stock Master'!$C$19 -> 29.78
B3: Gargantua | C3: Newcastlemax | D3: NACKS | E3: China | F3: 1 | G3: 42005 | H3: =(TODAY()-G3)/365 -> 11.641096 | I3: =$M$45*H3^3+$N$45*H3^2+$O$45*H3+$P$45 -> 48.775509 | J3: =I3*$M$58 -> 48.775509
B4: Star Gina 2GR | C4: Newcastlemax | D4: NACKS | E4: China | F4: 1 | G4: 42370 | H4: =(TODAY()-G4)/365 -> 10.641096 | I4: =$M$45*H4^3+$N$45*H4^2+$O$45*H4+$P$45 -> 51.727263 | J4: =I4*$M$58 -> 51.727263 | L4: Net Asset Value | M4: Q1 2026 | N4: Q2 2026 | O4: Q3 2026 | P4: Q4 2026 | Q4: Q1 2027 | R4: Q2 2027
B5: Maharaj | C5: Newcastlemax | D5: NACKS | E5: China | F5: 1 | G5: 42005 | H5: =(TODAY()-G5)/365 -> 11.641096 | I5: =$M$45*H5^3+$N$45*H5^2+$O$45*H5+$P$45 -> 48.775509 | J5: =I5*$M$58 -> 48.775509 | L5: Fleet Value | M5: 3574 | N5: 3568 | O5: =(SUM($J$2:$J$150)-SUM(J86:J89))*O19 -> 3681.5719 | P5: =(SUM($J$2:$J$150)-SUM(J88:J89))*P19 -> 3748.3124 | Q5: =(SUM($J$2:$J$150))*Q19 -> 3814.5101 | R5: =(SUM($J$2:$J$150))*R19 -> 3795.2449
B6: Star Leo | C6: Newcastlemax | D6: SWS | E6: China | F6: 1 | G6: 43101 | H6: =(TODAY()-G6)/365 -> 8.6383562 | I6: =$M$45*H6^3+$N$45*H6^2+$O$45*H6+$P$45 -> 57.677152 | J6: =I6*$M$58 -> 57.677152 | L6: Financial Debt | M6: =-Balance!F62/1000 -> -946.332 | N6: =-Balance!G62/1000 -> -1036.578 | O6: =-Balance!H62/1000 -> -1029.3827 | P6: =-Balance!I62/1000 -> -1048.9875 | Q6: =-Balance!J62/1000 -> -990.59225 | R6: =-Balance!K62/1000 -> -932.197
B7: Star Laetitia | C7: Newcastlemax | D7: SWS | E7: China | F7: 1 | G7: 42736 | H7: =(TODAY()-G7)/365 -> 9.6383562 | I7: =$M$45*H7^3+$N$45*H7^2+$O$45*H7+$P$45 -> 54.701491 | J7: =I7*$M$58 -> 54.701491 | L7: Cash | M7: =(Balance!F4+Balance!F5+Balance!F24)/1000 -> 409.432 | N7: =(Balance!G4+Balance!G5+Balance!G24)/1000 -> 565.282 | O7: =(Balance!H4+Balance!H5+Balance!H24)/1000 -> 620.48274 | P7: =(Balance!I4+Balance!I5+Balance!I24)/1000 -> 689.6253 | Q7: =(Balance!J4+Balance!J5+Balance!J24)/1000 -> 781.90509 | R7: =(Balance!K4+Balance!K5+Balance!K24)/1000 -> 788.3075
B8: Star Ariadne | C8: Newcastlemax | D8: SWS | E8: China | F8: 1 | G8: 42736 | H8: =(TODAY()-G8)/365 -> 9.6383562 | I8: =$M$45*H8^3+$N$45*H8^2+$O$45*H8+$P$45 -> 54.701491 | J8: =I8*$M$58 -> 54.701491 | L8: Working Capital | M8: =Balance!F70/1000 -> 115.876 | N8: =Balance!G70/1000 -> 118.744 | O8: =Balance!H70/1000 -> 107.794 | P8: =Balance!I70/1000 -> 107.794 | Q8: =Balance!J70/1000 -> 107.794 | R8: =Balance!K70/1000 -> 107.794
B9: Star Virgo | C9: Newcastlemax | D9: SWS | E9: China | F9: 1 | G9: 42736 | H9: =(TODAY()-G9)/365 -> 9.6383562 | I9: =$M$45*H9^3+$N$45*H9^2+$O$45*H9+$P$45 -> 54.701491 | J9: =I9*$M$58 -> 54.701491 | L9: Scrubbers | N9: =N21*2 -> 272 | O9: =O21*2 -> 272 | P9: =P21*2 -> 272 | Q9: =Q21*2 -> 272 | R9: =R21*2 -> 272
B10: Star Libra | C10: Newcastlemax | D10: SWS | E10: China | F10: 1 | G10: 42370 | H10: =(TODAY()-G10)/365 -> 10.641096 | I10: =$M$45*H10^3+$N$45*H10^2+$O$45*H10+$P$45 -> 51.727263 | J10: =I10*$M$58 -> 51.727263 | L10: Net Assets | M10: =SUM(M5:M9) -> 3152.976 | N10: =SUM(N5:N9) -> 3487.448 | O10: =SUM(O5:O9) -> 3652.4659 | P10: =SUM(P5:P9) -> 3768.7441 | Q10: =SUM(Q5:Q9) -> 3985.617 | R10: =SUM(R5:R9) -> 4031.1494
B11: Star Sienna | C11: Newcastlemax | D11: SWS | E11: China | F11: 1 | G11: 42736 | H11: =(TODAY()-G11)/365 -> 9.6383562 | I11: =$M$45*H11^3+$N$45*H11^2+$O$45*H11+$P$45 -> 54.701491 | J11: =I11*$M$58 -> 54.701491
B12: Star Marisa | C12: Newcastlemax | D12: SWS | E12: China | F12: 1 | G12: 42370 | H12: =(TODAY()-G12)/365 -> 10.641096 | I12: =$M$45*H12^3+$N$45*H12^2+$O$45*H12+$P$45 -> 51.727263 | J12: =I12*$M$58 -> 51.727263 | L12: Shares Outstanding | M12: ='P&L'!F40/1000000 -> 111.30934 | N12: ='P&L'!G40/1000000 -> 111.28554 | O12: ='P&L'!H40/1000000 -> 111.28554 | P12: ='P&L'!I40/1000000 -> 111.28554 | Q12: ='P&L'!J40/1000000 -> 111.28554 | R12: ='P&L'!K40/1000000 -> 111.28554
B13: Star Karlie | C13: Newcastlemax | D13: SWS | E13: China | F13: 1 | G13: 42370 | H13: =(TODAY()-G13)/365 -> 10.641096 | I13: =$M$45*H13^3+$N$45*H13^2+$O$45*H13+$P$45 -> 51.727263 | J13: =I13*$M$58 -> 51.727263
B14: Star Eleni | C14: Newcastlemax | D14: SWS | E14: China | F14: 1 | G14: 43101 | H14: =(TODAY()-G14)/365 -> 8.6383562 | I14: =$M$45*H14^3+$N$45*H14^2+$O$45*H14+$P$45 -> 57.677152 | J14: =I14*$M$58 -> 57.677152 | L14: Net Asset Value $/sh | M14: =M10/M12 -> 28.32625 | N14: =N10/N12 -> 31.337835 | O14: =O10/O12 -> 32.820668 | P14: =P10/P12 -> 33.865532 | Q14: =Q10/Q12 -> 35.814328 | R14: =R10/R12 -> 36.223478
B15: Star Magnanimus | C15: Newcastlemax | D15: SWS | E15: China | F15: 1 | G15: 43101 | H15: =(TODAY()-G15)/365 -> 8.6383562 | I15: =$M$45*H15^3+$N$45*H15^2+$O$45*H15+$P$45 -> 57.677152 | J15: =I15*$M$58 -> 57.677152 | L15: Más DIVI | M15: 0.37 | N15: 0.5 | O15: 0.9 | P15: =-(CashFlow!I60/('P&L'!I40/1000)) -> 0.65289458 | Q15: =-(CashFlow!J60/('P&L'!J40/1000)) -> 0.57330254 | R15: =-(CashFlow!K60/('P&L'!K40/1000)) -> 1.4025189
B16: Debbie H | C16: Newcastlemax | D16: SWS | E16: China | F16: 1 | G16: 43466 | H16: =(TODAY()-G16)/365 -> 7.6383562 | I16: =$M$45*H16^3+$N$45*H16^2+$O$45*H16+$P$45 -> 60.657577 | J16: =I16*$M$58 -> 60.657577 | L16: P / NAV | M16: =SUM($L$2/(M14)) -> 1.0513217 | N16: =SUM($L$2/(N14)) -> 0.95028901 | O16: =SUM($L$2/(O14)) -> 0.90735509 | P16: =SUM($L$2/(P14+P15)) -> 0.86272762 | Q16: =SUM($L$2/(Q14+Q15)) -> 0.81840998 | R16: =SUM($L$2/(R14+R15)) -> 0.79147405
B17: Star Ayesha | C17: Newcastlemax | D17: SWS | E17: China | F17: 1 | G17: 43466 | H17: =(TODAY()-G17)/365 -> 7.6383562 | I17: =$M$45*H17^3+$N$45*H17^2+$O$45*H17+$P$45 -> 60.657577 | J17: =I17*$M$58 -> 60.657577
B18: Katie K | C18: Newcastlemax | D18: SWS | E18: China | F18: 1 | G18: 43466 | H18: =(TODAY()-G18)/365 -> 7.6383562 | I18: =$M$45*H18^3+$N$45*H18^2+$O$45*H18+$P$45 -> 60.657577 | J18: =I18*$M$58 -> 60.657577
B19: Leviathan | C19: Capesize | D19: JMU | E19: Japan | F19: 1 | G19: 41640 | H19: =(TODAY()-G19)/365 -> 12.641096 | I19: =$M$44*H19^3+$N$44*H19^2+$O$44*H19+$P$44 -> 41.56325 | J19: =I19*$M$54 -> 44.472677 | L19: Asjusted Fleet Value | O19: 1 | P19: 0.995 | Q19: 0.99 | R19: 0.985
B20: Peloreus | C20: Capesize | D20: JMU | E20: Japan | F20: 1 | G20: 41640 | H20: =(TODAY()-G20)/365 -> 12.641096 | I20: =$M$44*H20^3+$N$44*H20^2+$O$44*H20+$P$44 -> 41.56325 | J20: =I20*$M$54 -> 44.472677 | L20: Value Growth in % | N20: =N5/M5-1 -> -0.0016787913 | O20: =O5/N5-1 -> 0.031830684 | P20: =P5/O5-1 -> 0.018128254 | Q20: =Q5/P5-1 -> 0.017660689 | R20: =R5/Q5-1 -> -0.0050505051
B21: Star Claudine | C21: Capesize | D21: STX | E21: S. Korea | F21: 1 | G21: 40544 | H21: =(TODAY()-G21)/365 -> 15.643836 | I21: =$M$44*H21^3+$N$44*H21^2+$O$44*H21+$P$44 -> 32.839269 | J21: =I21*$M$53 -> 35.46641 | L21: Scrubber | N21: 136 | O21: 136 | P21: 136 | Q21: 136 | R21: 136
B22: Star Ophelia | C22: Capesize | D22: STX | E22: S. Korea | F22: 1 | G22: 40179 | H22: =(TODAY()-G22)/365 -> 16.643836 | I22: =$M$44*H22^3+$N$44*H22^2+$O$44*H22+$P$44 -> 30.078012 | J22: =I22*$M$53 -> 32.484253 | L22: Fleet | N22: 141 | O22: 141 | P22: 141 | Q22: 141 | R22: 141
B23: Star Martha | C23: Capesize | D23: Imabari | E23: Japan | F23: 1 | G23: 40179 | H23: =(TODAY()-G23)/365 -> 16.643836 | I23: =$M$44*H23^3+$N$44*H23^2+$O$44*H23+$P$44 -> 30.078012 | J23: =I23*$M$54 -> 32.183473 | L23: % Fleet with scrubber | N23: =(N21/N22) -> 0.96453901 | O23: =(O21/O22) -> 0.96453901 | P23: =(P21/P22) -> 0.96453901 | Q23: =(Q21/Q22) -> 0.96453901 | R23: =(R21/R22) -> 0.96453901
B24: Star Pauline | C24: Capesize | D24: Imabari | E24: Japan | F24: 1 | G24: 39448 | H24: =(TODAY()-G24)/365 -> 18.646575 | I24: =$M$44*H24^3+$N$44*H24^2+$O$44*H24+$P$44 -> 24.836702 | J24: =I24*$M$54 -> 26.575271
B25: Star Lyra | C25: Capesize | D25: HHI | E25: S. Korea | F25: 1 | G25: 39814 | H25: =(TODAY()-G25)/365 -> 17.643836 | I25: =$M$44*H25^3+$N$44*H25^2+$O$44*H25+$P$44 -> 27.408778 | J25: =I25*$M$53 -> 29.60148 | L25: TCE Newcastlemax / Capesize | N25: 36759 | O25: =33087*1.05 -> 34741.35 | P25: =O25*0.98 -> 34046.523 | Q25: =P25*1.05 -> 35748.849 | R25: =Q25*1.02 -> 36463.826
B26: Star Bueno | C26: Capesize | D26: HHI | E26: S. Korea | F26: 1 | G26: 40179 | H26: =(TODAY()-G26)/365 -> 16.643836 | I26: =$M$44*H26^3+$N$44*H26^2+$O$44*H26+$P$44 -> 30.078012 | J26: =I26*$M$53 -> 32.484253 | L26: TCE Post Panamax / Kamsarmax / Panamax | N26: 20400 | O26: =21711*1.05 -> 22796.55 | P26: =O26*0.95 -> 21656.722 | Q26: =P26*1.05 -> 22739.559 | R26: =Q26*1.02 -> 23194.35
B27: Star Marilena | C27: Capesize | D27: HHI | E27: S. Korea | F27: 1 | G27: 40179 | H27: =(TODAY()-G27)/365 -> 16.643836 | I27: =$M$44*H27^3+$N$44*H27^2+$O$44*H27+$P$44 -> 30.078012 | J27: =I27*$M$53 -> 32.484253 | L27: TCE Ultramax / Supramax | N27: 20270 | O27: =19748*1.05 -> 20735.4 | P27: =O27*0.95 -> 19698.63 | Q27: =P27*1.05 -> 20683.562 | R27: =Q27*1.02 -> 21097.233
B28: Star Borneo | C28: Capesize | D28: HHI | E28: S. Korea | F28: 1 | G28: 40179 | H28: =(TODAY()-G28)/365 -> 16.643836 | I28: =$M$44*H28^3+$N$44*H28^2+$O$44*H28+$P$44 -> 30.078012 | J28: =I28*$M$53 -> 32.484253 | L28: % Spot
B29: Star Marianne | C29: Capesize | D29: Hyundai Samho | E29: S. Korea | F29: 1 | G29: 40179 | H29: =(TODAY()-G29)/365 -> 16.643836 | I29: =$M$44*H29^3+$N$44*H29^2+$O$44*H29+$P$44 -> 30.078012 | J29: =I29*$M$53 -> 32.484253
B30: Star Janni | C30: Capesize | D30: HHI | E30: S. Korea | F30: 1 | G30: 40179 | H30: =(TODAY()-G30)/365 -> 16.643836 | I30: =$M$44*H30^3+$N$44*H30^2+$O$44*H30+$P$44 -> 30.078012 | J30: =I30*$M$53 -> 32.484253 | L30: *in millions USD, except multiples | P30: FY 2026 | R30: NTM
B31: Star Angie | C31: Capesize | D31: SWS | E31: China | F31: 1 | G31: 39083 | H31: =(TODAY()-G31)/365 -> 19.646575 | I31: =$M$44*H31^3+$N$44*H31^2+$O$44*H31+$P$44 -> 22.38788 | J31: =I31*$M$58 -> 22.38788 | L31: Market Value | P31: =$L$2*P12 -> 3314.0835 | R31: =$L$2*R12 -> 3314.0835
B32: Kymopolia | C32: Capesize | D32: Namura | E32: Japan | F32: 1 | G32: 38718 | H32: =(TODAY()-G32)/365 -> 20.646575 | I32: =$M$44*H32^3+$N$44*H32^2+$O$44*H32+$P$44 -> 20.067145 | J32: =I32*$M$54 -> 21.471845 | L32: EV | P32: =P31-P6-P7 -> 3673.4457 | R32: =R31-R6-R7 -> 3457.973
B33: Star Eva | C33: Capesize | D33: STX | E33: China | F33: 1 | G33: 40909 | H33: =(TODAY()-G33)/365 -> 14.643836 | L33: Diluted Adj. EPS | P33: =SUM('P&L'!F38:I38) -> 4.7326611 | R33: =SUM('P&L'!H38:K38) -> 6.1882627
B34: Shibumi | C34: Capesize | D34: JMU | E34: Japan | F34: Chartered-in | G34: 44197 | L34: Adj. EBITDA | P34: =SUM('P&L'!F45:I45)/1000 -> 696.64851 | R34: =SUM('P&L'!H45:K45)/1000 -> 870.88559
B35: Star Vega | C35: PostPanamax | D35: Tsuneishi Zhousan | E35: China | F35: 1 | G35: 40544 | H35: =(TODAY()-G35)/365 -> 15.643836 | I35: =$M$46*H35^3+$N$46*H35^2+$O$46*H35+$P$46 -> 19.008871 | J35: =I35*$M$58 -> 19.008871 | L35: Dividend | P35: =SUM(M15:P15) -> 2.4228946 | R35: =SUM(O15:R15) -> 3.5287161
B36: Star Sirius | C36: PostPanamax | D36: Tsuneishi Zhousan | E36: China | F36: 1 | G36: 40544 | H36: =(TODAY()-G36)/365 -> 15.643836 | I36: =$M$46*H36^3+$N$46*H36^2+$O$46*H36+$P$46 -> 19.008871 | J36: =I36*$M$58 -> 19.008871 | L36: Levered FCF | P36: =SUM(CashFlow!F72:I72)/1000 -> 418.05651 | R36: =SUM(CashFlow!H72:K72)/1000 -> 688.60159
B37: Madredeus | C37: PostPanamax | D37: Tsuneishi Zhousan | E37: China | F37: 1 | G37: 40544 | H37: =(TODAY()-G37)/365 -> 15.643836 | I37: =$M$46*H37^3+$N$46*H37^2+$O$46*H37+$P$46 -> 19.008871 | J37: =I37*$M$58 -> 19.008871 | L37: Adjusted P/E | P37: =$L$2/P33 -> 6.292443 | R37: =$L$2/R33 -> 4.8123361
B38: Amami | C38: PostPanamax | D38: Tsuneishi Zhousan | E38: China | F38: 1 | G38: 40544 | H38: =(TODAY()-G38)/365 -> 15.643836 | I38: =$M$46*H38^3+$N$46*H38^2+$O$46*H38+$P$46 -> 19.008871 | J38: =I38*$M$58 -> 19.008871 | L38: EV/Adj. EBITDA | P38: =P32/P34 -> 5.273026 | R38: =R32/R34 -> 3.9706398
B39: Star Aphrodite | C39: PostPanamax | D39: Sungdong | E39: S. Korea | F39: 1 | G39: 40544 | H39: =(TODAY()-G39)/365 -> 15.643836 | I39: =$M$46*H39^3+$N$46*H39^2+$O$46*H39+$P$46 -> 19.008871 | J39: =I39*$M$53 -> 20.529581 | L39: P/FCF | P39: =$L$2/(P36/P12) -> 7.9273576 | R39: =$L$2/(R36/R12) -> 4.8127735
B40: Star Piera | C40: PostPanamax | D40: Sungdong | E40: S. Korea | F40: 1 | G40: 40179 | H40: =(TODAY()-G40)/365 -> 16.643836 | I40: =$M$46*H40^3+$N$46*H40^2+$O$46*H40+$P$46 -> 17.418836 | J40: =I40*$M$53 -> 18.812343 | L40: Dividend Yield | P40: =P35/$L$2 -> 0.081359791 | R40: =R35/$L$2 -> 0.11849282
...

Sheet P&L
B1: Star Bulk (in thousands of US Dollars) | C1: 2023 | D1: 2024 | E1: 2025 | F1: Q1 2026 | G1: Q2 2026 | H1: Q3 2026 | I1: Q4 2026 | J1: Q1 2027 | K1: Q2 2027
B2: Revenues:
B3: Voyage revenues | C3: 949269 | D3: 1265458 | E3: 1042499 | F3: 281152 | G3: 357412 | H3: =SUM(H204:H352)/1000 -> 304322.98 | I3: =SUM(I204:I352)/1000 -> 298665.54 | J3: =SUM(J204:J352)/1000 -> 320120.33 | K3: =SUM(K204:K352)/1000 -> 326522.74
B4: Total revenues | C4: =SUM(C3) -> 949269 | D4: =SUM(D3) -> 1265458 | E4: =SUM(E3) -> 1042499 | F4: =SUM(F3) -> 281152 | G4: =SUM(G3) -> 357412 | H4: =SUM(H3) -> 304322.98 | I4: =SUM(I3) -> 298665.54 | J4: =SUM(J3) -> 320120.33 | K4: =SUM(K3) -> 326522.74
B6: Expenses/(Income):
B7: Voyage expenses | C7: 253843 | D7: 266225 | E7: 215015 | F7: 52762 | G7: 57611
B8: Charter-in hire expenses | C8: 17656 | D8: 58003 | E8: 63466 | F8: 14479 | G8: 12624
B9: Vessel Operating expenses | C9: 221327 | D9: 274991 | E9: 269163 | F9: 61786 | G9: 64326 | H9: 64326 | I9: 64326 | J9: 64326 | K9: 64326
B10: Dry docking expenses | C10: 41969 | D10: 62728 | E10: 92201 | F10: 19593 | G10: 19553 | H10: 15600 | I10: 10700 | J10: =16700/4 -> 4175 | K10: =16700/4 -> 4175
B11: Depreciation | C11: 138429 | D11: 164055 | E11: 168277 | F11: 39578 | G11: 39783 | H11: 39783 | I11: 39783 | J11: 39783 | K11: 39783
B12: Management fees | C12: 16809 | D12: 18956 | E12: 23180 | F12: 5451 | G12: 5633 | H12: 5633 | I12: 5633 | J12: 5633 | K12: 5633
B13: G&A expenses | C13: 54413 | D13: 70778 | E13: 70542 | F13: 14481 | G13: 16065 | H13: 16065 | I13: 16065 | J13: 16065 | K13: 16065
B14: Impairment loss | C14: 17838 | D14: 1800 | E14: 0 | F14: 0 | G14: 0 | H14: 0 | I14: 0 | J14: 0 | K14: 0
B15: Loss on write-down of inventory | C15: 9318 | D15: 6286 | E15: 0 | F15: 0 | G15: 0 | H15: 0 | I15: 0 | J15: 0 | K15: 0
B16: Other operational loss | C16: 952 | D16: 2326 | E16: 5421 | F16: 873 | G16: 548 | H16: - | I16: - | J16: - | K16: -
B17: Other operational gain | C17: -33980 | D17: -4740 | E17: -15005 | F17: -711 | G17: -2450 | H17: - | I17: - | J17: - | K17: -
B18: Loss on bad debt | C18: 300 | D18: 308 | E18: 0 | F18: 0 | G18: 98 | H18: - | I18: - | J18: - | K18: -
B19: (Gain)/loss on FFAs & bunker swaps | C19: 1336 | D19: 4033 | E19: -4944 | F19: 2891 | G19: 943
B20: Gain/(loss) on sale of vessel | C20: -29399 | D20: -43287 | E20: 18313 | F20: -172 | G20: -12354 | H20: =-(CashFlow!H46-Balance!G13) -> -20550 | I20: 0 | J20: 0 | K20: 0
B21: Total operating expenses, net | C21: =SUM(C7:C20) -> 710811 | D21: =SUM(D7:D20) -> 882462 | E21: =SUM(E7:E20) -> 905629 | F21: =SUM(F7:F20) -> 211011 | G21: =SUM(G7:G20) -> 202380 | H21: =SUM(H7:H20) -> 120857 | I21: =SUM(I7:I20) -> 136507 | J21: =SUM(J7:J20) -> 129982 | K21: =SUM(K7:K20) -> 129982
B23: Operating income / (loss) | C23: =C4-C21 -> 238458 | D23: =D4-D21 -> 382996 | E23: =E4-E21 -> 136870 | F23: =F4-F21 -> 70141 | G23: =G4-G21 -> 155032 | H23: =H4-H21 -> 183465.98 | I23: =I4-I21 -> 162158.54 | J23: =J4-J21 -> 190138.33 | K23: =K4-K21 -> 196540.74
B25: Other Income/(Expenses)
B26: Interest and finance costs | C26: -71319 | D26: -91827 | E26: -71225 | F26: -12893 | G26: -12446 | H26: -12446 | I26: -12446 | J26: -12446 | K26: -12446
B27: Interest income and other income/(loss) | C27: 15228 | D27: 16378 | E27: 18887 | F27: 1188 | G27: 3035 | H27: 2000 | I27: 2000 | J27: 2000 | K27: 2000
B28: Gain/(loss) on interest rate swaps, net | C28: -3539 | D28: -1861 | E28: 980 | F28: 184 | G28: 28 | H28: 0 | I28: 0 | J28: 0 | K28: 0
B29: Gain/(loss) on debt extinguishment, net | C29: -5149 | D29: -1144 | E29: -431 | F29: -107 | G29: -714 | H29: 0 | I29: 0 | J29: 0 | K29: 0
B30: Total other expenses, net | C30: =SUM(C26:C29) -> -64779 | D30: =SUM(D26:D29) -> -78454 | E30: =SUM(E26:E29) -> -51789 | F30: =SUM(F26:F29) -> -11628 | G30: =SUM(G26:G29) -> -10097 | H30: =SUM(H26:H29) -> -10446 | I30: =SUM(I26:I29) -> -10446 | J30: =SUM(J26:J29) -> -10446 | K30: =SUM(K26:K29) -> -10446
B32: Income/(loss) before taxes | C32: =C23+C30 -> 173679 | D32: =D23+D30 -> 304542 | E32: =E23+E30 -> 85081 | F32: =F23+F30 -> 58513 | G32: =G23+G30 -> 144935 | H32: =H23+H30 -> 173019.98 | I32: =I23+I30 -> 151712.54 | J32: =J23+J30 -> 179692.33 | K32: =K23+K30 -> 186094.74
B33: Income taxes | C33: -183 | D33: 116 | E33: 0 | F33: 0 | G33: 0 | H33: 0 | I33: 0 | J33: 0 | K33: 0
B34: Equity in income/(loss) of investee | C34: 60 | D34: -4 | E34: -907 | F34: 19 | G34: 14 | H34: 0 | I34: 0 | J34: 0 | K34: 0
B35: Net profit / (Loss) | C35: =C32+C33+C34 -> 173556 | D35: =D32+D33+D34 -> 304654 | E35: =E32+E33+E34 -> 84174 | F35: =F32+F33+F34 -> 58532 | G35: =G32+G33+G34 -> 144949 | H35: =H32+H33+H34 -> 173019.98 | I35: =I32+I33+I34 -> 151712.54 | J35: =J32+J33+J34 -> 179692.33 | K35: =K32+K33+K34 -> 186094.74
B37: Basic earnings/(loss) per share | C37: =C35/(C40/1000) -> 1.7627427 | D37: =D35/(D40/1000) -> 2.8503416 | E37: =E35/(E40/1000) -> 0.73193051 | F37: =F35/(F40/1000) -> 0.52584988 | G37: =G35/(G40/1000) -> 1.3024962 | H37: =H35/(H40/1000) -> 1.554739 | I37: =I35/(I40/1000) -> 1.3632726 | J37: =J35/(J40/1000) -> 1.6146961 | K37: =K35/(K40/1000) -> 1.6722274
B38: Diluted earnings/(loss) per share | C38: =C35/(C42/1000) -> 1.7543666 | D38: =D35/(D42/1000) -> 2.8026277 | E38: =E35/(E42/1000) -> 0.72928196 | F38: =F35/(F42/1000) -> 0.52349354 | G38: =G35/(G42/1000) -> 1.2989965 | H38: =H35/(H42/1000) -> 1.5505615 | I38: =I35/(I42/1000) -> 1.3596096 | J38: =J35/(J42/1000) -> 1.6103575 | K38: =K35/(K42/1000) -> 1.6677342
B40: Weighted average number of shares (basic) | C40: 98457929 | D40: 106883330 | E40: 115002721 | F40: 111309335 | G40: 111285544 | H40: 111285544 | I40: 111285544 | J40: 111285544 | K40: 111285544
D41: =D40/C40-1 -> 0.085573616 | E41: =E40/D40-1 -> 0.075964989 | F41: =F40/E40-1 -> -0.03211564 | G41: =G40/F40-1 -> -0.00021373769 | H41: =H40/G40-1 -> 0 | I41: =I40/H40-1 -> 0 | J41: =J40/I40-1 -> 0 | K41: =K40/J40-1 -> 0
B42: Weighted average number of shares (diluted) | C42: 98928011 | D42: 108702988 | E42: 115420379 | F42: 111810357 | G42: 111585370 | H42: 111585370 | I42: 111585370 | J42: 111585370 | K42: 111585370
D43: =D42/C42-1 -> 0.098808992 | E43: =E42/D42-1 -> 0.061795827 | F43: =F42/E42-1 -> -0.031277163 | G43: =G42/F42-1 -> -0.0020122197 | H43: =H42/G42-1 -> 0 | I43: =I42/H42-1 -> 0 | J43: =J42/I42-1 -> 0 | K43: =K42/J42-1 -> 0
B45: Adjusted EBITDA | C45: =C23+C11+C20+C14 -> 365326 | D45: =D23+D11+D20+D14 -> 505564 | E45: =E23+E11+E20+E14 -> 323460 | F45: =F23+F11+F20+F14 -> 109547 | G45: =G23+G11+G20+G14 -> 182461 | H45: =H23+H11+H20+H14 -> 202698.98 | I45: =I23+I11+I20+I14 -> 201941.54 | J45: =J23+J11+J20+J14 -> 229921.33 | K45: =K23+K11+K20+K14 -> 236323.74
B46: Adjusted Profit after tax | C46: =C45-C11+C30+C33+C34 -> 161995 | D46: =D45-D11+D30+D33+D34 -> 263167 | E46: =E45-E11+E30+E33+E34 -> 102487 | F46: =F45-F11+F30+F33+F34 -> 58360 | G46: =G45-G11+G30+G33+G34 -> 132595 | H46: =H45-H11+H30+H33+H34 -> 152469.98 | I46: =I45-I11+I30+I33+I34 -> 151712.54 | J46: =J45-J11+J30+J33+J34 -> 179692.33 | K46: =K45-K11+K30+K33+K34 -> 186094.74
B47: Diluted Adj. EPS | C47: =C46/(C42/1000) -> 1.6375039 | D47: =D46/(D42/1000) -> 2.420973 | E47: =E46/(E42/1000) -> 0.88794545 | F47: =F46/(F42/1000) -> 0.52195522 | G47: =G46/(G42/1000) -> 1.188283 | H47: =H46/(H42/1000) -> 1.3663976 | I47: =I46/(I42/1000) -> 1.3596096 | J47: =J46/(J42/1000) -> 1.6103575 | K47: =K46/(K42/1000) -> 1.6677342
...

Sheet Balance
B1: Star Bulk (in thousands of US Dollars) | C1: 2023 | D1: 2024 | E1: 2025 | F1: Q1 2026 | G1: Q2 2026 | H1: Q3 2026 | I1: Q4 2026 | J1: Q1 2027 | K1: Q2 2027
B2: ASSETS
B3: CURRENT ASSETS
B4: Cash and cash equivalents | C4: 227481 | D4: 425066 | E4: 488511 | F4: 407817 | G4: 563667 | H4: =CashFlow!H69-H24 -> 618867.74 | I4: =CashFlow!I69-I24 -> 688010.3 | J4: =CashFlow!J69-J24 -> 780290.09 | K4: =CashFlow!K69-K24 -> 786692.5
B5: Restricted cash, current | C5: 32248 | D5: 11218 | E5: 11808
B6: Trade accounts receivable, net | C6: 68624 | D6: 79303 | E6: 83587
B7: Inventories | C7: 62362 | D7: 78589 | E7: 51477
B8: Due from managers | C8: 23 | D8: 45 | E8: 52
B9: Due from related parties | C9: 38 | D9: 37 | E9: 79
B10: Prepaid expenses and other receivables | C10: 19296 | D10: 18873 | E10: 12694
B11: Derivatives, current asset portion | C11: 6305 | D11: 2177 | E11: 617
B12: Accrued income | C12: 0 | D12: 67 | E12: 0
B13: Asset held for sale | C13: 15190 | D13: 0 | E13: 0 | F13: 0 | G13: 10950 | H13: 0 | I13: 0 | J13: 0 | K13: 0
B14: Other current assets | C14: 22830 | D14: 43598 | E14: 34520 | F14: 186387 | G14: 233262 | H14: 233262 | I14: 233262 | J14: 233262 | K14: 233262
B15: Total current assets | C15: =SUM(C4:C14) -> 454397 | D15: =SUM(D4:D14) -> 658973 | E15: =SUM(E4:E14) -> 683345 | F15: =SUM(F4:F14) -> 594204 | G15: =SUM(G4:G14) -> 807879 | H15: =SUM(H4:H14) -> 852129.74 | I15: =SUM(I4:I14) -> 921272.3 | J15: =SUM(J4:J14) -> 1013552.1 | K15: =SUM(K4:K14) -> 1019954.5
B17: FIXED ASSETS
B18: Advances for vessels under construction | C18: 0 | D18: 27526 | E18: 87277 | F18: 99999 | G18: 62929 | H18: 62929 | I18: 62929 | J18: 62929 | K18: 62929
B19: Vessels and other fixed assets, net | C19: 2539743 | D19: 3208357 | E19: 2874947 | F19: 2822365 | G19: 2838550 | H19: =G19+H75-'P&L'!H11 -> 2859967 | I19: =H19+I75-'P&L'!I11 -> 2889484 | J19: =I19+J75-'P&L'!J11 -> 2854701 | K19: =J19+K75-'P&L'!K11 -> 2819918
B20: Total Fixed assets | C20: =SUM(C18:C19) -> 2539743 | D20: =SUM(D18:D19) -> 3235883 | E20: =SUM(E18:E19) -> 2962224 | F20: =SUM(F18:F19) -> 2922364 | G20: =SUM(G18:G19) -> 2901479 | H20: =SUM(H18:H19) -> 2922896 | I20: =SUM(I18:I19) -> 2952413 | J20: =SUM(J18:J19) -> 2917630 | K20: =SUM(K18:K19) -> 2882847
B22: NON-CURRENT ASSETS
B23: Long term investment | C23: 1736 | D23: 1733 | E23: 826 | F23: 0 | G23: 0 | H23: 0 | I23: 0 | J23: 0 | K23: 0
B24: Restricted cash, non-current | C24: 2021 | D24: 4596 | E24: 1615 | F24: 1615 | G24: 1615 | H24: 1615 | I24: 1615 | J24: 1615 | K24: 1615
B25: Operating leases, RoU assets | C25: 27825 | D25: 184509 | E25: 157058
B26: Derivatives, non-current asset portion | C26: 2533 | D26: 330 | E26: 0
B27: Other non-current assets | C27: 0 | D27: 354 | E27: 317 | F27: 150614 | G27: 143190 | H27: 143190 | I27: 143190 | J27: 143190 | K27: 143190
B28: Total non-current assets | C28: =SUM(C23:C27) -> 34115 | D28: =SUM(D23:D27) -> 191522 | E28: =SUM(E23:E27) -> 159816 | F28: =SUM(F23:F27) -> 152229 | G28: =SUM(G23:G27) -> 144805 | H28: =SUM(H23:H27) -> 144805 | I28: =SUM(I23:I27) -> 144805 | J28: =SUM(J23:J27) -> 144805 | K28: =SUM(K23:K27) -> 144805
B30: TOTAL ASSETS | C30: =C15+C28+C20 -> 3028255 | D30: =D15+D28+D20 -> 4086378 | E30: =E15+E28+E20 -> 3805385 | F30: =F15+F28+F20 -> 3668797 | G30: =G15+G28+G20 -> 3854163 | H30: =H15+H28+H20 -> 3919830.7 | I30: =I15+I28+I20 -> 4018490.3 | J30: =J15+J28+J20 -> 4075987.1 | K30: =K15+K28+K20 -> 4047606.5
B32: LIABILITIES AND SHAREHOLDERS´EQUITY
B33: CURRENT LIABILITIES
B34: Current portion of long-term bank loans | C34: 249125 | D34: 221147 | E34: 226137 | F34: 173405 | G34: 233581
B35: Lease financing short term | C35: 2731 | D35: 2731 | E35: 2731
B36: Accounts payable | C36: 39317 | D36: 51591 | E36: 49456
B37: Due to managers | C37: 7386 | D37: 10938 | E37: 12151
B38: Due to related parties | C38: 1659 | D38: 3274 | E38: 3557
B39: Accrued liabilities | C39: 31372 | D39: 62607 | E39: 38660
B40: Operating lease liabilities, current | C40: 5251 | D40: 28227 | E40: 28624
B41: Derivative, current liability portion | C41: 5784 | D41: 0 | E41: 0
B42: Deferred revenue | C42: 16738 | D42: 17297 | E42: 20361
B43: Other current liabilities | C43: 0 | D43: 2000 | E43: 2000 | F43: 170510 | G43: 188397 | H43: 188397 | I43: 188397 | J43: 188397 | K43: 188397
B44: Total current liabilities | C44: =SUM(C34:C43) -> 359363 | D44: =SUM(D34:D43) -> 399812 | E44: =SUM(E34:E43) -> 383677 | F44: =SUM(F34:F43) -> 343915 | G44: =SUM(G34:G43) -> 421978 | H44: =SUM(H34:H43) -> 188397 | I44: =SUM(I34:I43) -> 188397 | J44: =SUM(J34:J43) -> 188397 | K44: =SUM(K34:K43) -> 188397
...

Sheet CashFlow
B1: Star Bulk (in thousands of US Dollars) | C1: 2023 | D1: 2024 | E1: 2025 | F1: Q1 2026 | G1: Q2 2026 | H1: Q3 2026 | I1: Q4 2026 | J1: Q1 2027 | K1: Q2 2027
B3: CASH FLOW FROM OPERATING ACTIVITIES
B4: Net income/(loss) | C4: 173556 | D4: 304654 | E4: 84174 | H4: ='P&L'!H35 -> 173019.98 | I4: ='P&L'!I35 -> 151712.54 | J4: ='P&L'!J35 -> 179692.33 | K4: ='P&L'!K35 -> 186094.74
B5: Adjustment:
B6: Depreciation | C6: 138429 | D6: 164055 | E6: 168277 | H6: ='P&L'!H11 -> 39783 | I6: ='P&L'!I11 -> 39783 | J6: ='P&L'!J11 -> 39783 | K6: ='P&L'!K11 -> 39783
B7: Amortization of debt (loan, leases) issuance costs | C7: 3661 | D7: 3583 | E7: 3141 | H7: 0 | I7: 0 | J7: 0 | K7: 0
B8: Noncash lease expense | C8: 9793 | D8: 18385 | E8: 28377 | H8: 0 | I8: 0 | J8: 0 | K8: 0
B9: Impairment loss | C9: 17838 | D9: 1800 | E9: 0 | H9: 0 | I9: 0 | J9: 0 | K9: 0
B10: Gain on sale of vessels | C10: -29399 | D10: -43287 | E10: 18313 | H10: ='P&L'!H20 -> -20550 | I10: 0 | J10: 0 | K10: 0
B11: Gain/(loss) on debt extinguishment, net | C11: 5149 | D11: 1144 | E11: 431 | H11: 0 | I11: 0 | J11: 0 | K11: 0
B12: Loss on bad debt | C12: 300 | D12: 308 | E12: 0 | H12: 0 | I12: 0 | J12: 0 | K12: 0
B13: Share-based compensation | C13: 20877 | D13: 18328 | E13: 17798 | H13: 0 | I13: 0 | J13: 0 | K13: 0
B14: Gain from insurance proceeds relating to vessel total loss | C14: -28163 | D14: 0 | E14: 0 | H14: 0 | I14: 0 | J14: 0 | K14: 0
B15: Loss on write-down of inventory | C15: 9318 | D15: 6286 | E15: 0 | H15: 0 | I15: 0 | J15: 0 | K15: 0
B16: Change in fair value of freight deriv. and bunker swaps | C16: 9662 | D16: -3372 | E16: -277 | H16: 0 | I16: 0 | J16: 0 | K16: 0
B17: Other non-cash charges | C17: 170 | D17: -190 | E17: -199 | H17: 0 | I17: 0 | J17: 0 | K17: 0
B18: Write-off accruals and current assets | C18: 0 | D18: 0 | E18: -9416 | H18: 0 | I18: 0 | J18: 0 | K18: 0
B19: Gain on hull and machinery claims | C19: -200 | D19: -898 | E19: -219 | H19: 0 | I19: 0 | J19: 0 | K19: 0
B20: Equity in income / (loss) of investee | C20: -60 | D20: 4 | E20: 907 | H20: 0 | I20: 0 | J20: 0 | K20: 0
B21: Changes in WC:
B22: (Increase)/Decrease in:
B23: Trade account receivable | C23: 14396 | D23: 33600 | E23: -4284 | H23: 0 | I23: 0 | J23: 0 | K23: 0
B24: Inventories | C24: -5851 | D24: 1925 | E24: 25639 | H24: 0 | I24: 0 | J24: 0 | K24: 0
B25: Prepaid expenses and other receivables | C25: -6829 | D25: -11187 | E25: 4101 | H25: 0 | I25: 0 | J25: 0 | K25: 0
B26: Derivatives asset | C26: 6625 | D26: 1066 | E26: 189 | H26: 0 | I26: 0 | J26: 0 | K26: 0
B27: Accrued income | C27: 0 | D27: -67 | E27: 67 | H27: 0 | I27: 0 | J27: 0 | K27: 0
B28: Due from related parties | C28: 286 | D28: 1 | E28: -42 | H28: 0 | I28: 0 | J28: 0 | K28: 0
B29: Due from managers | C29: 61 | D29: -22 | E29: -7 | H29: 0 | I29: 0 | J29: 0 | K29: 0
B30: Other current assets | C30: 0 | D30: 0 | E30: 0 | H30: 0 | I30: 0 | J30: 0 | K30: 0
B31: Other non-current assets | C31: 0 | D31: 0 | E31: 37 | H31: 0 | I31: 0 | J31: 0 | K31: 0
B32: Increase/(decrease) in:
B33: Account payable | C33: 7306 | D33: -6617 | E33: 6693 | H33: 0 | I33: 0 | J33: 0 | K33: 0
B34: Operating lease liability | C34: -9792 | D34: -18387 | E34: -28377 | H34: 0 | I34: 0 | J34: 0 | K34: 0
B35: Due to related parties | C35: 158 | D35: 1615 | E35: 283 | H35: 0 | I35: 0 | J35: 0 | K35: 0
B36: Accrued liabilities | C36: -2610 | D36: -3471 | E36: -23947 | H36: 0 | I36: 0 | J36: 0 | K36: 0
B37: Due to managers | C37: 1042 | D37: 3552 | E37: 1213 | H37: 0 | I37: 0 | J37: 0 | K37: 0
B38: Deferred revenue | C38: 54 | D38: -3654 | E38: 3064 | H38: 0 | I38: 0 | J38: 0 | K38: 0
B39: Other current liabilities | C39: 0 | D39: 2000 | E39: 0 | H39: 0 | I39: 0 | J39: 0 | K39: 0
A40: x | B40: Net Cash provided by operating activities | C40: =SUM(C4:C39) -> 335777 | D40: =SUM(D4:D39) -> 471154 | E40: =SUM(E4:E39) -> 295936 | F40: 112386 | G40: =262275-F40 -> 149889 | H40: =SUM(H4:H39) -> 192252.98 | I40: =SUM(I4:I39) -> 191495.54 | J40: =SUM(J4:J39) -> 219475.33 | K40: =SUM(K4:K39) -> 225877.74
B43: CASH FLOWS FROM INVESTING ACTIVITIES
...
